[2024-06-14T23:28:18.912+0530] {local_task_job_runner.py:120} INFO - ::group::Pre task execution logs
[2024-06-14T23:28:18.932+0530] {taskinstance.py:2073} INFO - Dependencies all met for dep_context=non-requeueable deps ti=<TaskInstance: my_data_pipeline_dag.collect_data_1 manual__2024-06-14T17:58:13.202032+00:00 [queued]>
[2024-06-14T23:28:18.940+0530] {taskinstance.py:2073} INFO - Dependencies all met for dep_context=requeueable deps ti=<TaskInstance: my_data_pipeline_dag.collect_data_1 manual__2024-06-14T17:58:13.202032+00:00 [queued]>
[2024-06-14T23:28:18.940+0530] {taskinstance.py:2303} INFO - Starting attempt 1 of 2
[2024-06-14T23:28:18.963+0530] {taskinstance.py:2327} INFO - Executing <Task(BashOperator): collect_data_1> on 2024-06-14 17:58:13.202032+00:00
[2024-06-14T23:28:18.967+0530] {standard_task_runner.py:63} INFO - Started process 14232 to run task
[2024-06-14T23:28:18.971+0530] {standard_task_runner.py:90} INFO - Running: ['airflow', 'tasks', 'run', 'my_data_pipeline_dag', 'collect_data_1', 'manual__2024-06-14T17:58:13.202032+00:00', '--job-id', '92', '--raw', '--subdir', 'DAGS_FOLDER/my_first_dag.py', '--cfg-path', '/tmp/tmp_t6r7rtf']
[2024-06-14T23:28:18.974+0530] {standard_task_runner.py:91} INFO - Job 92: Subtask collect_data_1
[2024-06-14T23:28:19.019+0530] {task_command.py:426} INFO - Running <TaskInstance: my_data_pipeline_dag.collect_data_1 manual__2024-06-14T17:58:13.202032+00:00 [running]> on host DESKTOP-J05K55U.
[2024-06-14T23:28:19.098+0530] {taskinstance.py:2644} INFO - Exporting env vars: AIRFLOW_CTX_DAG_EMAIL='airflow@example.com' AIRFLOW_CTX_DAG_OWNER='airflow' AIRFLOW_CTX_DAG_ID='my_data_pipeline_dag' AIRFLOW_CTX_TASK_ID='collect_data_1' AIRFLOW_CTX_EXECUTION_DATE='2024-06-14T17:58:13.202032+00:00' AIRFLOW_CTX_TRY_NUMBER='1' AIRFLOW_CTX_DAG_RUN_ID='manual__2024-06-14T17:58:13.202032+00:00'
[2024-06-14T23:28:19.103+0530] {taskinstance.py:430} INFO - ::endgroup::
[2024-06-14T23:28:19.104+0530] {subprocess.py:63} INFO - Tmp dir root location: /tmp
[2024-06-14T23:28:19.105+0530] {subprocess.py:75} INFO - Running command: ['/usr/bin/bash', '-c', 'python "/home/wsl/airflow/dags/Collect Data/covid_19_usa.py"']
[2024-06-14T23:28:19.117+0530] {subprocess.py:86} INFO - Output:
[2024-06-14T23:28:29.250+0530] {subprocess.py:93} INFO - Traceback (most recent call last):
[2024-06-14T23:28:29.252+0530] {subprocess.py:93} INFO -   File "/home/wsl/airflow_venv/lib/python3.10/site-packages/urllib3/connection.py", line 174, in _new_conn
[2024-06-14T23:28:29.254+0530] {subprocess.py:93} INFO -     conn = connection.create_connection(
[2024-06-14T23:28:29.255+0530] {subprocess.py:93} INFO -   File "/home/wsl/airflow_venv/lib/python3.10/site-packages/urllib3/util/connection.py", line 72, in create_connection
[2024-06-14T23:28:29.256+0530] {subprocess.py:93} INFO -     for res in socket.getaddrinfo(host, port, family, socket.SOCK_STREAM):
[2024-06-14T23:28:29.258+0530] {subprocess.py:93} INFO -   File "/usr/lib/python3.10/socket.py", line 955, in getaddrinfo
[2024-06-14T23:28:29.259+0530] {subprocess.py:93} INFO -     for res in _socket.getaddrinfo(host, port, family, type, proto, flags):
[2024-06-14T23:28:29.260+0530] {subprocess.py:93} INFO - socket.gaierror: [Errno -3] Temporary failure in name resolution
[2024-06-14T23:28:29.261+0530] {subprocess.py:93} INFO - 
[2024-06-14T23:28:29.262+0530] {subprocess.py:93} INFO - During handling of the above exception, another exception occurred:
[2024-06-14T23:28:29.263+0530] {subprocess.py:93} INFO - 
[2024-06-14T23:28:29.264+0530] {subprocess.py:93} INFO - Traceback (most recent call last):
[2024-06-14T23:28:29.265+0530] {subprocess.py:93} INFO -   File "/home/wsl/airflow_venv/lib/python3.10/site-packages/urllib3/connectionpool.py", line 715, in urlopen
[2024-06-14T23:28:29.266+0530] {subprocess.py:93} INFO -     httplib_response = self._make_request(
[2024-06-14T23:28:29.266+0530] {subprocess.py:93} INFO -   File "/home/wsl/airflow_venv/lib/python3.10/site-packages/urllib3/connectionpool.py", line 404, in _make_request
[2024-06-14T23:28:29.267+0530] {subprocess.py:93} INFO -     self._validate_conn(conn)
[2024-06-14T23:28:29.267+0530] {subprocess.py:93} INFO -   File "/home/wsl/airflow_venv/lib/python3.10/site-packages/urllib3/connectionpool.py", line 1058, in _validate_conn
[2024-06-14T23:28:29.268+0530] {subprocess.py:93} INFO -     conn.connect()
[2024-06-14T23:28:29.269+0530] {subprocess.py:93} INFO -   File "/home/wsl/airflow_venv/lib/python3.10/site-packages/urllib3/connection.py", line 363, in connect
[2024-06-14T23:28:29.269+0530] {subprocess.py:93} INFO -     self.sock = conn = self._new_conn()
[2024-06-14T23:28:29.270+0530] {subprocess.py:93} INFO -   File "/home/wsl/airflow_venv/lib/python3.10/site-packages/urllib3/connection.py", line 186, in _new_conn
[2024-06-14T23:28:29.271+0530] {subprocess.py:93} INFO -     raise NewConnectionError(
[2024-06-14T23:28:29.272+0530] {subprocess.py:93} INFO - urllib3.exceptions.NewConnectionError: <urllib3.connection.HTTPSConnection object at 0x7fd07da7a620>: Failed to establish a new connection: [Errno -3] Temporary failure in name resolution
[2024-06-14T23:28:29.273+0530] {subprocess.py:93} INFO - 
[2024-06-14T23:28:29.274+0530] {subprocess.py:93} INFO - During handling of the above exception, another exception occurred:
[2024-06-14T23:28:29.274+0530] {subprocess.py:93} INFO - 
[2024-06-14T23:28:29.275+0530] {subprocess.py:93} INFO - Traceback (most recent call last):
[2024-06-14T23:28:29.275+0530] {subprocess.py:93} INFO -   File "/home/wsl/airflow_venv/lib/python3.10/site-packages/requests/adapters.py", line 486, in send
[2024-06-14T23:28:29.276+0530] {subprocess.py:93} INFO -     resp = conn.urlopen(
[2024-06-14T23:28:29.276+0530] {subprocess.py:93} INFO -   File "/home/wsl/airflow_venv/lib/python3.10/site-packages/urllib3/connectionpool.py", line 799, in urlopen
[2024-06-14T23:28:29.277+0530] {subprocess.py:93} INFO -     retries = retries.increment(
[2024-06-14T23:28:29.278+0530] {subprocess.py:93} INFO -   File "/home/wsl/airflow_venv/lib/python3.10/site-packages/urllib3/util/retry.py", line 592, in increment
[2024-06-14T23:28:29.278+0530] {subprocess.py:93} INFO -     raise MaxRetryError(_pool, url, error or ResponseError(cause))
[2024-06-14T23:28:29.279+0530] {subprocess.py:93} INFO - urllib3.exceptions.MaxRetryError: HTTPSConnectionPool(host='covid-193.p.rapidapi.com', port=443): Max retries exceeded with url: /history?country=usa (Caused by NewConnectionError('<urllib3.connection.HTTPSConnection object at 0x7fd07da7a620>: Failed to establish a new connection: [Errno -3] Temporary failure in name resolution'))
[2024-06-14T23:28:29.280+0530] {subprocess.py:93} INFO - 
[2024-06-14T23:28:29.280+0530] {subprocess.py:93} INFO - During handling of the above exception, another exception occurred:
[2024-06-14T23:28:29.280+0530] {subprocess.py:93} INFO - 
[2024-06-14T23:28:29.280+0530] {subprocess.py:93} INFO - Traceback (most recent call last):
[2024-06-14T23:28:29.281+0530] {subprocess.py:93} INFO -   File "/home/wsl/airflow/dags/Collect Data/covid_19_usa.py", line 12, in <module>
[2024-06-14T23:28:29.281+0530] {subprocess.py:93} INFO -     response = requests.get(url, headers=headers, params=querystring)
[2024-06-14T23:28:29.281+0530] {subprocess.py:93} INFO -   File "/home/wsl/airflow_venv/lib/python3.10/site-packages/requests/api.py", line 73, in get
[2024-06-14T23:28:29.282+0530] {subprocess.py:93} INFO -     return request("get", url, params=params, **kwargs)
[2024-06-14T23:28:29.282+0530] {subprocess.py:93} INFO -   File "/home/wsl/airflow_venv/lib/python3.10/site-packages/requests/api.py", line 59, in request
[2024-06-14T23:28:29.282+0530] {subprocess.py:93} INFO -     return session.request(method=method, url=url, **kwargs)
[2024-06-14T23:28:29.283+0530] {subprocess.py:93} INFO -   File "/home/wsl/airflow_venv/lib/python3.10/site-packages/requests/sessions.py", line 589, in request
[2024-06-14T23:28:29.283+0530] {subprocess.py:93} INFO -     resp = self.send(prep, **send_kwargs)
[2024-06-14T23:28:29.283+0530] {subprocess.py:93} INFO -   File "/home/wsl/airflow_venv/lib/python3.10/site-packages/requests/sessions.py", line 703, in send
[2024-06-14T23:28:29.284+0530] {subprocess.py:93} INFO -     r = adapter.send(request, **kwargs)
[2024-06-14T23:28:29.284+0530] {subprocess.py:93} INFO -   File "/home/wsl/airflow_venv/lib/python3.10/site-packages/requests/adapters.py", line 519, in send
[2024-06-14T23:28:29.284+0530] {subprocess.py:93} INFO -     raise ConnectionError(e, request=request)
[2024-06-14T23:28:29.285+0530] {subprocess.py:93} INFO - requests.exceptions.ConnectionError: HTTPSConnectionPool(host='covid-193.p.rapidapi.com', port=443): Max retries exceeded with url: /history?country=usa (Caused by NewConnectionError('<urllib3.connection.HTTPSConnection object at 0x7fd07da7a620>: Failed to establish a new connection: [Errno -3] Temporary failure in name resolution'))
[2024-06-14T23:28:29.318+0530] {subprocess.py:97} INFO - Command exited with return code 1
[2024-06-14T23:28:29.319+0530] {taskinstance.py:441} INFO - ::group::Post task execution logs
[2024-06-14T23:28:29.340+0530] {taskinstance.py:2890} ERROR - Task failed with exception
Traceback (most recent call last):
  File "/home/wsl/airflow_venv/lib/python3.10/site-packages/airflow/models/taskinstance.py", line 465, in _execute_task
    result = _execute_callable(context=context, **execute_callable_kwargs)
  File "/home/wsl/airflow_venv/lib/python3.10/site-packages/airflow/models/taskinstance.py", line 432, in _execute_callable
    return execute_callable(context=context, **execute_callable_kwargs)
  File "/home/wsl/airflow_venv/lib/python3.10/site-packages/airflow/models/baseoperator.py", line 400, in wrapper
    return func(self, *args, **kwargs)
  File "/home/wsl/airflow_venv/lib/python3.10/site-packages/airflow/operators/bash.py", line 243, in execute
    raise AirflowException(
airflow.exceptions.AirflowException: Bash command failed. The command returned a non-zero exit code 1.
[2024-06-14T23:28:29.348+0530] {taskinstance.py:1205} INFO - Marking task as UP_FOR_RETRY. dag_id=my_data_pipeline_dag, task_id=collect_data_1, execution_date=20240614T175813, start_date=20240614T175818, end_date=20240614T175829
[2024-06-14T23:28:29.386+0530] {standard_task_runner.py:110} ERROR - Failed to execute job 92 for task collect_data_1 (Bash command failed. The command returned a non-zero exit code 1.; 14232)
[2024-06-14T23:28:29.407+0530] {local_task_job_runner.py:240} INFO - Task exited with return code 1
[2024-06-14T23:28:29.449+0530] {taskinstance.py:3482} INFO - 0 downstream tasks scheduled from follow-on schedule check
[2024-06-14T23:28:29.451+0530] {local_task_job_runner.py:222} INFO - ::endgroup::
