[2024-06-14T20:14:03.196+0530] {processor.py:161} INFO - Started process (PID=90891) to work on /home/wsl/airflow/dags/Collect Data/eindex.py
[2024-06-14T20:14:03.197+0530] {processor.py:830} INFO - Processing file /home/wsl/airflow/dags/Collect Data/eindex.py for tasks to queue
[2024-06-14T20:14:03.198+0530] {logging_mixin.py:188} INFO - [2024-06-14T20:14:03.198+0530] {dagbag.py:540} INFO - Filling up the DagBag from /home/wsl/airflow/dags/Collect Data/eindex.py
[2024-06-14T20:14:03.790+0530] {logging_mixin.py:188} INFO - [2024-06-14T20:14:03.789+0530] {dagbag.py:350} ERROR - Failed to import: /home/wsl/airflow/dags/Collect Data/eindex.py
Traceback (most recent call last):
  File "/home/wsl/airflow_venv/lib/python3.10/site-packages/airflow/models/dagbag.py", line 346, in parse
    loader.exec_module(new_module)
  File "<frozen importlib._bootstrap_external>", line 883, in exec_module
  File "<frozen importlib._bootstrap>", line 241, in _call_with_frames_removed
  File "/home/wsl/airflow/dags/Collect Data/eindex.py", line 5, in <module>
    df = pd.read_parquet('/home/wsl/airflow/dags/Collect Data/world.parquet')
  File "/home/wsl/airflow_venv/lib/python3.10/site-packages/pandas/io/parquet.py", line 651, in read_parquet
    impl = get_engine(engine)
  File "/home/wsl/airflow_venv/lib/python3.10/site-packages/pandas/io/parquet.py", line 67, in get_engine
    raise ImportError(
ImportError: Unable to find a usable engine; tried using: 'pyarrow', 'fastparquet'.
A suitable version of pyarrow or fastparquet is required for parquet support.
Trying to import the above resulted in these errors:
 - Missing optional dependency 'pyarrow'. pyarrow is required for parquet support. Use pip or conda to install pyarrow.
 - Missing optional dependency 'fastparquet'. fastparquet is required for parquet support. Use pip or conda to install fastparquet.
[2024-06-14T20:14:03.790+0530] {processor.py:842} WARNING - No viable dags retrieved from /home/wsl/airflow/dags/Collect Data/eindex.py
[2024-06-14T20:14:04.679+0530] {processor.py:183} INFO - Processing /home/wsl/airflow/dags/Collect Data/eindex.py took 1.488 seconds
[2024-06-14T20:14:45.084+0530] {processor.py:161} INFO - Started process (PID=91503) to work on /home/wsl/airflow/dags/Collect Data/eindex.py
[2024-06-14T20:14:45.085+0530] {processor.py:830} INFO - Processing file /home/wsl/airflow/dags/Collect Data/eindex.py for tasks to queue
[2024-06-14T20:14:45.087+0530] {logging_mixin.py:188} INFO - [2024-06-14T20:14:45.086+0530] {dagbag.py:540} INFO - Filling up the DagBag from /home/wsl/airflow/dags/Collect Data/eindex.py
[2024-06-14T20:14:45.725+0530] {logging_mixin.py:188} INFO - [2024-06-14T20:14:45.723+0530] {dagbag.py:350} ERROR - Failed to import: /home/wsl/airflow/dags/Collect Data/eindex.py
Traceback (most recent call last):
  File "/home/wsl/airflow_venv/lib/python3.10/site-packages/airflow/models/dagbag.py", line 346, in parse
    loader.exec_module(new_module)
  File "<frozen importlib._bootstrap_external>", line 883, in exec_module
  File "<frozen importlib._bootstrap>", line 241, in _call_with_frames_removed
  File "/home/wsl/airflow/dags/Collect Data/eindex.py", line 5, in <module>
    df = pd.read_parquet('/home/wsl/airflow/dags/Collect Data/world.parquet')
  File "/home/wsl/airflow_venv/lib/python3.10/site-packages/pandas/io/parquet.py", line 651, in read_parquet
    impl = get_engine(engine)
  File "/home/wsl/airflow_venv/lib/python3.10/site-packages/pandas/io/parquet.py", line 67, in get_engine
    raise ImportError(
ImportError: Unable to find a usable engine; tried using: 'pyarrow', 'fastparquet'.
A suitable version of pyarrow or fastparquet is required for parquet support.
Trying to import the above resulted in these errors:
 - Missing optional dependency 'pyarrow'. pyarrow is required for parquet support. Use pip or conda to install pyarrow.
 - Missing optional dependency 'fastparquet'. fastparquet is required for parquet support. Use pip or conda to install fastparquet.
[2024-06-14T20:14:45.725+0530] {processor.py:842} WARNING - No viable dags retrieved from /home/wsl/airflow/dags/Collect Data/eindex.py
[2024-06-14T20:14:45.742+0530] {processor.py:183} INFO - Processing /home/wsl/airflow/dags/Collect Data/eindex.py took 0.665 seconds
[2024-06-14T20:16:15.175+0530] {processor.py:161} INFO - Started process (PID=92999) to work on /home/wsl/airflow/dags/Collect Data/eindex.py
[2024-06-14T20:16:15.177+0530] {processor.py:830} INFO - Processing file /home/wsl/airflow/dags/Collect Data/eindex.py for tasks to queue
[2024-06-14T20:16:15.179+0530] {logging_mixin.py:188} INFO - [2024-06-14T20:16:15.178+0530] {dagbag.py:540} INFO - Filling up the DagBag from /home/wsl/airflow/dags/Collect Data/eindex.py
[2024-06-14T20:16:18.103+0530] {logging_mixin.py:188} INFO - [2024-06-14T20:16:18.103+0530] {_transport.py:372} INFO - HEAD http://localhost:9200/world [status:N/A duration:0.001s]
[2024-06-14T20:16:18.104+0530] {logging_mixin.py:188} INFO - [2024-06-14T20:16:18.104+0530] {_node_pool.py:249} WARNING - Node <Urllib3HttpNode(http://localhost:9200)> has failed for 1 times in a row, putting on 1 second timeout
[2024-06-14T20:16:18.252+0530] {logging_mixin.py:188} INFO - [2024-06-14T20:16:18.104+0530] {_transport.py:415} WARNING - Retrying request after failure (attempt 0 of 3)
Traceback (most recent call last):
  File "/home/wsl/airflow_venv/lib/python3.10/site-packages/elastic_transport/_transport.py", line 342, in perform_request
    resp = node.perform_request(
  File "/home/wsl/airflow_venv/lib/python3.10/site-packages/elastic_transport/_node/_http_urllib3.py", line 202, in perform_request
    raise err from None
elastic_transport.ConnectionError: Connection error caused by: NewConnectionError(<urllib3.connection.HTTPConnection object at 0x7f0bfac2e0b0>: Failed to establish a new connection: [Errno 111] Connection refused)
[2024-06-14T20:16:18.254+0530] {logging_mixin.py:188} INFO - [2024-06-14T20:16:18.254+0530] {_transport.py:372} INFO - HEAD http://localhost:9200/world [status:N/A duration:0.001s]
[2024-06-14T20:16:18.255+0530] {logging_mixin.py:188} INFO - [2024-06-14T20:16:18.255+0530] {_node_pool.py:249} WARNING - Node <Urllib3HttpNode(http://localhost:9200)> has failed for 2 times in a row, putting on 2 second timeout
[2024-06-14T20:16:18.256+0530] {logging_mixin.py:188} INFO - [2024-06-14T20:16:18.256+0530] {_transport.py:415} WARNING - Retrying request after failure (attempt 1 of 3)
Traceback (most recent call last):
  File "/home/wsl/airflow_venv/lib/python3.10/site-packages/elastic_transport/_transport.py", line 342, in perform_request
    resp = node.perform_request(
  File "/home/wsl/airflow_venv/lib/python3.10/site-packages/elastic_transport/_node/_http_urllib3.py", line 202, in perform_request
    raise err from None
elastic_transport.ConnectionError: Connection error caused by: NewConnectionError(<urllib3.connection.HTTPConnection object at 0x7f0bfac2e3e0>: Failed to establish a new connection: [Errno 111] Connection refused)
[2024-06-14T20:16:18.259+0530] {logging_mixin.py:188} INFO - [2024-06-14T20:16:18.258+0530] {_transport.py:372} INFO - HEAD http://localhost:9200/world [status:N/A duration:0.001s]
[2024-06-14T20:16:18.259+0530] {logging_mixin.py:188} INFO - [2024-06-14T20:16:18.259+0530] {_node_pool.py:249} WARNING - Node <Urllib3HttpNode(http://localhost:9200)> has failed for 3 times in a row, putting on 4 second timeout
[2024-06-14T20:16:18.260+0530] {logging_mixin.py:188} INFO - [2024-06-14T20:16:18.260+0530] {_transport.py:415} WARNING - Retrying request after failure (attempt 2 of 3)
Traceback (most recent call last):
  File "/home/wsl/airflow_venv/lib/python3.10/site-packages/elastic_transport/_transport.py", line 342, in perform_request
    resp = node.perform_request(
  File "/home/wsl/airflow_venv/lib/python3.10/site-packages/elastic_transport/_node/_http_urllib3.py", line 202, in perform_request
    raise err from None
elastic_transport.ConnectionError: Connection error caused by: NewConnectionError(<urllib3.connection.HTTPConnection object at 0x7f0bfac2e6e0>: Failed to establish a new connection: [Errno 111] Connection refused)
[2024-06-14T20:16:18.262+0530] {logging_mixin.py:188} INFO - [2024-06-14T20:16:18.262+0530] {_transport.py:372} INFO - HEAD http://localhost:9200/world [status:N/A duration:0.001s]
[2024-06-14T20:16:18.263+0530] {logging_mixin.py:188} INFO - [2024-06-14T20:16:18.262+0530] {_node_pool.py:249} WARNING - Node <Urllib3HttpNode(http://localhost:9200)> has failed for 4 times in a row, putting on 8 second timeout
[2024-06-14T20:16:18.707+0530] {logging_mixin.py:188} INFO - [2024-06-14T20:16:18.263+0530] {dagbag.py:350} ERROR - Failed to import: /home/wsl/airflow/dags/Collect Data/eindex.py
Traceback (most recent call last):
  File "/home/wsl/airflow_venv/lib/python3.10/site-packages/airflow/models/dagbag.py", line 346, in parse
    loader.exec_module(new_module)
  File "<frozen importlib._bootstrap_external>", line 883, in exec_module
  File "<frozen importlib._bootstrap>", line 241, in _call_with_frames_removed
  File "/home/wsl/airflow/dags/Collect Data/eindex.py", line 28, in <module>
    if not es.indices.exists(index=index_name):
  File "/home/wsl/airflow_venv/lib/python3.10/site-packages/elasticsearch/_sync/client/utils.py", line 446, in wrapped
    return api(*args, **kwargs)
  File "/home/wsl/airflow_venv/lib/python3.10/site-packages/elasticsearch/_sync/client/indices.py", line 1238, in exists
    return self.perform_request(  # type: ignore[return-value]
  File "/home/wsl/airflow_venv/lib/python3.10/site-packages/elasticsearch/_sync/client/_base.py", line 423, in perform_request
    return self._client.perform_request(
  File "/home/wsl/airflow_venv/lib/python3.10/site-packages/elasticsearch/_sync/client/_base.py", line 271, in perform_request
    response = self._perform_request(
  File "/home/wsl/airflow_venv/lib/python3.10/site-packages/elasticsearch/_sync/client/_base.py", line 316, in _perform_request
    meta, resp_body = self.transport.perform_request(
  File "/home/wsl/airflow_venv/lib/python3.10/site-packages/elastic_transport/_transport.py", line 342, in perform_request
    resp = node.perform_request(
  File "/home/wsl/airflow_venv/lib/python3.10/site-packages/elastic_transport/_node/_http_urllib3.py", line 202, in perform_request
    raise err from None
elastic_transport.ConnectionError: Connection error caused by: ConnectionError(Connection error caused by: NewConnectionError(<urllib3.connection.HTTPConnection object at 0x7f0bfac2e0b0>: Failed to establish a new connection: [Errno 111] Connection refused))
[2024-06-14T20:16:18.708+0530] {processor.py:842} WARNING - No viable dags retrieved from /home/wsl/airflow/dags/Collect Data/eindex.py
[2024-06-14T20:16:21.121+0530] {processor.py:183} INFO - Processing /home/wsl/airflow/dags/Collect Data/eindex.py took 5.994 seconds
[2024-06-14T20:18:17.416+0530] {processor.py:161} INFO - Started process (PID=94701) to work on /home/wsl/airflow/dags/Collect Data/eindex.py
[2024-06-14T20:18:17.417+0530] {processor.py:830} INFO - Processing file /home/wsl/airflow/dags/Collect Data/eindex.py for tasks to queue
[2024-06-14T20:18:17.418+0530] {logging_mixin.py:188} INFO - [2024-06-14T20:18:17.418+0530] {dagbag.py:540} INFO - Filling up the DagBag from /home/wsl/airflow/dags/Collect Data/eindex.py
[2024-06-14T20:18:18.236+0530] {logging_mixin.py:188} INFO - [2024-06-14T20:18:18.232+0530] {dagbag.py:350} ERROR - Failed to import: /home/wsl/airflow/dags/Collect Data/eindex.py
Traceback (most recent call last):
  File "/home/wsl/airflow_venv/lib/python3.10/site-packages/airflow/models/dagbag.py", line 346, in parse
    loader.exec_module(new_module)
  File "<frozen importlib._bootstrap_external>", line 883, in exec_module
  File "<frozen importlib._bootstrap>", line 241, in _call_with_frames_removed
  File "/home/wsl/airflow/dags/Collect Data/eindex.py", line 8, in <module>
    df = df[['date', 'continent', 'location', 'total_cases', 'total_deaths']]
  File "/home/wsl/airflow_venv/lib/python3.10/site-packages/pandas/core/frame.py", line 4108, in __getitem__
    indexer = self.columns._get_indexer_strict(key, "columns")[1]
  File "/home/wsl/airflow_venv/lib/python3.10/site-packages/pandas/core/indexes/base.py", line 6200, in _get_indexer_strict
    self._raise_if_missing(keyarr, indexer, axis_name)
  File "/home/wsl/airflow_venv/lib/python3.10/site-packages/pandas/core/indexes/base.py", line 6252, in _raise_if_missing
    raise KeyError(f"{not_found} not in index")
KeyError: "['location', 'total_cases', 'total_deaths'] not in index"
[2024-06-14T20:18:18.237+0530] {processor.py:842} WARNING - No viable dags retrieved from /home/wsl/airflow/dags/Collect Data/eindex.py
[2024-06-14T20:18:18.262+0530] {processor.py:183} INFO - Processing /home/wsl/airflow/dags/Collect Data/eindex.py took 0.855 seconds
[2024-06-14T20:19:43.860+0530] {processor.py:161} INFO - Started process (PID=96022) to work on /home/wsl/airflow/dags/Collect Data/eindex.py
[2024-06-14T20:19:43.862+0530] {processor.py:830} INFO - Processing file /home/wsl/airflow/dags/Collect Data/eindex.py for tasks to queue
[2024-06-14T20:19:43.864+0530] {logging_mixin.py:188} INFO - [2024-06-14T20:19:43.864+0530] {dagbag.py:540} INFO - Filling up the DagBag from /home/wsl/airflow/dags/Collect Data/eindex.py
[2024-06-14T20:19:44.580+0530] {logging_mixin.py:188} INFO - Columns in DataFrame: Index(['date', 'continent', 'country', 'cases', 'deaths', 'idx'], dtype='object')
[2024-06-14T20:19:44.735+0530] {logging_mixin.py:188} INFO - [2024-06-14T20:19:44.735+0530] {_transport.py:372} INFO - HEAD http://localhost:9200/world_data [status:N/A duration:0.001s]
[2024-06-14T20:19:44.735+0530] {logging_mixin.py:188} INFO - [2024-06-14T20:19:44.735+0530] {_node_pool.py:249} WARNING - Node <Urllib3HttpNode(http://localhost:9200)> has failed for 1 times in a row, putting on 1 second timeout
[2024-06-14T20:19:44.736+0530] {logging_mixin.py:188} INFO - [2024-06-14T20:19:44.736+0530] {_transport.py:415} WARNING - Retrying request after failure (attempt 0 of 3)
Traceback (most recent call last):
  File "/home/wsl/airflow_venv/lib/python3.10/site-packages/elastic_transport/_transport.py", line 342, in perform_request
    resp = node.perform_request(
  File "/home/wsl/airflow_venv/lib/python3.10/site-packages/elastic_transport/_node/_http_urllib3.py", line 202, in perform_request
    raise err from None
elastic_transport.ConnectionError: Connection error caused by: NewConnectionError(<urllib3.connection.HTTPConnection object at 0x7f0bfac3dfc0>: Failed to establish a new connection: [Errno 111] Connection refused)
[2024-06-14T20:19:44.737+0530] {logging_mixin.py:188} INFO - [2024-06-14T20:19:44.737+0530] {_transport.py:372} INFO - HEAD http://localhost:9200/world_data [status:N/A duration:0.000s]
[2024-06-14T20:19:44.737+0530] {logging_mixin.py:188} INFO - [2024-06-14T20:19:44.737+0530] {_node_pool.py:249} WARNING - Node <Urllib3HttpNode(http://localhost:9200)> has failed for 2 times in a row, putting on 2 second timeout
[2024-06-14T20:19:44.737+0530] {logging_mixin.py:188} INFO - [2024-06-14T20:19:44.737+0530] {_transport.py:415} WARNING - Retrying request after failure (attempt 1 of 3)
Traceback (most recent call last):
  File "/home/wsl/airflow_venv/lib/python3.10/site-packages/elastic_transport/_transport.py", line 342, in perform_request
    resp = node.perform_request(
  File "/home/wsl/airflow_venv/lib/python3.10/site-packages/elastic_transport/_node/_http_urllib3.py", line 202, in perform_request
    raise err from None
elastic_transport.ConnectionError: Connection error caused by: NewConnectionError(<urllib3.connection.HTTPConnection object at 0x7f0bfac3e3b0>: Failed to establish a new connection: [Errno 111] Connection refused)
[2024-06-14T20:19:44.738+0530] {logging_mixin.py:188} INFO - [2024-06-14T20:19:44.738+0530] {_transport.py:372} INFO - HEAD http://localhost:9200/world_data [status:N/A duration:0.000s]
[2024-06-14T20:19:44.739+0530] {logging_mixin.py:188} INFO - [2024-06-14T20:19:44.738+0530] {_node_pool.py:249} WARNING - Node <Urllib3HttpNode(http://localhost:9200)> has failed for 3 times in a row, putting on 4 second timeout
[2024-06-14T20:19:44.739+0530] {logging_mixin.py:188} INFO - [2024-06-14T20:19:44.739+0530] {_transport.py:415} WARNING - Retrying request after failure (attempt 2 of 3)
Traceback (most recent call last):
  File "/home/wsl/airflow_venv/lib/python3.10/site-packages/elastic_transport/_transport.py", line 342, in perform_request
    resp = node.perform_request(
  File "/home/wsl/airflow_venv/lib/python3.10/site-packages/elastic_transport/_node/_http_urllib3.py", line 202, in perform_request
    raise err from None
elastic_transport.ConnectionError: Connection error caused by: NewConnectionError(<urllib3.connection.HTTPConnection object at 0x7f0bfac3e650>: Failed to establish a new connection: [Errno 111] Connection refused)
[2024-06-14T20:19:44.741+0530] {logging_mixin.py:188} INFO - [2024-06-14T20:19:44.740+0530] {_transport.py:372} INFO - HEAD http://localhost:9200/world_data [status:N/A duration:0.001s]
[2024-06-14T20:19:44.741+0530] {logging_mixin.py:188} INFO - [2024-06-14T20:19:44.741+0530] {_node_pool.py:249} WARNING - Node <Urllib3HttpNode(http://localhost:9200)> has failed for 4 times in a row, putting on 8 second timeout
[2024-06-14T20:19:44.743+0530] {logging_mixin.py:188} INFO - [2024-06-14T20:19:44.741+0530] {dagbag.py:350} ERROR - Failed to import: /home/wsl/airflow/dags/Collect Data/eindex.py
Traceback (most recent call last):
  File "/home/wsl/airflow_venv/lib/python3.10/site-packages/airflow/models/dagbag.py", line 346, in parse
    loader.exec_module(new_module)
  File "<frozen importlib._bootstrap_external>", line 883, in exec_module
  File "<frozen importlib._bootstrap>", line 241, in _call_with_frames_removed
  File "/home/wsl/airflow/dags/Collect Data/eindex.py", line 36, in <module>
    if not es.indices.exists(index=index_name):
  File "/home/wsl/airflow_venv/lib/python3.10/site-packages/elasticsearch/_sync/client/utils.py", line 446, in wrapped
    return api(*args, **kwargs)
  File "/home/wsl/airflow_venv/lib/python3.10/site-packages/elasticsearch/_sync/client/indices.py", line 1238, in exists
    return self.perform_request(  # type: ignore[return-value]
  File "/home/wsl/airflow_venv/lib/python3.10/site-packages/elasticsearch/_sync/client/_base.py", line 423, in perform_request
    return self._client.perform_request(
  File "/home/wsl/airflow_venv/lib/python3.10/site-packages/elasticsearch/_sync/client/_base.py", line 271, in perform_request
    response = self._perform_request(
  File "/home/wsl/airflow_venv/lib/python3.10/site-packages/elasticsearch/_sync/client/_base.py", line 316, in _perform_request
    meta, resp_body = self.transport.perform_request(
  File "/home/wsl/airflow_venv/lib/python3.10/site-packages/elastic_transport/_transport.py", line 342, in perform_request
    resp = node.perform_request(
  File "/home/wsl/airflow_venv/lib/python3.10/site-packages/elastic_transport/_node/_http_urllib3.py", line 202, in perform_request
    raise err from None
elastic_transport.ConnectionError: Connection error caused by: ConnectionError(Connection error caused by: NewConnectionError(<urllib3.connection.HTTPConnection object at 0x7f0bfac3dfc0>: Failed to establish a new connection: [Errno 111] Connection refused))
[2024-06-14T20:19:44.743+0530] {processor.py:842} WARNING - No viable dags retrieved from /home/wsl/airflow/dags/Collect Data/eindex.py
[2024-06-14T20:19:44.761+0530] {processor.py:183} INFO - Processing /home/wsl/airflow/dags/Collect Data/eindex.py took 0.915 seconds
[2024-06-14T20:21:31.826+0530] {processor.py:161} INFO - Started process (PID=97248) to work on /home/wsl/airflow/dags/Collect Data/eindex.py
[2024-06-14T20:21:31.829+0530] {processor.py:830} INFO - Processing file /home/wsl/airflow/dags/Collect Data/eindex.py for tasks to queue
[2024-06-14T20:21:31.830+0530] {logging_mixin.py:188} INFO - [2024-06-14T20:21:31.830+0530] {dagbag.py:540} INFO - Filling up the DagBag from /home/wsl/airflow/dags/Collect Data/eindex.py
[2024-06-14T20:21:32.829+0530] {logging_mixin.py:188} INFO - Columns in DataFrame: Index(['date', 'continent', 'country', 'cases', 'deaths', 'idx'], dtype='object')
[2024-06-14T20:21:32.993+0530] {logging_mixin.py:188} INFO - [2024-06-14T20:21:32.993+0530] {_transport.py:372} INFO - HEAD http://localhost:9200/world_data [status:N/A duration:0.001s]
[2024-06-14T20:21:32.994+0530] {logging_mixin.py:188} INFO - [2024-06-14T20:21:32.994+0530] {_node_pool.py:249} WARNING - Node <Urllib3HttpNode(http://localhost:9200)> has failed for 1 times in a row, putting on 1 second timeout
[2024-06-14T20:21:32.995+0530] {logging_mixin.py:188} INFO - [2024-06-14T20:21:32.994+0530] {_transport.py:415} WARNING - Retrying request after failure (attempt 0 of 3)
Traceback (most recent call last):
  File "/home/wsl/airflow_venv/lib/python3.10/site-packages/elastic_transport/_transport.py", line 342, in perform_request
    resp = node.perform_request(
  File "/home/wsl/airflow_venv/lib/python3.10/site-packages/elastic_transport/_node/_http_urllib3.py", line 202, in perform_request
    raise err from None
elastic_transport.ConnectionError: Connection error caused by: NewConnectionError(<urllib3.connection.HTTPConnection object at 0x7f0bfb441ff0>: Failed to establish a new connection: [Errno 111] Connection refused)
[2024-06-14T20:21:32.995+0530] {logging_mixin.py:188} INFO - [2024-06-14T20:21:32.995+0530] {_transport.py:372} INFO - HEAD http://localhost:9200/world_data [status:N/A duration:0.000s]
[2024-06-14T20:21:32.996+0530] {logging_mixin.py:188} INFO - [2024-06-14T20:21:32.996+0530] {_node_pool.py:249} WARNING - Node <Urllib3HttpNode(http://localhost:9200)> has failed for 2 times in a row, putting on 2 second timeout
[2024-06-14T20:21:32.996+0530] {logging_mixin.py:188} INFO - [2024-06-14T20:21:32.996+0530] {_transport.py:415} WARNING - Retrying request after failure (attempt 1 of 3)
Traceback (most recent call last):
  File "/home/wsl/airflow_venv/lib/python3.10/site-packages/elastic_transport/_transport.py", line 342, in perform_request
    resp = node.perform_request(
  File "/home/wsl/airflow_venv/lib/python3.10/site-packages/elastic_transport/_node/_http_urllib3.py", line 202, in perform_request
    raise err from None
elastic_transport.ConnectionError: Connection error caused by: NewConnectionError(<urllib3.connection.HTTPConnection object at 0x7f0bfb4423e0>: Failed to establish a new connection: [Errno 111] Connection refused)
[2024-06-14T20:21:32.997+0530] {logging_mixin.py:188} INFO - [2024-06-14T20:21:32.997+0530] {_transport.py:372} INFO - HEAD http://localhost:9200/world_data [status:N/A duration:0.001s]
[2024-06-14T20:21:32.997+0530] {logging_mixin.py:188} INFO - [2024-06-14T20:21:32.997+0530] {_node_pool.py:249} WARNING - Node <Urllib3HttpNode(http://localhost:9200)> has failed for 3 times in a row, putting on 4 second timeout
[2024-06-14T20:21:32.998+0530] {logging_mixin.py:188} INFO - [2024-06-14T20:21:32.998+0530] {_transport.py:415} WARNING - Retrying request after failure (attempt 2 of 3)
Traceback (most recent call last):
  File "/home/wsl/airflow_venv/lib/python3.10/site-packages/elastic_transport/_transport.py", line 342, in perform_request
    resp = node.perform_request(
  File "/home/wsl/airflow_venv/lib/python3.10/site-packages/elastic_transport/_node/_http_urllib3.py", line 202, in perform_request
    raise err from None
elastic_transport.ConnectionError: Connection error caused by: NewConnectionError(<urllib3.connection.HTTPConnection object at 0x7f0bfb442680>: Failed to establish a new connection: [Errno 111] Connection refused)
[2024-06-14T20:21:32.999+0530] {logging_mixin.py:188} INFO - [2024-06-14T20:21:32.998+0530] {_transport.py:372} INFO - HEAD http://localhost:9200/world_data [status:N/A duration:0.000s]
[2024-06-14T20:21:32.999+0530] {logging_mixin.py:188} INFO - [2024-06-14T20:21:32.999+0530] {_node_pool.py:249} WARNING - Node <Urllib3HttpNode(http://localhost:9200)> has failed for 4 times in a row, putting on 8 second timeout
[2024-06-14T20:21:33.001+0530] {logging_mixin.py:188} INFO - [2024-06-14T20:21:32.999+0530] {dagbag.py:350} ERROR - Failed to import: /home/wsl/airflow/dags/Collect Data/eindex.py
Traceback (most recent call last):
  File "/home/wsl/airflow_venv/lib/python3.10/site-packages/airflow/models/dagbag.py", line 346, in parse
    loader.exec_module(new_module)
  File "<frozen importlib._bootstrap_external>", line 883, in exec_module
  File "<frozen importlib._bootstrap>", line 241, in _call_with_frames_removed
  File "/home/wsl/airflow/dags/Collect Data/eindex.py", line 36, in <module>
    if not es.indices.exists(index=index_name):
  File "/home/wsl/airflow_venv/lib/python3.10/site-packages/elasticsearch/_sync/client/utils.py", line 446, in wrapped
    return api(*args, **kwargs)
  File "/home/wsl/airflow_venv/lib/python3.10/site-packages/elasticsearch/_sync/client/indices.py", line 1238, in exists
    return self.perform_request(  # type: ignore[return-value]
  File "/home/wsl/airflow_venv/lib/python3.10/site-packages/elasticsearch/_sync/client/_base.py", line 423, in perform_request
    return self._client.perform_request(
  File "/home/wsl/airflow_venv/lib/python3.10/site-packages/elasticsearch/_sync/client/_base.py", line 271, in perform_request
    response = self._perform_request(
  File "/home/wsl/airflow_venv/lib/python3.10/site-packages/elasticsearch/_sync/client/_base.py", line 316, in _perform_request
    meta, resp_body = self.transport.perform_request(
  File "/home/wsl/airflow_venv/lib/python3.10/site-packages/elastic_transport/_transport.py", line 342, in perform_request
    resp = node.perform_request(
  File "/home/wsl/airflow_venv/lib/python3.10/site-packages/elastic_transport/_node/_http_urllib3.py", line 202, in perform_request
    raise err from None
elastic_transport.ConnectionError: Connection error caused by: ConnectionError(Connection error caused by: NewConnectionError(<urllib3.connection.HTTPConnection object at 0x7f0bfb441ff0>: Failed to establish a new connection: [Errno 111] Connection refused))
[2024-06-14T20:21:33.001+0530] {processor.py:842} WARNING - No viable dags retrieved from /home/wsl/airflow/dags/Collect Data/eindex.py
[2024-06-14T20:21:40.410+0530] {processor.py:183} INFO - Processing /home/wsl/airflow/dags/Collect Data/eindex.py took 8.618 seconds
[2024-06-14T20:23:56.824+0530] {processor.py:161} INFO - Started process (PID=98600) to work on /home/wsl/airflow/dags/Collect Data/eindex.py
[2024-06-14T20:23:56.828+0530] {processor.py:830} INFO - Processing file /home/wsl/airflow/dags/Collect Data/eindex.py for tasks to queue
[2024-06-14T20:23:56.830+0530] {logging_mixin.py:188} INFO - [2024-06-14T20:23:56.829+0530] {dagbag.py:540} INFO - Filling up the DagBag from /home/wsl/airflow/dags/Collect Data/eindex.py
[2024-06-14T20:23:58.835+0530] {logging_mixin.py:188} INFO - Columns in DataFrame: Index(['date', 'continent', 'country', 'cases', 'deaths', 'idx'], dtype='object')
[2024-06-14T20:23:59.912+0530] {logging_mixin.py:188} INFO - [2024-06-14T20:23:59.912+0530] {_transport.py:372} INFO - HEAD http://localhost:9200/world_data [status:N/A duration:0.806s]
[2024-06-14T20:23:59.913+0530] {logging_mixin.py:188} INFO - [2024-06-14T20:23:59.913+0530] {_node_pool.py:249} WARNING - Node <Urllib3HttpNode(http://localhost:9200)> has failed for 1 times in a row, putting on 1 second timeout
[2024-06-14T20:23:59.915+0530] {logging_mixin.py:188} INFO - [2024-06-14T20:23:59.913+0530] {_transport.py:415} WARNING - Retrying request after failure (attempt 0 of 3)
Traceback (most recent call last):
  File "/home/wsl/airflow_venv/lib/python3.10/site-packages/elastic_transport/_transport.py", line 342, in perform_request
    resp = node.perform_request(
  File "/home/wsl/airflow_venv/lib/python3.10/site-packages/elastic_transport/_node/_http_urllib3.py", line 202, in perform_request
    raise err from None
elastic_transport.ConnectionError: Connection error caused by: NewConnectionError(<urllib3.connection.HTTPConnection object at 0x7f0bfb43dff0>: Failed to establish a new connection: [Errno 111] Connection refused)
[2024-06-14T20:23:59.917+0530] {logging_mixin.py:188} INFO - [2024-06-14T20:23:59.916+0530] {_transport.py:372} INFO - HEAD http://localhost:9200/world_data [status:N/A duration:0.001s]
[2024-06-14T20:23:59.917+0530] {logging_mixin.py:188} INFO - [2024-06-14T20:23:59.917+0530] {_node_pool.py:249} WARNING - Node <Urllib3HttpNode(http://localhost:9200)> has failed for 2 times in a row, putting on 2 second timeout
[2024-06-14T20:23:59.918+0530] {logging_mixin.py:188} INFO - [2024-06-14T20:23:59.917+0530] {_transport.py:415} WARNING - Retrying request after failure (attempt 1 of 3)
Traceback (most recent call last):
  File "/home/wsl/airflow_venv/lib/python3.10/site-packages/elastic_transport/_transport.py", line 342, in perform_request
    resp = node.perform_request(
  File "/home/wsl/airflow_venv/lib/python3.10/site-packages/elastic_transport/_node/_http_urllib3.py", line 202, in perform_request
    raise err from None
elastic_transport.ConnectionError: Connection error caused by: NewConnectionError(<urllib3.connection.HTTPConnection object at 0x7f0bfb43e3e0>: Failed to establish a new connection: [Errno 111] Connection refused)
[2024-06-14T20:23:59.919+0530] {logging_mixin.py:188} INFO - [2024-06-14T20:23:59.919+0530] {_transport.py:372} INFO - HEAD http://localhost:9200/world_data [status:N/A duration:0.001s]
[2024-06-14T20:23:59.920+0530] {logging_mixin.py:188} INFO - [2024-06-14T20:23:59.920+0530] {_node_pool.py:249} WARNING - Node <Urllib3HttpNode(http://localhost:9200)> has failed for 3 times in a row, putting on 4 second timeout
[2024-06-14T20:23:59.920+0530] {logging_mixin.py:188} INFO - [2024-06-14T20:23:59.920+0530] {_transport.py:415} WARNING - Retrying request after failure (attempt 2 of 3)
Traceback (most recent call last):
  File "/home/wsl/airflow_venv/lib/python3.10/site-packages/elastic_transport/_transport.py", line 342, in perform_request
    resp = node.perform_request(
  File "/home/wsl/airflow_venv/lib/python3.10/site-packages/elastic_transport/_node/_http_urllib3.py", line 202, in perform_request
    raise err from None
elastic_transport.ConnectionError: Connection error caused by: NewConnectionError(<urllib3.connection.HTTPConnection object at 0x7f0bfb43e680>: Failed to establish a new connection: [Errno 111] Connection refused)
[2024-06-14T20:23:59.922+0530] {logging_mixin.py:188} INFO - [2024-06-14T20:23:59.922+0530] {_transport.py:372} INFO - HEAD http://localhost:9200/world_data [status:N/A duration:0.001s]
[2024-06-14T20:23:59.923+0530] {logging_mixin.py:188} INFO - [2024-06-14T20:23:59.922+0530] {_node_pool.py:249} WARNING - Node <Urllib3HttpNode(http://localhost:9200)> has failed for 4 times in a row, putting on 8 second timeout
[2024-06-14T20:23:59.943+0530] {logging_mixin.py:188} INFO - [2024-06-14T20:23:59.923+0530] {dagbag.py:350} ERROR - Failed to import: /home/wsl/airflow/dags/Collect Data/eindex.py
Traceback (most recent call last):
  File "/home/wsl/airflow_venv/lib/python3.10/site-packages/airflow/models/dagbag.py", line 346, in parse
    loader.exec_module(new_module)
  File "<frozen importlib._bootstrap_external>", line 883, in exec_module
  File "<frozen importlib._bootstrap>", line 241, in _call_with_frames_removed
  File "/home/wsl/airflow/dags/Collect Data/eindex.py", line 36, in <module>
    if not es.indices.exists(index=index_name):
  File "/home/wsl/airflow_venv/lib/python3.10/site-packages/elasticsearch/_sync/client/utils.py", line 446, in wrapped
    return api(*args, **kwargs)
  File "/home/wsl/airflow_venv/lib/python3.10/site-packages/elasticsearch/_sync/client/indices.py", line 1238, in exists
    return self.perform_request(  # type: ignore[return-value]
  File "/home/wsl/airflow_venv/lib/python3.10/site-packages/elasticsearch/_sync/client/_base.py", line 423, in perform_request
    return self._client.perform_request(
  File "/home/wsl/airflow_venv/lib/python3.10/site-packages/elasticsearch/_sync/client/_base.py", line 271, in perform_request
    response = self._perform_request(
  File "/home/wsl/airflow_venv/lib/python3.10/site-packages/elasticsearch/_sync/client/_base.py", line 316, in _perform_request
    meta, resp_body = self.transport.perform_request(
  File "/home/wsl/airflow_venv/lib/python3.10/site-packages/elastic_transport/_transport.py", line 342, in perform_request
    resp = node.perform_request(
  File "/home/wsl/airflow_venv/lib/python3.10/site-packages/elastic_transport/_node/_http_urllib3.py", line 202, in perform_request
    raise err from None
elastic_transport.ConnectionError: Connection error caused by: ConnectionError(Connection error caused by: NewConnectionError(<urllib3.connection.HTTPConnection object at 0x7f0bfb43dff0>: Failed to establish a new connection: [Errno 111] Connection refused))
[2024-06-14T20:23:59.943+0530] {processor.py:842} WARNING - No viable dags retrieved from /home/wsl/airflow/dags/Collect Data/eindex.py
[2024-06-14T20:23:59.981+0530] {processor.py:183} INFO - Processing /home/wsl/airflow/dags/Collect Data/eindex.py took 3.167 seconds
[2024-06-14T23:32:19.482+0530] {processor.py:161} INFO - Started process (PID=16475) to work on /home/wsl/airflow/dags/Collect Data/eindex.py
[2024-06-14T23:32:19.579+0530] {processor.py:830} INFO - Processing file /home/wsl/airflow/dags/Collect Data/eindex.py for tasks to queue
[2024-06-14T23:32:19.581+0530] {logging_mixin.py:188} INFO - [2024-06-14T23:32:19.580+0530] {dagbag.py:540} INFO - Filling up the DagBag from /home/wsl/airflow/dags/Collect Data/eindex.py
[2024-06-14T23:32:29.664+0530] {logging_mixin.py:188} INFO - Columns in DataFrame: Index(['date', 'continent', 'country', 'cases', 'deaths', 'idx'], dtype='object')
[2024-06-14T23:32:30.277+0530] {logging_mixin.py:188} INFO - [2024-06-14T23:32:30.277+0530] {_transport.py:372} INFO - HEAD http://localhost:9200/ [status:N/A duration:0.001s]
[2024-06-14T23:32:30.278+0530] {logging_mixin.py:188} INFO - [2024-06-14T23:32:30.277+0530] {_node_pool.py:249} WARNING - Node <Urllib3HttpNode(http://localhost:9200)> has failed for 1 times in a row, putting on 1 second timeout
[2024-06-14T23:32:30.298+0530] {logging_mixin.py:188} INFO - [2024-06-14T23:32:30.278+0530] {_transport.py:415} WARNING - Retrying request after failure (attempt 0 of 3)
Traceback (most recent call last):
  File "/home/wsl/airflow_venv/lib/python3.10/site-packages/elastic_transport/_transport.py", line 342, in perform_request
    resp = node.perform_request(
  File "/home/wsl/airflow_venv/lib/python3.10/site-packages/elastic_transport/_node/_http_urllib3.py", line 202, in perform_request
    raise err from None
elastic_transport.ConnectionError: Connection error caused by: NewConnectionError(<urllib3.connection.HTTPConnection object at 0x7f306c2a54e0>: Failed to establish a new connection: [Errno 111] Connection refused)
[2024-06-14T23:32:30.299+0530] {logging_mixin.py:188} INFO - [2024-06-14T23:32:30.299+0530] {_transport.py:372} INFO - HEAD http://localhost:9200/ [status:N/A duration:0.001s]
[2024-06-14T23:32:30.300+0530] {logging_mixin.py:188} INFO - [2024-06-14T23:32:30.300+0530] {_node_pool.py:249} WARNING - Node <Urllib3HttpNode(http://localhost:9200)> has failed for 2 times in a row, putting on 2 second timeout
[2024-06-14T23:32:30.301+0530] {logging_mixin.py:188} INFO - [2024-06-14T23:32:30.300+0530] {_transport.py:415} WARNING - Retrying request after failure (attempt 1 of 3)
Traceback (most recent call last):
  File "/home/wsl/airflow_venv/lib/python3.10/site-packages/elastic_transport/_transport.py", line 342, in perform_request
    resp = node.perform_request(
  File "/home/wsl/airflow_venv/lib/python3.10/site-packages/elastic_transport/_node/_http_urllib3.py", line 202, in perform_request
    raise err from None
elastic_transport.ConnectionError: Connection error caused by: NewConnectionError(<urllib3.connection.HTTPConnection object at 0x7f306c2a5930>: Failed to establish a new connection: [Errno 111] Connection refused)
[2024-06-14T23:32:30.303+0530] {logging_mixin.py:188} INFO - [2024-06-14T23:32:30.302+0530] {_transport.py:372} INFO - HEAD http://localhost:9200/ [status:N/A duration:0.001s]
[2024-06-14T23:32:30.304+0530] {logging_mixin.py:188} INFO - [2024-06-14T23:32:30.303+0530] {_node_pool.py:249} WARNING - Node <Urllib3HttpNode(http://localhost:9200)> has failed for 3 times in a row, putting on 4 second timeout
[2024-06-14T23:32:30.305+0530] {logging_mixin.py:188} INFO - [2024-06-14T23:32:30.305+0530] {_transport.py:415} WARNING - Retrying request after failure (attempt 2 of 3)
Traceback (most recent call last):
  File "/home/wsl/airflow_venv/lib/python3.10/site-packages/elastic_transport/_transport.py", line 342, in perform_request
    resp = node.perform_request(
  File "/home/wsl/airflow_venv/lib/python3.10/site-packages/elastic_transport/_node/_http_urllib3.py", line 202, in perform_request
    raise err from None
elastic_transport.ConnectionError: Connection error caused by: NewConnectionError(<urllib3.connection.HTTPConnection object at 0x7f306c2a5bd0>: Failed to establish a new connection: [Errno 111] Connection refused)
[2024-06-14T23:32:30.308+0530] {logging_mixin.py:188} INFO - [2024-06-14T23:32:30.307+0530] {_transport.py:372} INFO - HEAD http://localhost:9200/ [status:N/A duration:0.001s]
[2024-06-14T23:32:30.308+0530] {logging_mixin.py:188} INFO - [2024-06-14T23:32:30.308+0530] {_node_pool.py:249} WARNING - Node <Urllib3HttpNode(http://localhost:9200)> has failed for 4 times in a row, putting on 8 second timeout
[2024-06-14T23:32:30.309+0530] {logging_mixin.py:188} INFO - Error: Connection to Elasticsearch failed
[2024-06-14T23:32:30.309+0530] {processor.py:842} WARNING - No viable dags retrieved from /home/wsl/airflow/dags/Collect Data/eindex.py
[2024-06-14T23:32:30.319+0530] {processor.py:183} INFO - Processing /home/wsl/airflow/dags/Collect Data/eindex.py took 10.845 seconds
[2024-06-14T23:34:08.489+0530] {processor.py:161} INFO - Started process (PID=17714) to work on /home/wsl/airflow/dags/Collect Data/eindex.py
[2024-06-14T23:34:08.491+0530] {processor.py:830} INFO - Processing file /home/wsl/airflow/dags/Collect Data/eindex.py for tasks to queue
[2024-06-14T23:34:08.492+0530] {logging_mixin.py:188} INFO - [2024-06-14T23:34:08.492+0530] {dagbag.py:540} INFO - Filling up the DagBag from /home/wsl/airflow/dags/Collect Data/eindex.py
[2024-06-14T23:34:09.303+0530] {logging_mixin.py:188} INFO - Columns in DataFrame: Index(['date', 'continent', 'country', 'cases', 'deaths', 'idx'], dtype='object')
[2024-06-14T23:34:09.589+0530] {logging_mixin.py:188} INFO - [2024-06-14T23:34:09.588+0530] {_transport.py:372} INFO - HEAD http://localhost:9200/ [status:N/A duration:0.001s]
[2024-06-14T23:34:09.590+0530] {logging_mixin.py:188} INFO - [2024-06-14T23:34:09.589+0530] {_node_pool.py:249} WARNING - Node <Urllib3HttpNode(http://localhost:9200)> has failed for 1 times in a row, putting on 1 second timeout
[2024-06-14T23:34:09.591+0530] {logging_mixin.py:188} INFO - [2024-06-14T23:34:09.590+0530] {_transport.py:415} WARNING - Retrying request after failure (attempt 0 of 3)
Traceback (most recent call last):
  File "/home/wsl/airflow_venv/lib/python3.10/site-packages/elastic_transport/_transport.py", line 342, in perform_request
    resp = node.perform_request(
  File "/home/wsl/airflow_venv/lib/python3.10/site-packages/elastic_transport/_node/_http_urllib3.py", line 202, in perform_request
    raise err from None
elastic_transport.ConnectionError: Connection error caused by: NewConnectionError(<urllib3.connection.HTTPConnection object at 0x7f306caa1570>: Failed to establish a new connection: [Errno 111] Connection refused)
[2024-06-14T23:34:09.592+0530] {logging_mixin.py:188} INFO - [2024-06-14T23:34:09.591+0530] {_transport.py:372} INFO - HEAD http://localhost:9200/ [status:N/A duration:0.001s]
[2024-06-14T23:34:09.592+0530] {logging_mixin.py:188} INFO - [2024-06-14T23:34:09.592+0530] {_node_pool.py:249} WARNING - Node <Urllib3HttpNode(http://localhost:9200)> has failed for 2 times in a row, putting on 2 second timeout
[2024-06-14T23:34:09.593+0530] {logging_mixin.py:188} INFO - [2024-06-14T23:34:09.593+0530] {_transport.py:415} WARNING - Retrying request after failure (attempt 1 of 3)
Traceback (most recent call last):
  File "/home/wsl/airflow_venv/lib/python3.10/site-packages/elastic_transport/_transport.py", line 342, in perform_request
    resp = node.perform_request(
  File "/home/wsl/airflow_venv/lib/python3.10/site-packages/elastic_transport/_node/_http_urllib3.py", line 202, in perform_request
    raise err from None
elastic_transport.ConnectionError: Connection error caused by: NewConnectionError(<urllib3.connection.HTTPConnection object at 0x7f306caa19c0>: Failed to establish a new connection: [Errno 111] Connection refused)
[2024-06-14T23:34:09.594+0530] {logging_mixin.py:188} INFO - [2024-06-14T23:34:09.594+0530] {_transport.py:372} INFO - HEAD http://localhost:9200/ [status:N/A duration:0.001s]
[2024-06-14T23:34:09.596+0530] {logging_mixin.py:188} INFO - [2024-06-14T23:34:09.595+0530] {_node_pool.py:249} WARNING - Node <Urllib3HttpNode(http://localhost:9200)> has failed for 3 times in a row, putting on 4 second timeout
[2024-06-14T23:34:09.597+0530] {logging_mixin.py:188} INFO - [2024-06-14T23:34:09.596+0530] {_transport.py:415} WARNING - Retrying request after failure (attempt 2 of 3)
Traceback (most recent call last):
  File "/home/wsl/airflow_venv/lib/python3.10/site-packages/elastic_transport/_transport.py", line 342, in perform_request
    resp = node.perform_request(
  File "/home/wsl/airflow_venv/lib/python3.10/site-packages/elastic_transport/_node/_http_urllib3.py", line 202, in perform_request
    raise err from None
elastic_transport.ConnectionError: Connection error caused by: NewConnectionError(<urllib3.connection.HTTPConnection object at 0x7f306caa1c60>: Failed to establish a new connection: [Errno 111] Connection refused)
[2024-06-14T23:34:09.598+0530] {logging_mixin.py:188} INFO - [2024-06-14T23:34:09.598+0530] {_transport.py:372} INFO - HEAD http://localhost:9200/ [status:N/A duration:0.001s]
[2024-06-14T23:34:09.599+0530] {logging_mixin.py:188} INFO - [2024-06-14T23:34:09.598+0530] {_node_pool.py:249} WARNING - Node <Urllib3HttpNode(http://localhost:9200)> has failed for 4 times in a row, putting on 8 second timeout
[2024-06-14T23:34:09.599+0530] {logging_mixin.py:188} INFO - Error: Connection to Elasticsearch failed
[2024-06-14T23:34:09.599+0530] {processor.py:842} WARNING - No viable dags retrieved from /home/wsl/airflow/dags/Collect Data/eindex.py
[2024-06-14T23:34:09.613+0530] {processor.py:183} INFO - Processing /home/wsl/airflow/dags/Collect Data/eindex.py took 1.134 seconds
[2024-06-15T00:48:23.609+0530] {processor.py:161} INFO - Started process (PID=19970) to work on /home/wsl/airflow/dags/Collect Data/eindex.py
[2024-06-15T00:48:23.615+0530] {processor.py:830} INFO - Processing file /home/wsl/airflow/dags/Collect Data/eindex.py for tasks to queue
[2024-06-15T00:48:23.616+0530] {logging_mixin.py:188} INFO - [2024-06-15T00:48:23.616+0530] {dagbag.py:540} INFO - Filling up the DagBag from /home/wsl/airflow/dags/Collect Data/eindex.py
[2024-06-15T00:48:25.250+0530] {logging_mixin.py:188} INFO - Columns in DataFrame: Index(['date', 'continent', 'country', 'cases', 'deaths', 'idx'], dtype='object')
[2024-06-15T00:48:25.474+0530] {logging_mixin.py:188} INFO - [2024-06-15T00:48:25.473+0530] {_transport.py:372} INFO - HEAD http://localhost:9200/ [status:N/A duration:0.001s]
[2024-06-15T00:48:25.474+0530] {logging_mixin.py:188} INFO - [2024-06-15T00:48:25.474+0530] {_node_pool.py:249} WARNING - Node <Urllib3HttpNode(http://localhost:9200)> has failed for 1 times in a row, putting on 1 second timeout
[2024-06-15T00:48:25.475+0530] {logging_mixin.py:188} INFO - [2024-06-15T00:48:25.474+0530] {_transport.py:415} WARNING - Retrying request after failure (attempt 0 of 3)
Traceback (most recent call last):
  File "/home/wsl/airflow_venv/lib/python3.10/site-packages/elastic_transport/_transport.py", line 342, in perform_request
    resp = node.perform_request(
  File "/home/wsl/airflow_venv/lib/python3.10/site-packages/elastic_transport/_node/_http_urllib3.py", line 202, in perform_request
    raise err from None
elastic_transport.ConnectionError: Connection error caused by: NewConnectionError(<urllib3.connection.HTTPConnection object at 0x7f306c49d5a0>: Failed to establish a new connection: [Errno 111] Connection refused)
[2024-06-15T00:48:25.476+0530] {logging_mixin.py:188} INFO - [2024-06-15T00:48:25.476+0530] {_transport.py:372} INFO - HEAD http://localhost:9200/ [status:N/A duration:0.001s]
[2024-06-15T00:48:25.477+0530] {logging_mixin.py:188} INFO - [2024-06-15T00:48:25.476+0530] {_node_pool.py:249} WARNING - Node <Urllib3HttpNode(http://localhost:9200)> has failed for 2 times in a row, putting on 2 second timeout
[2024-06-15T00:48:25.477+0530] {logging_mixin.py:188} INFO - [2024-06-15T00:48:25.477+0530] {_transport.py:415} WARNING - Retrying request after failure (attempt 1 of 3)
Traceback (most recent call last):
  File "/home/wsl/airflow_venv/lib/python3.10/site-packages/elastic_transport/_transport.py", line 342, in perform_request
    resp = node.perform_request(
  File "/home/wsl/airflow_venv/lib/python3.10/site-packages/elastic_transport/_node/_http_urllib3.py", line 202, in perform_request
    raise err from None
elastic_transport.ConnectionError: Connection error caused by: NewConnectionError(<urllib3.connection.HTTPConnection object at 0x7f306c49d9f0>: Failed to establish a new connection: [Errno 111] Connection refused)
[2024-06-15T00:48:25.478+0530] {logging_mixin.py:188} INFO - [2024-06-15T00:48:25.478+0530] {_transport.py:372} INFO - HEAD http://localhost:9200/ [status:N/A duration:0.001s]
[2024-06-15T00:48:25.479+0530] {logging_mixin.py:188} INFO - [2024-06-15T00:48:25.478+0530] {_node_pool.py:249} WARNING - Node <Urllib3HttpNode(http://localhost:9200)> has failed for 3 times in a row, putting on 4 second timeout
[2024-06-15T00:48:25.479+0530] {logging_mixin.py:188} INFO - [2024-06-15T00:48:25.479+0530] {_transport.py:415} WARNING - Retrying request after failure (attempt 2 of 3)
Traceback (most recent call last):
  File "/home/wsl/airflow_venv/lib/python3.10/site-packages/elastic_transport/_transport.py", line 342, in perform_request
    resp = node.perform_request(
  File "/home/wsl/airflow_venv/lib/python3.10/site-packages/elastic_transport/_node/_http_urllib3.py", line 202, in perform_request
    raise err from None
elastic_transport.ConnectionError: Connection error caused by: NewConnectionError(<urllib3.connection.HTTPConnection object at 0x7f306c49dc90>: Failed to establish a new connection: [Errno 111] Connection refused)
[2024-06-15T00:48:25.481+0530] {logging_mixin.py:188} INFO - [2024-06-15T00:48:25.480+0530] {_transport.py:372} INFO - HEAD http://localhost:9200/ [status:N/A duration:0.001s]
[2024-06-15T00:48:25.481+0530] {logging_mixin.py:188} INFO - [2024-06-15T00:48:25.481+0530] {_node_pool.py:249} WARNING - Node <Urllib3HttpNode(http://localhost:9200)> has failed for 4 times in a row, putting on 8 second timeout
[2024-06-15T00:48:25.482+0530] {logging_mixin.py:188} INFO - Error: Connection to Elasticsearch failed
[2024-06-15T00:48:25.482+0530] {processor.py:842} WARNING - No viable dags retrieved from /home/wsl/airflow/dags/Collect Data/eindex.py
[2024-06-15T00:48:25.495+0530] {processor.py:183} INFO - Processing /home/wsl/airflow/dags/Collect Data/eindex.py took 1.917 seconds
[2024-06-15T00:50:21.509+0530] {processor.py:161} INFO - Started process (PID=21383) to work on /home/wsl/airflow/dags/Collect Data/eindex.py
[2024-06-15T00:50:21.511+0530] {processor.py:830} INFO - Processing file /home/wsl/airflow/dags/Collect Data/eindex.py for tasks to queue
[2024-06-15T00:50:21.512+0530] {logging_mixin.py:188} INFO - [2024-06-15T00:50:21.512+0530] {dagbag.py:540} INFO - Filling up the DagBag from /home/wsl/airflow/dags/Collect Data/eindex.py
[2024-06-15T00:50:22.328+0530] {logging_mixin.py:188} INFO - Columns in DataFrame: Index(['date', 'continent', 'country', 'cases', 'deaths', 'idx'], dtype='object')
[2024-06-15T00:50:22.673+0530] {logging_mixin.py:188} INFO - [2024-06-15T00:50:22.673+0530] {_transport.py:372} INFO - HEAD http://localhost:9200/ [status:N/A duration:0.001s]
[2024-06-15T00:50:22.674+0530] {logging_mixin.py:188} INFO - [2024-06-15T00:50:22.674+0530] {_node_pool.py:249} WARNING - Node <Urllib3HttpNode(http://localhost:9200)> has failed for 1 times in a row, putting on 1 second timeout
[2024-06-15T00:50:22.675+0530] {logging_mixin.py:188} INFO - [2024-06-15T00:50:22.674+0530] {_transport.py:415} WARNING - Retrying request after failure (attempt 0 of 3)
Traceback (most recent call last):
  File "/home/wsl/airflow_venv/lib/python3.10/site-packages/elastic_transport/_transport.py", line 342, in perform_request
    resp = node.perform_request(
  File "/home/wsl/airflow_venv/lib/python3.10/site-packages/elastic_transport/_node/_http_urllib3.py", line 202, in perform_request
    raise err from None
elastic_transport.ConnectionError: Connection error caused by: NewConnectionError(<urllib3.connection.HTTPConnection object at 0x7f306c0a15d0>: Failed to establish a new connection: [Errno 111] Connection refused)
[2024-06-15T00:50:22.676+0530] {logging_mixin.py:188} INFO - [2024-06-15T00:50:22.676+0530] {_transport.py:372} INFO - HEAD http://localhost:9200/ [status:N/A duration:0.001s]
[2024-06-15T00:50:22.677+0530] {logging_mixin.py:188} INFO - [2024-06-15T00:50:22.676+0530] {_node_pool.py:249} WARNING - Node <Urllib3HttpNode(http://localhost:9200)> has failed for 2 times in a row, putting on 2 second timeout
[2024-06-15T00:50:22.677+0530] {logging_mixin.py:188} INFO - [2024-06-15T00:50:22.677+0530] {_transport.py:415} WARNING - Retrying request after failure (attempt 1 of 3)
Traceback (most recent call last):
  File "/home/wsl/airflow_venv/lib/python3.10/site-packages/elastic_transport/_transport.py", line 342, in perform_request
    resp = node.perform_request(
  File "/home/wsl/airflow_venv/lib/python3.10/site-packages/elastic_transport/_node/_http_urllib3.py", line 202, in perform_request
    raise err from None
elastic_transport.ConnectionError: Connection error caused by: NewConnectionError(<urllib3.connection.HTTPConnection object at 0x7f306c0a1a20>: Failed to establish a new connection: [Errno 111] Connection refused)
[2024-06-15T00:50:22.678+0530] {logging_mixin.py:188} INFO - [2024-06-15T00:50:22.678+0530] {_transport.py:372} INFO - HEAD http://localhost:9200/ [status:N/A duration:0.001s]
[2024-06-15T00:50:22.678+0530] {logging_mixin.py:188} INFO - [2024-06-15T00:50:22.678+0530] {_node_pool.py:249} WARNING - Node <Urllib3HttpNode(http://localhost:9200)> has failed for 3 times in a row, putting on 4 second timeout
[2024-06-15T00:50:22.679+0530] {logging_mixin.py:188} INFO - [2024-06-15T00:50:22.678+0530] {_transport.py:415} WARNING - Retrying request after failure (attempt 2 of 3)
Traceback (most recent call last):
  File "/home/wsl/airflow_venv/lib/python3.10/site-packages/elastic_transport/_transport.py", line 342, in perform_request
    resp = node.perform_request(
  File "/home/wsl/airflow_venv/lib/python3.10/site-packages/elastic_transport/_node/_http_urllib3.py", line 202, in perform_request
    raise err from None
elastic_transport.ConnectionError: Connection error caused by: NewConnectionError(<urllib3.connection.HTTPConnection object at 0x7f306c0a1cc0>: Failed to establish a new connection: [Errno 111] Connection refused)
[2024-06-15T00:50:22.680+0530] {logging_mixin.py:188} INFO - [2024-06-15T00:50:22.680+0530] {_transport.py:372} INFO - HEAD http://localhost:9200/ [status:N/A duration:0.001s]
[2024-06-15T00:50:22.680+0530] {logging_mixin.py:188} INFO - [2024-06-15T00:50:22.680+0530] {_node_pool.py:249} WARNING - Node <Urllib3HttpNode(http://localhost:9200)> has failed for 4 times in a row, putting on 8 second timeout
[2024-06-15T00:50:22.681+0530] {logging_mixin.py:188} INFO - Error: Connection to Elasticsearch failed
[2024-06-15T00:50:22.681+0530] {processor.py:842} WARNING - No viable dags retrieved from /home/wsl/airflow/dags/Collect Data/eindex.py
[2024-06-15T00:50:22.691+0530] {processor.py:183} INFO - Processing /home/wsl/airflow/dags/Collect Data/eindex.py took 1.189 seconds
[2024-06-15T00:51:46.822+0530] {processor.py:161} INFO - Started process (PID=22348) to work on /home/wsl/airflow/dags/Collect Data/eindex.py
[2024-06-15T00:51:46.823+0530] {processor.py:830} INFO - Processing file /home/wsl/airflow/dags/Collect Data/eindex.py for tasks to queue
[2024-06-15T00:51:46.824+0530] {logging_mixin.py:188} INFO - [2024-06-15T00:51:46.824+0530] {dagbag.py:540} INFO - Filling up the DagBag from /home/wsl/airflow/dags/Collect Data/eindex.py
[2024-06-15T00:51:47.531+0530] {logging_mixin.py:188} INFO - Columns in DataFrame: Index(['date', 'continent', 'country', 'cases', 'deaths', 'idx'], dtype='object')
[2024-06-15T00:51:47.774+0530] {logging_mixin.py:188} INFO - [2024-06-15T00:51:47.773+0530] {_transport.py:372} INFO - HEAD http://localhost:9200/ [status:N/A duration:0.002s]
[2024-06-15T00:51:47.775+0530] {logging_mixin.py:188} INFO - [2024-06-15T00:51:47.774+0530] {_node_pool.py:249} WARNING - Node <Urllib3HttpNode(http://localhost:9200)> has failed for 1 times in a row, putting on 1 second timeout
[2024-06-15T00:51:47.776+0530] {logging_mixin.py:188} INFO - [2024-06-15T00:51:47.775+0530] {_transport.py:415} WARNING - Retrying request after failure (attempt 0 of 3)
Traceback (most recent call last):
  File "/home/wsl/airflow_venv/lib/python3.10/site-packages/elastic_transport/_transport.py", line 342, in perform_request
    resp = node.perform_request(
  File "/home/wsl/airflow_venv/lib/python3.10/site-packages/elastic_transport/_node/_http_urllib3.py", line 202, in perform_request
    raise err from None
elastic_transport.ConnectionError: Connection error caused by: NewConnectionError(<urllib3.connection.HTTPConnection object at 0x7f306c0a1600>: Failed to establish a new connection: [Errno 111] Connection refused)
[2024-06-15T00:51:47.778+0530] {logging_mixin.py:188} INFO - [2024-06-15T00:51:47.778+0530] {_transport.py:372} INFO - HEAD http://localhost:9200/ [status:N/A duration:0.001s]
[2024-06-15T00:51:47.788+0530] {logging_mixin.py:188} INFO - [2024-06-15T00:51:47.787+0530] {_node_pool.py:249} WARNING - Node <Urllib3HttpNode(http://localhost:9200)> has failed for 2 times in a row, putting on 2 second timeout
[2024-06-15T00:51:47.788+0530] {logging_mixin.py:188} INFO - [2024-06-15T00:51:47.788+0530] {_transport.py:415} WARNING - Retrying request after failure (attempt 1 of 3)
Traceback (most recent call last):
  File "/home/wsl/airflow_venv/lib/python3.10/site-packages/elastic_transport/_transport.py", line 342, in perform_request
    resp = node.perform_request(
  File "/home/wsl/airflow_venv/lib/python3.10/site-packages/elastic_transport/_node/_http_urllib3.py", line 202, in perform_request
    raise err from None
elastic_transport.ConnectionError: Connection error caused by: NewConnectionError(<urllib3.connection.HTTPConnection object at 0x7f306c0a1a50>: Failed to establish a new connection: [Errno 111] Connection refused)
[2024-06-15T00:51:47.790+0530] {logging_mixin.py:188} INFO - [2024-06-15T00:51:47.789+0530] {_transport.py:372} INFO - HEAD http://localhost:9200/ [status:N/A duration:0.001s]
[2024-06-15T00:51:47.791+0530] {logging_mixin.py:188} INFO - [2024-06-15T00:51:47.790+0530] {_node_pool.py:249} WARNING - Node <Urllib3HttpNode(http://localhost:9200)> has failed for 3 times in a row, putting on 4 second timeout
[2024-06-15T00:51:47.791+0530] {logging_mixin.py:188} INFO - [2024-06-15T00:51:47.791+0530] {_transport.py:415} WARNING - Retrying request after failure (attempt 2 of 3)
Traceback (most recent call last):
  File "/home/wsl/airflow_venv/lib/python3.10/site-packages/elastic_transport/_transport.py", line 342, in perform_request
    resp = node.perform_request(
  File "/home/wsl/airflow_venv/lib/python3.10/site-packages/elastic_transport/_node/_http_urllib3.py", line 202, in perform_request
    raise err from None
elastic_transport.ConnectionError: Connection error caused by: NewConnectionError(<urllib3.connection.HTTPConnection object at 0x7f306c0a1cf0>: Failed to establish a new connection: [Errno 111] Connection refused)
[2024-06-15T00:51:47.793+0530] {logging_mixin.py:188} INFO - [2024-06-15T00:51:47.792+0530] {_transport.py:372} INFO - HEAD http://localhost:9200/ [status:N/A duration:0.001s]
[2024-06-15T00:51:47.793+0530] {logging_mixin.py:188} INFO - [2024-06-15T00:51:47.793+0530] {_node_pool.py:249} WARNING - Node <Urllib3HttpNode(http://localhost:9200)> has failed for 4 times in a row, putting on 8 second timeout
[2024-06-15T00:51:47.794+0530] {logging_mixin.py:188} INFO - Error: Connection to Elasticsearch failed
[2024-06-15T00:51:47.794+0530] {processor.py:842} WARNING - No viable dags retrieved from /home/wsl/airflow/dags/Collect Data/eindex.py
[2024-06-15T00:51:47.825+0530] {processor.py:183} INFO - Processing /home/wsl/airflow/dags/Collect Data/eindex.py took 1.014 seconds
[2024-06-15T00:52:48.400+0530] {processor.py:161} INFO - Started process (PID=23286) to work on /home/wsl/airflow/dags/Collect Data/eindex.py
[2024-06-15T00:52:48.402+0530] {processor.py:830} INFO - Processing file /home/wsl/airflow/dags/Collect Data/eindex.py for tasks to queue
[2024-06-15T00:52:48.412+0530] {logging_mixin.py:188} INFO - [2024-06-15T00:52:48.411+0530] {dagbag.py:540} INFO - Filling up the DagBag from /home/wsl/airflow/dags/Collect Data/eindex.py
[2024-06-15T00:52:50.466+0530] {logging_mixin.py:188} INFO - Columns in DataFrame: Index(['date', 'continent', 'country', 'cases', 'deaths', 'idx'], dtype='object')
[2024-06-15T00:52:50.779+0530] {logging_mixin.py:188} INFO - [2024-06-15T00:52:50.779+0530] {_transport.py:372} INFO - HEAD http://localhost:9200/ [status:N/A duration:0.001s]
[2024-06-15T00:52:50.780+0530] {logging_mixin.py:188} INFO - [2024-06-15T00:52:50.779+0530] {_node_pool.py:249} WARNING - Node <Urllib3HttpNode(http://localhost:9200)> has failed for 1 times in a row, putting on 1 second timeout
[2024-06-15T00:52:50.781+0530] {logging_mixin.py:188} INFO - [2024-06-15T00:52:50.780+0530] {_transport.py:415} WARNING - Retrying request after failure (attempt 0 of 3)
Traceback (most recent call last):
  File "/home/wsl/airflow_venv/lib/python3.10/site-packages/elastic_transport/_transport.py", line 342, in perform_request
    resp = node.perform_request(
  File "/home/wsl/airflow_venv/lib/python3.10/site-packages/elastic_transport/_node/_http_urllib3.py", line 202, in perform_request
    raise err from None
elastic_transport.ConnectionError: Connection error caused by: NewConnectionError(<urllib3.connection.HTTPConnection object at 0x7f3074699600>: Failed to establish a new connection: [Errno 111] Connection refused)
[2024-06-15T00:52:50.783+0530] {logging_mixin.py:188} INFO - [2024-06-15T00:52:50.782+0530] {_transport.py:372} INFO - HEAD http://localhost:9200/ [status:N/A duration:0.001s]
[2024-06-15T00:52:50.783+0530] {logging_mixin.py:188} INFO - [2024-06-15T00:52:50.783+0530] {_node_pool.py:249} WARNING - Node <Urllib3HttpNode(http://localhost:9200)> has failed for 2 times in a row, putting on 2 second timeout
[2024-06-15T00:52:50.783+0530] {logging_mixin.py:188} INFO - [2024-06-15T00:52:50.783+0530] {_transport.py:415} WARNING - Retrying request after failure (attempt 1 of 3)
Traceback (most recent call last):
  File "/home/wsl/airflow_venv/lib/python3.10/site-packages/elastic_transport/_transport.py", line 342, in perform_request
    resp = node.perform_request(
  File "/home/wsl/airflow_venv/lib/python3.10/site-packages/elastic_transport/_node/_http_urllib3.py", line 202, in perform_request
    raise err from None
elastic_transport.ConnectionError: Connection error caused by: NewConnectionError(<urllib3.connection.HTTPConnection object at 0x7f3074699a50>: Failed to establish a new connection: [Errno 111] Connection refused)
[2024-06-15T00:52:50.784+0530] {logging_mixin.py:188} INFO - [2024-06-15T00:52:50.784+0530] {_transport.py:372} INFO - HEAD http://localhost:9200/ [status:N/A duration:0.000s]
[2024-06-15T00:52:50.784+0530] {logging_mixin.py:188} INFO - [2024-06-15T00:52:50.784+0530] {_node_pool.py:249} WARNING - Node <Urllib3HttpNode(http://localhost:9200)> has failed for 3 times in a row, putting on 4 second timeout
[2024-06-15T00:52:50.785+0530] {logging_mixin.py:188} INFO - [2024-06-15T00:52:50.784+0530] {_transport.py:415} WARNING - Retrying request after failure (attempt 2 of 3)
Traceback (most recent call last):
  File "/home/wsl/airflow_venv/lib/python3.10/site-packages/elastic_transport/_transport.py", line 342, in perform_request
    resp = node.perform_request(
  File "/home/wsl/airflow_venv/lib/python3.10/site-packages/elastic_transport/_node/_http_urllib3.py", line 202, in perform_request
    raise err from None
elastic_transport.ConnectionError: Connection error caused by: NewConnectionError(<urllib3.connection.HTTPConnection object at 0x7f3074699cf0>: Failed to establish a new connection: [Errno 111] Connection refused)
[2024-06-15T00:52:50.785+0530] {logging_mixin.py:188} INFO - [2024-06-15T00:52:50.785+0530] {_transport.py:372} INFO - HEAD http://localhost:9200/ [status:N/A duration:0.000s]
[2024-06-15T00:52:50.786+0530] {logging_mixin.py:188} INFO - [2024-06-15T00:52:50.786+0530] {_node_pool.py:249} WARNING - Node <Urllib3HttpNode(http://localhost:9200)> has failed for 4 times in a row, putting on 8 second timeout
[2024-06-15T00:52:50.786+0530] {logging_mixin.py:188} INFO - Error: Connection to Elasticsearch failed
[2024-06-15T00:52:50.786+0530] {processor.py:842} WARNING - No viable dags retrieved from /home/wsl/airflow/dags/Collect Data/eindex.py
[2024-06-15T00:52:50.792+0530] {processor.py:183} INFO - Processing /home/wsl/airflow/dags/Collect Data/eindex.py took 2.410 seconds
[2024-06-15T00:53:59.861+0530] {processor.py:161} INFO - Started process (PID=24307) to work on /home/wsl/airflow/dags/Collect Data/eindex.py
[2024-06-15T00:53:59.863+0530] {processor.py:830} INFO - Processing file /home/wsl/airflow/dags/Collect Data/eindex.py for tasks to queue
[2024-06-15T00:53:59.864+0530] {logging_mixin.py:188} INFO - [2024-06-15T00:53:59.863+0530] {dagbag.py:540} INFO - Filling up the DagBag from /home/wsl/airflow/dags/Collect Data/eindex.py
[2024-06-15T00:54:00.520+0530] {logging_mixin.py:188} INFO - Columns in DataFrame: Index(['date', 'continent', 'country', 'cases', 'deaths', 'idx'], dtype='object')
[2024-06-15T00:54:00.712+0530] {logging_mixin.py:188} INFO - [2024-06-15T00:54:00.712+0530] {_transport.py:372} INFO - HEAD http://localhost:9200/ [status:N/A duration:0.001s]
[2024-06-15T00:54:00.712+0530] {logging_mixin.py:188} INFO - [2024-06-15T00:54:00.712+0530] {_node_pool.py:249} WARNING - Node <Urllib3HttpNode(http://localhost:9200)> has failed for 1 times in a row, putting on 1 second timeout
[2024-06-15T00:54:00.713+0530] {logging_mixin.py:188} INFO - [2024-06-15T00:54:00.712+0530] {_transport.py:415} WARNING - Retrying request after failure (attempt 0 of 3)
Traceback (most recent call last):
  File "/home/wsl/airflow_venv/lib/python3.10/site-packages/elastic_transport/_transport.py", line 342, in perform_request
    resp = node.perform_request(
  File "/home/wsl/airflow_venv/lib/python3.10/site-packages/elastic_transport/_node/_http_urllib3.py", line 202, in perform_request
    raise err from None
elastic_transport.ConnectionError: Connection error caused by: NewConnectionError(<urllib3.connection.HTTPConnection object at 0x7f306c8a1660>: Failed to establish a new connection: [Errno 111] Connection refused)
[2024-06-15T00:54:00.714+0530] {logging_mixin.py:188} INFO - [2024-06-15T00:54:00.714+0530] {_transport.py:372} INFO - HEAD http://localhost:9200/ [status:N/A duration:0.000s]
[2024-06-15T00:54:00.714+0530] {logging_mixin.py:188} INFO - [2024-06-15T00:54:00.714+0530] {_node_pool.py:249} WARNING - Node <Urllib3HttpNode(http://localhost:9200)> has failed for 2 times in a row, putting on 2 second timeout
[2024-06-15T00:54:00.714+0530] {logging_mixin.py:188} INFO - [2024-06-15T00:54:00.714+0530] {_transport.py:415} WARNING - Retrying request after failure (attempt 1 of 3)
Traceback (most recent call last):
  File "/home/wsl/airflow_venv/lib/python3.10/site-packages/elastic_transport/_transport.py", line 342, in perform_request
    resp = node.perform_request(
  File "/home/wsl/airflow_venv/lib/python3.10/site-packages/elastic_transport/_node/_http_urllib3.py", line 202, in perform_request
    raise err from None
elastic_transport.ConnectionError: Connection error caused by: NewConnectionError(<urllib3.connection.HTTPConnection object at 0x7f306c8a1ab0>: Failed to establish a new connection: [Errno 111] Connection refused)
[2024-06-15T00:54:00.715+0530] {logging_mixin.py:188} INFO - [2024-06-15T00:54:00.715+0530] {_transport.py:372} INFO - HEAD http://localhost:9200/ [status:N/A duration:0.000s]
[2024-06-15T00:54:00.715+0530] {logging_mixin.py:188} INFO - [2024-06-15T00:54:00.715+0530] {_node_pool.py:249} WARNING - Node <Urllib3HttpNode(http://localhost:9200)> has failed for 3 times in a row, putting on 4 second timeout
[2024-06-15T00:54:00.715+0530] {logging_mixin.py:188} INFO - [2024-06-15T00:54:00.715+0530] {_transport.py:415} WARNING - Retrying request after failure (attempt 2 of 3)
Traceback (most recent call last):
  File "/home/wsl/airflow_venv/lib/python3.10/site-packages/elastic_transport/_transport.py", line 342, in perform_request
    resp = node.perform_request(
  File "/home/wsl/airflow_venv/lib/python3.10/site-packages/elastic_transport/_node/_http_urllib3.py", line 202, in perform_request
    raise err from None
elastic_transport.ConnectionError: Connection error caused by: NewConnectionError(<urllib3.connection.HTTPConnection object at 0x7f306c8a1d50>: Failed to establish a new connection: [Errno 111] Connection refused)
[2024-06-15T00:54:00.716+0530] {logging_mixin.py:188} INFO - [2024-06-15T00:54:00.716+0530] {_transport.py:372} INFO - HEAD http://localhost:9200/ [status:N/A duration:0.000s]
[2024-06-15T00:54:00.716+0530] {logging_mixin.py:188} INFO - [2024-06-15T00:54:00.716+0530] {_node_pool.py:249} WARNING - Node <Urllib3HttpNode(http://localhost:9200)> has failed for 4 times in a row, putting on 8 second timeout
[2024-06-15T00:54:00.717+0530] {logging_mixin.py:188} INFO - Error: Connection to Elasticsearch failed
[2024-06-15T00:54:00.717+0530] {processor.py:842} WARNING - No viable dags retrieved from /home/wsl/airflow/dags/Collect Data/eindex.py
[2024-06-15T00:54:00.723+0530] {processor.py:183} INFO - Processing /home/wsl/airflow/dags/Collect Data/eindex.py took 0.873 seconds
[2024-06-15T00:55:02.370+0530] {processor.py:161} INFO - Started process (PID=25240) to work on /home/wsl/airflow/dags/Collect Data/eindex.py
[2024-06-15T00:55:02.371+0530] {processor.py:830} INFO - Processing file /home/wsl/airflow/dags/Collect Data/eindex.py for tasks to queue
[2024-06-15T00:55:02.373+0530] {logging_mixin.py:188} INFO - [2024-06-15T00:55:02.372+0530] {dagbag.py:540} INFO - Filling up the DagBag from /home/wsl/airflow/dags/Collect Data/eindex.py
[2024-06-15T00:55:03.083+0530] {logging_mixin.py:188} INFO - Columns in DataFrame: Index(['date', 'continent', 'country', 'cases', 'deaths', 'idx'], dtype='object')
[2024-06-15T00:55:03.273+0530] {logging_mixin.py:188} INFO - [2024-06-15T00:55:03.273+0530] {_transport.py:372} INFO - HEAD http://localhost:9200/ [status:N/A duration:0.001s]
[2024-06-15T00:55:03.274+0530] {logging_mixin.py:188} INFO - [2024-06-15T00:55:03.274+0530] {_node_pool.py:249} WARNING - Node <Urllib3HttpNode(http://localhost:9200)> has failed for 1 times in a row, putting on 1 second timeout
[2024-06-15T00:55:03.275+0530] {logging_mixin.py:188} INFO - [2024-06-15T00:55:03.274+0530] {_transport.py:415} WARNING - Retrying request after failure (attempt 0 of 3)
Traceback (most recent call last):
  File "/home/wsl/airflow_venv/lib/python3.10/site-packages/elastic_transport/_transport.py", line 342, in perform_request
    resp = node.perform_request(
  File "/home/wsl/airflow_venv/lib/python3.10/site-packages/elastic_transport/_node/_http_urllib3.py", line 202, in perform_request
    raise err from None
elastic_transport.ConnectionError: Connection error caused by: NewConnectionError(<urllib3.connection.HTTPConnection object at 0x7f306c09d660>: Failed to establish a new connection: [Errno 111] Connection refused)
[2024-06-15T00:55:03.275+0530] {logging_mixin.py:188} INFO - [2024-06-15T00:55:03.275+0530] {_transport.py:372} INFO - HEAD http://localhost:9200/ [status:N/A duration:0.000s]
[2024-06-15T00:55:03.276+0530] {logging_mixin.py:188} INFO - [2024-06-15T00:55:03.275+0530] {_node_pool.py:249} WARNING - Node <Urllib3HttpNode(http://localhost:9200)> has failed for 2 times in a row, putting on 2 second timeout
[2024-06-15T00:55:03.276+0530] {logging_mixin.py:188} INFO - [2024-06-15T00:55:03.276+0530] {_transport.py:415} WARNING - Retrying request after failure (attempt 1 of 3)
Traceback (most recent call last):
  File "/home/wsl/airflow_venv/lib/python3.10/site-packages/elastic_transport/_transport.py", line 342, in perform_request
    resp = node.perform_request(
  File "/home/wsl/airflow_venv/lib/python3.10/site-packages/elastic_transport/_node/_http_urllib3.py", line 202, in perform_request
    raise err from None
elastic_transport.ConnectionError: Connection error caused by: NewConnectionError(<urllib3.connection.HTTPConnection object at 0x7f306c09dab0>: Failed to establish a new connection: [Errno 111] Connection refused)
[2024-06-15T00:55:03.277+0530] {logging_mixin.py:188} INFO - [2024-06-15T00:55:03.276+0530] {_transport.py:372} INFO - HEAD http://localhost:9200/ [status:N/A duration:0.000s]
[2024-06-15T00:55:03.277+0530] {logging_mixin.py:188} INFO - [2024-06-15T00:55:03.277+0530] {_node_pool.py:249} WARNING - Node <Urllib3HttpNode(http://localhost:9200)> has failed for 3 times in a row, putting on 4 second timeout
[2024-06-15T00:55:03.277+0530] {logging_mixin.py:188} INFO - [2024-06-15T00:55:03.277+0530] {_transport.py:415} WARNING - Retrying request after failure (attempt 2 of 3)
Traceback (most recent call last):
  File "/home/wsl/airflow_venv/lib/python3.10/site-packages/elastic_transport/_transport.py", line 342, in perform_request
    resp = node.perform_request(
  File "/home/wsl/airflow_venv/lib/python3.10/site-packages/elastic_transport/_node/_http_urllib3.py", line 202, in perform_request
    raise err from None
elastic_transport.ConnectionError: Connection error caused by: NewConnectionError(<urllib3.connection.HTTPConnection object at 0x7f306c09dd50>: Failed to establish a new connection: [Errno 111] Connection refused)
[2024-06-15T00:55:03.278+0530] {logging_mixin.py:188} INFO - [2024-06-15T00:55:03.278+0530] {_transport.py:372} INFO - HEAD http://localhost:9200/ [status:N/A duration:0.000s]
[2024-06-15T00:55:03.278+0530] {logging_mixin.py:188} INFO - [2024-06-15T00:55:03.278+0530] {_node_pool.py:249} WARNING - Node <Urllib3HttpNode(http://localhost:9200)> has failed for 4 times in a row, putting on 8 second timeout
[2024-06-15T00:55:03.278+0530] {logging_mixin.py:188} INFO - Error: Connection to Elasticsearch failed
[2024-06-15T00:55:03.279+0530] {processor.py:842} WARNING - No viable dags retrieved from /home/wsl/airflow/dags/Collect Data/eindex.py
[2024-06-15T00:55:03.285+0530] {processor.py:183} INFO - Processing /home/wsl/airflow/dags/Collect Data/eindex.py took 0.928 seconds
[2024-06-15T00:56:07.144+0530] {processor.py:161} INFO - Started process (PID=26177) to work on /home/wsl/airflow/dags/Collect Data/eindex.py
[2024-06-15T00:56:07.145+0530] {processor.py:830} INFO - Processing file /home/wsl/airflow/dags/Collect Data/eindex.py for tasks to queue
[2024-06-15T00:56:07.147+0530] {logging_mixin.py:188} INFO - [2024-06-15T00:56:07.146+0530] {dagbag.py:540} INFO - Filling up the DagBag from /home/wsl/airflow/dags/Collect Data/eindex.py
[2024-06-15T00:56:07.788+0530] {logging_mixin.py:188} INFO - Columns in DataFrame: Index(['date', 'continent', 'country', 'cases', 'deaths', 'idx'], dtype='object')
[2024-06-15T00:56:07.985+0530] {logging_mixin.py:188} INFO - [2024-06-15T00:56:07.985+0530] {_transport.py:372} INFO - HEAD http://localhost:9200/ [status:N/A duration:0.001s]
[2024-06-15T00:56:07.985+0530] {logging_mixin.py:188} INFO - [2024-06-15T00:56:07.985+0530] {_node_pool.py:249} WARNING - Node <Urllib3HttpNode(http://localhost:9200)> has failed for 1 times in a row, putting on 1 second timeout
[2024-06-15T00:56:07.986+0530] {logging_mixin.py:188} INFO - [2024-06-15T00:56:07.986+0530] {_transport.py:415} WARNING - Retrying request after failure (attempt 0 of 3)
Traceback (most recent call last):
  File "/home/wsl/airflow_venv/lib/python3.10/site-packages/elastic_transport/_transport.py", line 342, in perform_request
    resp = node.perform_request(
  File "/home/wsl/airflow_venv/lib/python3.10/site-packages/elastic_transport/_node/_http_urllib3.py", line 202, in perform_request
    raise err from None
elastic_transport.ConnectionError: Connection error caused by: NewConnectionError(<urllib3.connection.HTTPConnection object at 0x7f306c0a1660>: Failed to establish a new connection: [Errno 111] Connection refused)
[2024-06-15T00:56:07.987+0530] {logging_mixin.py:188} INFO - [2024-06-15T00:56:07.987+0530] {_transport.py:372} INFO - HEAD http://localhost:9200/ [status:N/A duration:0.000s]
[2024-06-15T00:56:07.987+0530] {logging_mixin.py:188} INFO - [2024-06-15T00:56:07.987+0530] {_node_pool.py:249} WARNING - Node <Urllib3HttpNode(http://localhost:9200)> has failed for 2 times in a row, putting on 2 second timeout
[2024-06-15T00:56:07.987+0530] {logging_mixin.py:188} INFO - [2024-06-15T00:56:07.987+0530] {_transport.py:415} WARNING - Retrying request after failure (attempt 1 of 3)
Traceback (most recent call last):
  File "/home/wsl/airflow_venv/lib/python3.10/site-packages/elastic_transport/_transport.py", line 342, in perform_request
    resp = node.perform_request(
  File "/home/wsl/airflow_venv/lib/python3.10/site-packages/elastic_transport/_node/_http_urllib3.py", line 202, in perform_request
    raise err from None
elastic_transport.ConnectionError: Connection error caused by: NewConnectionError(<urllib3.connection.HTTPConnection object at 0x7f306c0a1ab0>: Failed to establish a new connection: [Errno 111] Connection refused)
[2024-06-15T00:56:07.988+0530] {logging_mixin.py:188} INFO - [2024-06-15T00:56:07.988+0530] {_transport.py:372} INFO - HEAD http://localhost:9200/ [status:N/A duration:0.000s]
[2024-06-15T00:56:07.988+0530] {logging_mixin.py:188} INFO - [2024-06-15T00:56:07.988+0530] {_node_pool.py:249} WARNING - Node <Urllib3HttpNode(http://localhost:9200)> has failed for 3 times in a row, putting on 4 second timeout
[2024-06-15T00:56:07.989+0530] {logging_mixin.py:188} INFO - [2024-06-15T00:56:07.989+0530] {_transport.py:415} WARNING - Retrying request after failure (attempt 2 of 3)
Traceback (most recent call last):
  File "/home/wsl/airflow_venv/lib/python3.10/site-packages/elastic_transport/_transport.py", line 342, in perform_request
    resp = node.perform_request(
  File "/home/wsl/airflow_venv/lib/python3.10/site-packages/elastic_transport/_node/_http_urllib3.py", line 202, in perform_request
    raise err from None
elastic_transport.ConnectionError: Connection error caused by: NewConnectionError(<urllib3.connection.HTTPConnection object at 0x7f306c0a1d50>: Failed to establish a new connection: [Errno 111] Connection refused)
[2024-06-15T00:56:07.989+0530] {logging_mixin.py:188} INFO - [2024-06-15T00:56:07.989+0530] {_transport.py:372} INFO - HEAD http://localhost:9200/ [status:N/A duration:0.000s]
[2024-06-15T00:56:07.990+0530] {logging_mixin.py:188} INFO - [2024-06-15T00:56:07.990+0530] {_node_pool.py:249} WARNING - Node <Urllib3HttpNode(http://localhost:9200)> has failed for 4 times in a row, putting on 8 second timeout
[2024-06-15T00:56:07.990+0530] {logging_mixin.py:188} INFO - Error: Connection to Elasticsearch failed
[2024-06-15T00:56:07.990+0530] {processor.py:842} WARNING - No viable dags retrieved from /home/wsl/airflow/dags/Collect Data/eindex.py
[2024-06-15T00:56:07.997+0530] {processor.py:183} INFO - Processing /home/wsl/airflow/dags/Collect Data/eindex.py took 0.866 seconds
[2024-06-15T00:57:12.887+0530] {processor.py:161} INFO - Started process (PID=27204) to work on /home/wsl/airflow/dags/Collect Data/eindex.py
[2024-06-15T00:57:12.888+0530] {processor.py:830} INFO - Processing file /home/wsl/airflow/dags/Collect Data/eindex.py for tasks to queue
[2024-06-15T00:57:12.889+0530] {logging_mixin.py:188} INFO - [2024-06-15T00:57:12.889+0530] {dagbag.py:540} INFO - Filling up the DagBag from /home/wsl/airflow/dags/Collect Data/eindex.py
[2024-06-15T00:57:13.554+0530] {logging_mixin.py:188} INFO - Columns in DataFrame: Index(['date', 'continent', 'country', 'cases', 'deaths', 'idx'], dtype='object')
[2024-06-15T00:57:13.760+0530] {logging_mixin.py:188} INFO - [2024-06-15T00:57:13.759+0530] {_transport.py:372} INFO - HEAD http://localhost:9200/ [status:N/A duration:0.001s]
[2024-06-15T00:57:13.760+0530] {logging_mixin.py:188} INFO - [2024-06-15T00:57:13.760+0530] {_node_pool.py:249} WARNING - Node <Urllib3HttpNode(http://localhost:9200)> has failed for 1 times in a row, putting on 1 second timeout
[2024-06-15T00:57:13.761+0530] {logging_mixin.py:188} INFO - [2024-06-15T00:57:13.760+0530] {_transport.py:415} WARNING - Retrying request after failure (attempt 0 of 3)
Traceback (most recent call last):
  File "/home/wsl/airflow_venv/lib/python3.10/site-packages/elastic_transport/_transport.py", line 342, in perform_request
    resp = node.perform_request(
  File "/home/wsl/airflow_venv/lib/python3.10/site-packages/elastic_transport/_node/_http_urllib3.py", line 202, in perform_request
    raise err from None
elastic_transport.ConnectionError: Connection error caused by: NewConnectionError(<urllib3.connection.HTTPConnection object at 0x7f306c0a1660>: Failed to establish a new connection: [Errno 111] Connection refused)
[2024-06-15T00:57:13.762+0530] {logging_mixin.py:188} INFO - [2024-06-15T00:57:13.761+0530] {_transport.py:372} INFO - HEAD http://localhost:9200/ [status:N/A duration:0.000s]
[2024-06-15T00:57:13.762+0530] {logging_mixin.py:188} INFO - [2024-06-15T00:57:13.762+0530] {_node_pool.py:249} WARNING - Node <Urllib3HttpNode(http://localhost:9200)> has failed for 2 times in a row, putting on 2 second timeout
[2024-06-15T00:57:13.762+0530] {logging_mixin.py:188} INFO - [2024-06-15T00:57:13.762+0530] {_transport.py:415} WARNING - Retrying request after failure (attempt 1 of 3)
Traceback (most recent call last):
  File "/home/wsl/airflow_venv/lib/python3.10/site-packages/elastic_transport/_transport.py", line 342, in perform_request
    resp = node.perform_request(
  File "/home/wsl/airflow_venv/lib/python3.10/site-packages/elastic_transport/_node/_http_urllib3.py", line 202, in perform_request
    raise err from None
elastic_transport.ConnectionError: Connection error caused by: NewConnectionError(<urllib3.connection.HTTPConnection object at 0x7f306c0a1ab0>: Failed to establish a new connection: [Errno 111] Connection refused)
[2024-06-15T00:57:13.763+0530] {logging_mixin.py:188} INFO - [2024-06-15T00:57:13.763+0530] {_transport.py:372} INFO - HEAD http://localhost:9200/ [status:N/A duration:0.000s]
[2024-06-15T00:57:13.763+0530] {logging_mixin.py:188} INFO - [2024-06-15T00:57:13.763+0530] {_node_pool.py:249} WARNING - Node <Urllib3HttpNode(http://localhost:9200)> has failed for 3 times in a row, putting on 4 second timeout
[2024-06-15T00:57:13.763+0530] {logging_mixin.py:188} INFO - [2024-06-15T00:57:13.763+0530] {_transport.py:415} WARNING - Retrying request after failure (attempt 2 of 3)
Traceback (most recent call last):
  File "/home/wsl/airflow_venv/lib/python3.10/site-packages/elastic_transport/_transport.py", line 342, in perform_request
    resp = node.perform_request(
  File "/home/wsl/airflow_venv/lib/python3.10/site-packages/elastic_transport/_node/_http_urllib3.py", line 202, in perform_request
    raise err from None
elastic_transport.ConnectionError: Connection error caused by: NewConnectionError(<urllib3.connection.HTTPConnection object at 0x7f306c0a1d50>: Failed to establish a new connection: [Errno 111] Connection refused)
[2024-06-15T00:57:13.764+0530] {logging_mixin.py:188} INFO - [2024-06-15T00:57:13.764+0530] {_transport.py:372} INFO - HEAD http://localhost:9200/ [status:N/A duration:0.000s]
[2024-06-15T00:57:13.764+0530] {logging_mixin.py:188} INFO - [2024-06-15T00:57:13.764+0530] {_node_pool.py:249} WARNING - Node <Urllib3HttpNode(http://localhost:9200)> has failed for 4 times in a row, putting on 8 second timeout
[2024-06-15T00:57:13.764+0530] {logging_mixin.py:188} INFO - Error: Connection to Elasticsearch failed
[2024-06-15T00:57:13.765+0530] {processor.py:842} WARNING - No viable dags retrieved from /home/wsl/airflow/dags/Collect Data/eindex.py
[2024-06-15T00:57:13.772+0530] {processor.py:183} INFO - Processing /home/wsl/airflow/dags/Collect Data/eindex.py took 0.891 seconds
[2024-06-15T00:58:25.817+0530] {processor.py:161} INFO - Started process (PID=28150) to work on /home/wsl/airflow/dags/Collect Data/eindex.py
[2024-06-15T00:58:25.819+0530] {processor.py:830} INFO - Processing file /home/wsl/airflow/dags/Collect Data/eindex.py for tasks to queue
[2024-06-15T00:58:25.821+0530] {logging_mixin.py:188} INFO - [2024-06-15T00:58:25.820+0530] {dagbag.py:540} INFO - Filling up the DagBag from /home/wsl/airflow/dags/Collect Data/eindex.py
[2024-06-15T00:58:26.920+0530] {logging_mixin.py:188} INFO - Columns in DataFrame: Index(['date', 'continent', 'country', 'cases', 'deaths', 'idx'], dtype='object')
[2024-06-15T00:58:27.190+0530] {logging_mixin.py:188} INFO - [2024-06-15T00:58:27.190+0530] {_transport.py:372} INFO - HEAD http://localhost:9200/ [status:N/A duration:0.001s]
[2024-06-15T00:58:27.190+0530] {logging_mixin.py:188} INFO - [2024-06-15T00:58:27.190+0530] {_node_pool.py:249} WARNING - Node <Urllib3HttpNode(http://localhost:9200)> has failed for 1 times in a row, putting on 1 second timeout
[2024-06-15T00:58:27.191+0530] {logging_mixin.py:188} INFO - [2024-06-15T00:58:27.191+0530] {_transport.py:415} WARNING - Retrying request after failure (attempt 0 of 3)
Traceback (most recent call last):
  File "/home/wsl/airflow_venv/lib/python3.10/site-packages/elastic_transport/_transport.py", line 342, in perform_request
    resp = node.perform_request(
  File "/home/wsl/airflow_venv/lib/python3.10/site-packages/elastic_transport/_node/_http_urllib3.py", line 202, in perform_request
    raise err from None
elastic_transport.ConnectionError: Connection error caused by: NewConnectionError(<urllib3.connection.HTTPConnection object at 0x7f307c595690>: Failed to establish a new connection: [Errno 111] Connection refused)
[2024-06-15T00:58:27.192+0530] {logging_mixin.py:188} INFO - [2024-06-15T00:58:27.192+0530] {_transport.py:372} INFO - HEAD http://localhost:9200/ [status:N/A duration:0.000s]
[2024-06-15T00:58:27.192+0530] {logging_mixin.py:188} INFO - [2024-06-15T00:58:27.192+0530] {_node_pool.py:249} WARNING - Node <Urllib3HttpNode(http://localhost:9200)> has failed for 2 times in a row, putting on 2 second timeout
[2024-06-15T00:58:27.192+0530] {logging_mixin.py:188} INFO - [2024-06-15T00:58:27.192+0530] {_transport.py:415} WARNING - Retrying request after failure (attempt 1 of 3)
Traceback (most recent call last):
  File "/home/wsl/airflow_venv/lib/python3.10/site-packages/elastic_transport/_transport.py", line 342, in perform_request
    resp = node.perform_request(
  File "/home/wsl/airflow_venv/lib/python3.10/site-packages/elastic_transport/_node/_http_urllib3.py", line 202, in perform_request
    raise err from None
elastic_transport.ConnectionError: Connection error caused by: NewConnectionError(<urllib3.connection.HTTPConnection object at 0x7f307c595ae0>: Failed to establish a new connection: [Errno 111] Connection refused)
[2024-06-15T00:58:27.193+0530] {logging_mixin.py:188} INFO - [2024-06-15T00:58:27.193+0530] {_transport.py:372} INFO - HEAD http://localhost:9200/ [status:N/A duration:0.000s]
[2024-06-15T00:58:27.193+0530] {logging_mixin.py:188} INFO - [2024-06-15T00:58:27.193+0530] {_node_pool.py:249} WARNING - Node <Urllib3HttpNode(http://localhost:9200)> has failed for 3 times in a row, putting on 4 second timeout
[2024-06-15T00:58:27.194+0530] {logging_mixin.py:188} INFO - [2024-06-15T00:58:27.193+0530] {_transport.py:415} WARNING - Retrying request after failure (attempt 2 of 3)
Traceback (most recent call last):
  File "/home/wsl/airflow_venv/lib/python3.10/site-packages/elastic_transport/_transport.py", line 342, in perform_request
    resp = node.perform_request(
  File "/home/wsl/airflow_venv/lib/python3.10/site-packages/elastic_transport/_node/_http_urllib3.py", line 202, in perform_request
    raise err from None
elastic_transport.ConnectionError: Connection error caused by: NewConnectionError(<urllib3.connection.HTTPConnection object at 0x7f307c595d80>: Failed to establish a new connection: [Errno 111] Connection refused)
[2024-06-15T00:58:27.194+0530] {logging_mixin.py:188} INFO - [2024-06-15T00:58:27.194+0530] {_transport.py:372} INFO - HEAD http://localhost:9200/ [status:N/A duration:0.000s]
[2024-06-15T00:58:27.195+0530] {logging_mixin.py:188} INFO - [2024-06-15T00:58:27.194+0530] {_node_pool.py:249} WARNING - Node <Urllib3HttpNode(http://localhost:9200)> has failed for 4 times in a row, putting on 8 second timeout
[2024-06-15T00:58:27.195+0530] {logging_mixin.py:188} INFO - Error: Connection to Elasticsearch failed
[2024-06-15T00:58:27.195+0530] {processor.py:842} WARNING - No viable dags retrieved from /home/wsl/airflow/dags/Collect Data/eindex.py
[2024-06-15T00:58:27.201+0530] {processor.py:183} INFO - Processing /home/wsl/airflow/dags/Collect Data/eindex.py took 1.394 seconds
[2024-06-15T00:59:48.442+0530] {processor.py:161} INFO - Started process (PID=29230) to work on /home/wsl/airflow/dags/Collect Data/eindex.py
[2024-06-15T00:59:48.445+0530] {processor.py:830} INFO - Processing file /home/wsl/airflow/dags/Collect Data/eindex.py for tasks to queue
[2024-06-15T00:59:48.446+0530] {logging_mixin.py:188} INFO - [2024-06-15T00:59:48.446+0530] {dagbag.py:540} INFO - Filling up the DagBag from /home/wsl/airflow/dags/Collect Data/eindex.py
[2024-06-15T00:59:49.100+0530] {logging_mixin.py:188} INFO - Columns in DataFrame: Index(['date', 'continent', 'country', 'cases', 'deaths', 'idx'], dtype='object')
[2024-06-15T00:59:49.293+0530] {logging_mixin.py:188} INFO - [2024-06-15T00:59:49.292+0530] {_transport.py:372} INFO - HEAD http://localhost:9200/ [status:N/A duration:0.001s]
[2024-06-15T00:59:49.293+0530] {logging_mixin.py:188} INFO - [2024-06-15T00:59:49.293+0530] {_node_pool.py:249} WARNING - Node <Urllib3HttpNode(http://localhost:9200)> has failed for 1 times in a row, putting on 1 second timeout
[2024-06-15T00:59:49.294+0530] {logging_mixin.py:188} INFO - [2024-06-15T00:59:49.293+0530] {_transport.py:415} WARNING - Retrying request after failure (attempt 0 of 3)
Traceback (most recent call last):
  File "/home/wsl/airflow_venv/lib/python3.10/site-packages/elastic_transport/_transport.py", line 342, in perform_request
    resp = node.perform_request(
  File "/home/wsl/airflow_venv/lib/python3.10/site-packages/elastic_transport/_node/_http_urllib3.py", line 202, in perform_request
    raise err from None
elastic_transport.ConnectionError: Connection error caused by: NewConnectionError(<urllib3.connection.HTTPConnection object at 0x7f306c5c5690>: Failed to establish a new connection: [Errno 111] Connection refused)
[2024-06-15T00:59:49.295+0530] {logging_mixin.py:188} INFO - [2024-06-15T00:59:49.295+0530] {_transport.py:372} INFO - HEAD http://localhost:9200/ [status:N/A duration:0.000s]
[2024-06-15T00:59:49.295+0530] {logging_mixin.py:188} INFO - [2024-06-15T00:59:49.295+0530] {_node_pool.py:249} WARNING - Node <Urllib3HttpNode(http://localhost:9200)> has failed for 2 times in a row, putting on 2 second timeout
[2024-06-15T00:59:49.295+0530] {logging_mixin.py:188} INFO - [2024-06-15T00:59:49.295+0530] {_transport.py:415} WARNING - Retrying request after failure (attempt 1 of 3)
Traceback (most recent call last):
  File "/home/wsl/airflow_venv/lib/python3.10/site-packages/elastic_transport/_transport.py", line 342, in perform_request
    resp = node.perform_request(
  File "/home/wsl/airflow_venv/lib/python3.10/site-packages/elastic_transport/_node/_http_urllib3.py", line 202, in perform_request
    raise err from None
elastic_transport.ConnectionError: Connection error caused by: NewConnectionError(<urllib3.connection.HTTPConnection object at 0x7f306c5c5ae0>: Failed to establish a new connection: [Errno 111] Connection refused)
[2024-06-15T00:59:49.296+0530] {logging_mixin.py:188} INFO - [2024-06-15T00:59:49.296+0530] {_transport.py:372} INFO - HEAD http://localhost:9200/ [status:N/A duration:0.000s]
[2024-06-15T00:59:49.297+0530] {logging_mixin.py:188} INFO - [2024-06-15T00:59:49.296+0530] {_node_pool.py:249} WARNING - Node <Urllib3HttpNode(http://localhost:9200)> has failed for 3 times in a row, putting on 4 second timeout
[2024-06-15T00:59:49.297+0530] {logging_mixin.py:188} INFO - [2024-06-15T00:59:49.297+0530] {_transport.py:415} WARNING - Retrying request after failure (attempt 2 of 3)
Traceback (most recent call last):
  File "/home/wsl/airflow_venv/lib/python3.10/site-packages/elastic_transport/_transport.py", line 342, in perform_request
    resp = node.perform_request(
  File "/home/wsl/airflow_venv/lib/python3.10/site-packages/elastic_transport/_node/_http_urllib3.py", line 202, in perform_request
    raise err from None
elastic_transport.ConnectionError: Connection error caused by: NewConnectionError(<urllib3.connection.HTTPConnection object at 0x7f306c5c5d80>: Failed to establish a new connection: [Errno 111] Connection refused)
[2024-06-15T00:59:49.298+0530] {logging_mixin.py:188} INFO - [2024-06-15T00:59:49.297+0530] {_transport.py:372} INFO - HEAD http://localhost:9200/ [status:N/A duration:0.000s]
[2024-06-15T00:59:49.298+0530] {logging_mixin.py:188} INFO - [2024-06-15T00:59:49.298+0530] {_node_pool.py:249} WARNING - Node <Urllib3HttpNode(http://localhost:9200)> has failed for 4 times in a row, putting on 8 second timeout
[2024-06-15T00:59:49.298+0530] {logging_mixin.py:188} INFO - Error: Connection to Elasticsearch failed
[2024-06-15T00:59:49.298+0530] {processor.py:842} WARNING - No viable dags retrieved from /home/wsl/airflow/dags/Collect Data/eindex.py
[2024-06-15T00:59:49.304+0530] {processor.py:183} INFO - Processing /home/wsl/airflow/dags/Collect Data/eindex.py took 0.873 seconds
[2024-06-15T01:00:58.342+0530] {processor.py:161} INFO - Started process (PID=30219) to work on /home/wsl/airflow/dags/Collect Data/eindex.py
[2024-06-15T01:00:58.345+0530] {processor.py:830} INFO - Processing file /home/wsl/airflow/dags/Collect Data/eindex.py for tasks to queue
[2024-06-15T01:00:58.348+0530] {logging_mixin.py:188} INFO - [2024-06-15T01:00:58.347+0530] {dagbag.py:540} INFO - Filling up the DagBag from /home/wsl/airflow/dags/Collect Data/eindex.py
[2024-06-15T01:00:59.141+0530] {logging_mixin.py:188} INFO - Columns in DataFrame: Index(['date', 'continent', 'country', 'cases', 'deaths', 'idx'], dtype='object')
[2024-06-15T01:00:59.772+0530] {logging_mixin.py:188} INFO - [2024-06-15T01:00:59.770+0530] {_transport.py:372} INFO - HEAD http://localhost:9200/ [status:N/A duration:0.001s]
[2024-06-15T01:00:59.773+0530] {logging_mixin.py:188} INFO - [2024-06-15T01:00:59.773+0530] {_node_pool.py:249} WARNING - Node <Urllib3HttpNode(http://localhost:9200)> has failed for 1 times in a row, putting on 1 second timeout
[2024-06-15T01:00:59.775+0530] {logging_mixin.py:188} INFO - [2024-06-15T01:00:59.774+0530] {_transport.py:415} WARNING - Retrying request after failure (attempt 0 of 3)
Traceback (most recent call last):
  File "/home/wsl/airflow_venv/lib/python3.10/site-packages/elastic_transport/_transport.py", line 342, in perform_request
    resp = node.perform_request(
  File "/home/wsl/airflow_venv/lib/python3.10/site-packages/elastic_transport/_node/_http_urllib3.py", line 202, in perform_request
    raise err from None
elastic_transport.ConnectionError: Connection error caused by: NewConnectionError(<urllib3.connection.HTTPConnection object at 0x7f306c0a56c0>: Failed to establish a new connection: [Errno 111] Connection refused)
[2024-06-15T01:00:59.780+0530] {logging_mixin.py:188} INFO - [2024-06-15T01:00:59.779+0530] {_transport.py:372} INFO - HEAD http://localhost:9200/ [status:N/A duration:0.004s]
[2024-06-15T01:00:59.780+0530] {logging_mixin.py:188} INFO - [2024-06-15T01:00:59.780+0530] {_node_pool.py:249} WARNING - Node <Urllib3HttpNode(http://localhost:9200)> has failed for 2 times in a row, putting on 2 second timeout
[2024-06-15T01:00:59.781+0530] {logging_mixin.py:188} INFO - [2024-06-15T01:00:59.781+0530] {_transport.py:415} WARNING - Retrying request after failure (attempt 1 of 3)
Traceback (most recent call last):
  File "/home/wsl/airflow_venv/lib/python3.10/site-packages/elastic_transport/_transport.py", line 342, in perform_request
    resp = node.perform_request(
  File "/home/wsl/airflow_venv/lib/python3.10/site-packages/elastic_transport/_node/_http_urllib3.py", line 202, in perform_request
    raise err from None
elastic_transport.ConnectionError: Connection error caused by: NewConnectionError(<urllib3.connection.HTTPConnection object at 0x7f306c0a5b10>: Failed to establish a new connection: [Errno 111] Connection refused)
[2024-06-15T01:00:59.782+0530] {logging_mixin.py:188} INFO - [2024-06-15T01:00:59.782+0530] {_transport.py:372} INFO - HEAD http://localhost:9200/ [status:N/A duration:0.001s]
[2024-06-15T01:00:59.783+0530] {logging_mixin.py:188} INFO - [2024-06-15T01:00:59.782+0530] {_node_pool.py:249} WARNING - Node <Urllib3HttpNode(http://localhost:9200)> has failed for 3 times in a row, putting on 4 second timeout
[2024-06-15T01:00:59.783+0530] {logging_mixin.py:188} INFO - [2024-06-15T01:00:59.783+0530] {_transport.py:415} WARNING - Retrying request after failure (attempt 2 of 3)
Traceback (most recent call last):
  File "/home/wsl/airflow_venv/lib/python3.10/site-packages/elastic_transport/_transport.py", line 342, in perform_request
    resp = node.perform_request(
  File "/home/wsl/airflow_venv/lib/python3.10/site-packages/elastic_transport/_node/_http_urllib3.py", line 202, in perform_request
    raise err from None
elastic_transport.ConnectionError: Connection error caused by: NewConnectionError(<urllib3.connection.HTTPConnection object at 0x7f306c0a5db0>: Failed to establish a new connection: [Errno 111] Connection refused)
[2024-06-15T01:00:59.785+0530] {logging_mixin.py:188} INFO - [2024-06-15T01:00:59.784+0530] {_transport.py:372} INFO - HEAD http://localhost:9200/ [status:N/A duration:0.001s]
[2024-06-15T01:00:59.785+0530] {logging_mixin.py:188} INFO - [2024-06-15T01:00:59.785+0530] {_node_pool.py:249} WARNING - Node <Urllib3HttpNode(http://localhost:9200)> has failed for 4 times in a row, putting on 8 second timeout
[2024-06-15T01:00:59.785+0530] {logging_mixin.py:188} INFO - Error: Connection to Elasticsearch failed
[2024-06-15T01:00:59.786+0530] {processor.py:842} WARNING - No viable dags retrieved from /home/wsl/airflow/dags/Collect Data/eindex.py
[2024-06-15T01:00:59.800+0530] {processor.py:183} INFO - Processing /home/wsl/airflow/dags/Collect Data/eindex.py took 1.480 seconds
[2024-06-15T01:02:03.433+0530] {processor.py:161} INFO - Started process (PID=31298) to work on /home/wsl/airflow/dags/Collect Data/eindex.py
[2024-06-15T01:02:03.436+0530] {processor.py:830} INFO - Processing file /home/wsl/airflow/dags/Collect Data/eindex.py for tasks to queue
[2024-06-15T01:02:03.437+0530] {logging_mixin.py:188} INFO - [2024-06-15T01:02:03.436+0530] {dagbag.py:540} INFO - Filling up the DagBag from /home/wsl/airflow/dags/Collect Data/eindex.py
[2024-06-15T01:02:04.335+0530] {logging_mixin.py:188} INFO - Columns in DataFrame: Index(['date', 'continent', 'country', 'cases', 'deaths', 'idx'], dtype='object')
[2024-06-15T01:02:04.590+0530] {logging_mixin.py:188} INFO - [2024-06-15T01:02:04.590+0530] {_transport.py:372} INFO - HEAD http://localhost:9200/ [status:N/A duration:0.001s]
[2024-06-15T01:02:04.591+0530] {logging_mixin.py:188} INFO - [2024-06-15T01:02:04.591+0530] {_node_pool.py:249} WARNING - Node <Urllib3HttpNode(http://localhost:9200)> has failed for 1 times in a row, putting on 1 second timeout
[2024-06-15T01:02:04.593+0530] {logging_mixin.py:188} INFO - [2024-06-15T01:02:04.592+0530] {_transport.py:415} WARNING - Retrying request after failure (attempt 0 of 3)
Traceback (most recent call last):
  File "/home/wsl/airflow_venv/lib/python3.10/site-packages/elastic_transport/_transport.py", line 342, in perform_request
    resp = node.perform_request(
  File "/home/wsl/airflow_venv/lib/python3.10/site-packages/elastic_transport/_node/_http_urllib3.py", line 202, in perform_request
    raise err from None
elastic_transport.ConnectionError: Connection error caused by: NewConnectionError(<urllib3.connection.HTTPConnection object at 0x7f306c08d780>: Failed to establish a new connection: [Errno 111] Connection refused)
[2024-06-15T01:02:04.594+0530] {logging_mixin.py:188} INFO - [2024-06-15T01:02:04.594+0530] {_transport.py:372} INFO - HEAD http://localhost:9200/ [status:N/A duration:0.001s]
[2024-06-15T01:02:04.595+0530] {logging_mixin.py:188} INFO - [2024-06-15T01:02:04.595+0530] {_node_pool.py:249} WARNING - Node <Urllib3HttpNode(http://localhost:9200)> has failed for 2 times in a row, putting on 2 second timeout
[2024-06-15T01:02:04.596+0530] {logging_mixin.py:188} INFO - [2024-06-15T01:02:04.595+0530] {_transport.py:415} WARNING - Retrying request after failure (attempt 1 of 3)
Traceback (most recent call last):
  File "/home/wsl/airflow_venv/lib/python3.10/site-packages/elastic_transport/_transport.py", line 342, in perform_request
    resp = node.perform_request(
  File "/home/wsl/airflow_venv/lib/python3.10/site-packages/elastic_transport/_node/_http_urllib3.py", line 202, in perform_request
    raise err from None
elastic_transport.ConnectionError: Connection error caused by: NewConnectionError(<urllib3.connection.HTTPConnection object at 0x7f306c08dbd0>: Failed to establish a new connection: [Errno 111] Connection refused)
[2024-06-15T01:02:04.597+0530] {logging_mixin.py:188} INFO - [2024-06-15T01:02:04.597+0530] {_transport.py:372} INFO - HEAD http://localhost:9200/ [status:N/A duration:0.001s]
[2024-06-15T01:02:04.598+0530] {logging_mixin.py:188} INFO - [2024-06-15T01:02:04.598+0530] {_node_pool.py:249} WARNING - Node <Urllib3HttpNode(http://localhost:9200)> has failed for 3 times in a row, putting on 4 second timeout
[2024-06-15T01:02:04.598+0530] {logging_mixin.py:188} INFO - [2024-06-15T01:02:04.598+0530] {_transport.py:415} WARNING - Retrying request after failure (attempt 2 of 3)
Traceback (most recent call last):
  File "/home/wsl/airflow_venv/lib/python3.10/site-packages/elastic_transport/_transport.py", line 342, in perform_request
    resp = node.perform_request(
  File "/home/wsl/airflow_venv/lib/python3.10/site-packages/elastic_transport/_node/_http_urllib3.py", line 202, in perform_request
    raise err from None
elastic_transport.ConnectionError: Connection error caused by: NewConnectionError(<urllib3.connection.HTTPConnection object at 0x7f306c08de70>: Failed to establish a new connection: [Errno 111] Connection refused)
[2024-06-15T01:02:04.599+0530] {logging_mixin.py:188} INFO - [2024-06-15T01:02:04.599+0530] {_transport.py:372} INFO - HEAD http://localhost:9200/ [status:N/A duration:0.001s]
[2024-06-15T01:02:04.600+0530] {logging_mixin.py:188} INFO - [2024-06-15T01:02:04.600+0530] {_node_pool.py:249} WARNING - Node <Urllib3HttpNode(http://localhost:9200)> has failed for 4 times in a row, putting on 8 second timeout
[2024-06-15T01:02:04.600+0530] {logging_mixin.py:188} INFO - Error: Connection to Elasticsearch failed
[2024-06-15T01:02:04.600+0530] {processor.py:842} WARNING - No viable dags retrieved from /home/wsl/airflow/dags/Collect Data/eindex.py
[2024-06-15T01:02:04.608+0530] {processor.py:183} INFO - Processing /home/wsl/airflow/dags/Collect Data/eindex.py took 1.186 seconds
[2024-06-15T01:03:12.396+0530] {processor.py:161} INFO - Started process (PID=32262) to work on /home/wsl/airflow/dags/Collect Data/eindex.py
[2024-06-15T01:03:12.398+0530] {processor.py:830} INFO - Processing file /home/wsl/airflow/dags/Collect Data/eindex.py for tasks to queue
[2024-06-15T01:03:12.399+0530] {logging_mixin.py:188} INFO - [2024-06-15T01:03:12.399+0530] {dagbag.py:540} INFO - Filling up the DagBag from /home/wsl/airflow/dags/Collect Data/eindex.py
[2024-06-15T01:03:13.121+0530] {logging_mixin.py:188} INFO - Columns in DataFrame: Index(['date', 'continent', 'country', 'cases', 'deaths', 'idx'], dtype='object')
[2024-06-15T01:03:13.393+0530] {logging_mixin.py:188} INFO - [2024-06-15T01:03:13.393+0530] {_transport.py:372} INFO - HEAD http://localhost:9200/ [status:N/A duration:0.001s]
[2024-06-15T01:03:13.394+0530] {logging_mixin.py:188} INFO - [2024-06-15T01:03:13.393+0530] {_node_pool.py:249} WARNING - Node <Urllib3HttpNode(http://localhost:9200)> has failed for 1 times in a row, putting on 1 second timeout
[2024-06-15T01:03:13.395+0530] {logging_mixin.py:188} INFO - [2024-06-15T01:03:13.394+0530] {_transport.py:415} WARNING - Retrying request after failure (attempt 0 of 3)
Traceback (most recent call last):
  File "/home/wsl/airflow_venv/lib/python3.10/site-packages/elastic_transport/_transport.py", line 342, in perform_request
    resp = node.perform_request(
  File "/home/wsl/airflow_venv/lib/python3.10/site-packages/elastic_transport/_node/_http_urllib3.py", line 202, in perform_request
    raise err from None
elastic_transport.ConnectionError: Connection error caused by: NewConnectionError(<urllib3.connection.HTTPConnection object at 0x7f306c5857b0>: Failed to establish a new connection: [Errno 111] Connection refused)
[2024-06-15T01:03:13.396+0530] {logging_mixin.py:188} INFO - [2024-06-15T01:03:13.396+0530] {_transport.py:372} INFO - HEAD http://localhost:9200/ [status:N/A duration:0.000s]
[2024-06-15T01:03:13.397+0530] {logging_mixin.py:188} INFO - [2024-06-15T01:03:13.396+0530] {_node_pool.py:249} WARNING - Node <Urllib3HttpNode(http://localhost:9200)> has failed for 2 times in a row, putting on 2 second timeout
[2024-06-15T01:03:13.397+0530] {logging_mixin.py:188} INFO - [2024-06-15T01:03:13.397+0530] {_transport.py:415} WARNING - Retrying request after failure (attempt 1 of 3)
Traceback (most recent call last):
  File "/home/wsl/airflow_venv/lib/python3.10/site-packages/elastic_transport/_transport.py", line 342, in perform_request
    resp = node.perform_request(
  File "/home/wsl/airflow_venv/lib/python3.10/site-packages/elastic_transport/_node/_http_urllib3.py", line 202, in perform_request
    raise err from None
elastic_transport.ConnectionError: Connection error caused by: NewConnectionError(<urllib3.connection.HTTPConnection object at 0x7f306c585c00>: Failed to establish a new connection: [Errno 111] Connection refused)
[2024-06-15T01:03:13.398+0530] {logging_mixin.py:188} INFO - [2024-06-15T01:03:13.398+0530] {_transport.py:372} INFO - HEAD http://localhost:9200/ [status:N/A duration:0.001s]
[2024-06-15T01:03:13.399+0530] {logging_mixin.py:188} INFO - [2024-06-15T01:03:13.398+0530] {_node_pool.py:249} WARNING - Node <Urllib3HttpNode(http://localhost:9200)> has failed for 3 times in a row, putting on 4 second timeout
[2024-06-15T01:03:13.399+0530] {logging_mixin.py:188} INFO - [2024-06-15T01:03:13.399+0530] {_transport.py:415} WARNING - Retrying request after failure (attempt 2 of 3)
Traceback (most recent call last):
  File "/home/wsl/airflow_venv/lib/python3.10/site-packages/elastic_transport/_transport.py", line 342, in perform_request
    resp = node.perform_request(
  File "/home/wsl/airflow_venv/lib/python3.10/site-packages/elastic_transport/_node/_http_urllib3.py", line 202, in perform_request
    raise err from None
elastic_transport.ConnectionError: Connection error caused by: NewConnectionError(<urllib3.connection.HTTPConnection object at 0x7f306c585ea0>: Failed to establish a new connection: [Errno 111] Connection refused)
[2024-06-15T01:03:13.400+0530] {logging_mixin.py:188} INFO - [2024-06-15T01:03:13.400+0530] {_transport.py:372} INFO - HEAD http://localhost:9200/ [status:N/A duration:0.001s]
[2024-06-15T01:03:13.401+0530] {logging_mixin.py:188} INFO - [2024-06-15T01:03:13.400+0530] {_node_pool.py:249} WARNING - Node <Urllib3HttpNode(http://localhost:9200)> has failed for 4 times in a row, putting on 8 second timeout
[2024-06-15T01:03:13.401+0530] {logging_mixin.py:188} INFO - Error: Connection to Elasticsearch failed
[2024-06-15T01:03:13.401+0530] {processor.py:842} WARNING - No viable dags retrieved from /home/wsl/airflow/dags/Collect Data/eindex.py
[2024-06-15T01:03:13.409+0530] {processor.py:183} INFO - Processing /home/wsl/airflow/dags/Collect Data/eindex.py took 1.023 seconds
[2024-06-15T01:04:21.165+0530] {processor.py:161} INFO - Started process (PID=33172) to work on /home/wsl/airflow/dags/Collect Data/eindex.py
[2024-06-15T01:04:21.166+0530] {processor.py:830} INFO - Processing file /home/wsl/airflow/dags/Collect Data/eindex.py for tasks to queue
[2024-06-15T01:04:21.167+0530] {logging_mixin.py:188} INFO - [2024-06-15T01:04:21.167+0530] {dagbag.py:540} INFO - Filling up the DagBag from /home/wsl/airflow/dags/Collect Data/eindex.py
[2024-06-15T01:04:21.807+0530] {logging_mixin.py:188} INFO - Columns in DataFrame: Index(['date', 'continent', 'country', 'cases', 'deaths', 'idx'], dtype='object')
[2024-06-15T01:04:21.995+0530] {logging_mixin.py:188} INFO - [2024-06-15T01:04:21.995+0530] {_transport.py:372} INFO - HEAD http://localhost:9200/ [status:N/A duration:0.002s]
[2024-06-15T01:04:21.996+0530] {logging_mixin.py:188} INFO - [2024-06-15T01:04:21.996+0530] {_node_pool.py:249} WARNING - Node <Urllib3HttpNode(http://localhost:9200)> has failed for 1 times in a row, putting on 1 second timeout
[2024-06-15T01:04:21.997+0530] {logging_mixin.py:188} INFO - [2024-06-15T01:04:21.996+0530] {_transport.py:415} WARNING - Retrying request after failure (attempt 0 of 3)
Traceback (most recent call last):
  File "/home/wsl/airflow_venv/lib/python3.10/site-packages/elastic_transport/_transport.py", line 342, in perform_request
    resp = node.perform_request(
  File "/home/wsl/airflow_venv/lib/python3.10/site-packages/elastic_transport/_node/_http_urllib3.py", line 202, in perform_request
    raise err from None
elastic_transport.ConnectionError: Connection error caused by: NewConnectionError(<urllib3.connection.HTTPConnection object at 0x7f306c6097e0>: Failed to establish a new connection: [Errno 111] Connection refused)
[2024-06-15T01:04:21.997+0530] {logging_mixin.py:188} INFO - [2024-06-15T01:04:21.997+0530] {_transport.py:372} INFO - HEAD http://localhost:9200/ [status:N/A duration:0.000s]
[2024-06-15T01:04:21.998+0530] {logging_mixin.py:188} INFO - [2024-06-15T01:04:21.998+0530] {_node_pool.py:249} WARNING - Node <Urllib3HttpNode(http://localhost:9200)> has failed for 2 times in a row, putting on 2 second timeout
[2024-06-15T01:04:21.998+0530] {logging_mixin.py:188} INFO - [2024-06-15T01:04:21.998+0530] {_transport.py:415} WARNING - Retrying request after failure (attempt 1 of 3)
Traceback (most recent call last):
  File "/home/wsl/airflow_venv/lib/python3.10/site-packages/elastic_transport/_transport.py", line 342, in perform_request
    resp = node.perform_request(
  File "/home/wsl/airflow_venv/lib/python3.10/site-packages/elastic_transport/_node/_http_urllib3.py", line 202, in perform_request
    raise err from None
elastic_transport.ConnectionError: Connection error caused by: NewConnectionError(<urllib3.connection.HTTPConnection object at 0x7f306c609c30>: Failed to establish a new connection: [Errno 111] Connection refused)
[2024-06-15T01:04:21.999+0530] {logging_mixin.py:188} INFO - [2024-06-15T01:04:21.998+0530] {_transport.py:372} INFO - HEAD http://localhost:9200/ [status:N/A duration:0.000s]
[2024-06-15T01:04:21.999+0530] {logging_mixin.py:188} INFO - [2024-06-15T01:04:21.999+0530] {_node_pool.py:249} WARNING - Node <Urllib3HttpNode(http://localhost:9200)> has failed for 3 times in a row, putting on 4 second timeout
[2024-06-15T01:04:21.999+0530] {logging_mixin.py:188} INFO - [2024-06-15T01:04:21.999+0530] {_transport.py:415} WARNING - Retrying request after failure (attempt 2 of 3)
Traceback (most recent call last):
  File "/home/wsl/airflow_venv/lib/python3.10/site-packages/elastic_transport/_transport.py", line 342, in perform_request
    resp = node.perform_request(
  File "/home/wsl/airflow_venv/lib/python3.10/site-packages/elastic_transport/_node/_http_urllib3.py", line 202, in perform_request
    raise err from None
elastic_transport.ConnectionError: Connection error caused by: NewConnectionError(<urllib3.connection.HTTPConnection object at 0x7f306c609ed0>: Failed to establish a new connection: [Errno 111] Connection refused)
[2024-06-15T01:04:22.000+0530] {logging_mixin.py:188} INFO - [2024-06-15T01:04:22.000+0530] {_transport.py:372} INFO - HEAD http://localhost:9200/ [status:N/A duration:0.000s]
[2024-06-15T01:04:22.000+0530] {logging_mixin.py:188} INFO - [2024-06-15T01:04:22.000+0530] {_node_pool.py:249} WARNING - Node <Urllib3HttpNode(http://localhost:9200)> has failed for 4 times in a row, putting on 8 second timeout
[2024-06-15T01:04:22.000+0530] {logging_mixin.py:188} INFO - Error: Connection to Elasticsearch failed
[2024-06-15T01:04:22.000+0530] {processor.py:842} WARNING - No viable dags retrieved from /home/wsl/airflow/dags/Collect Data/eindex.py
[2024-06-15T01:04:22.007+0530] {processor.py:183} INFO - Processing /home/wsl/airflow/dags/Collect Data/eindex.py took 0.851 seconds
[2024-06-15T01:05:23.087+0530] {processor.py:161} INFO - Started process (PID=34134) to work on /home/wsl/airflow/dags/Collect Data/eindex.py
[2024-06-15T01:05:23.089+0530] {processor.py:830} INFO - Processing file /home/wsl/airflow/dags/Collect Data/eindex.py for tasks to queue
[2024-06-15T01:05:23.090+0530] {logging_mixin.py:188} INFO - [2024-06-15T01:05:23.090+0530] {dagbag.py:540} INFO - Filling up the DagBag from /home/wsl/airflow/dags/Collect Data/eindex.py
[2024-06-15T01:05:23.778+0530] {logging_mixin.py:188} INFO - Columns in DataFrame: Index(['date', 'continent', 'country', 'cases', 'deaths', 'idx'], dtype='object')
[2024-06-15T01:05:23.967+0530] {logging_mixin.py:188} INFO - [2024-06-15T01:05:23.966+0530] {_transport.py:372} INFO - HEAD http://localhost:9200/ [status:N/A duration:0.001s]
[2024-06-15T01:05:23.967+0530] {logging_mixin.py:188} INFO - [2024-06-15T01:05:23.967+0530] {_node_pool.py:249} WARNING - Node <Urllib3HttpNode(http://localhost:9200)> has failed for 1 times in a row, putting on 1 second timeout
[2024-06-15T01:05:23.968+0530] {logging_mixin.py:188} INFO - [2024-06-15T01:05:23.967+0530] {_transport.py:415} WARNING - Retrying request after failure (attempt 0 of 3)
Traceback (most recent call last):
  File "/home/wsl/airflow_venv/lib/python3.10/site-packages/elastic_transport/_transport.py", line 342, in perform_request
    resp = node.perform_request(
  File "/home/wsl/airflow_venv/lib/python3.10/site-packages/elastic_transport/_node/_http_urllib3.py", line 202, in perform_request
    raise err from None
elastic_transport.ConnectionError: Connection error caused by: NewConnectionError(<urllib3.connection.HTTPConnection object at 0x7f306c0a9840>: Failed to establish a new connection: [Errno 111] Connection refused)
[2024-06-15T01:05:23.968+0530] {logging_mixin.py:188} INFO - [2024-06-15T01:05:23.968+0530] {_transport.py:372} INFO - HEAD http://localhost:9200/ [status:N/A duration:0.000s]
[2024-06-15T01:05:23.969+0530] {logging_mixin.py:188} INFO - [2024-06-15T01:05:23.968+0530] {_node_pool.py:249} WARNING - Node <Urllib3HttpNode(http://localhost:9200)> has failed for 2 times in a row, putting on 2 second timeout
[2024-06-15T01:05:23.969+0530] {logging_mixin.py:188} INFO - [2024-06-15T01:05:23.969+0530] {_transport.py:415} WARNING - Retrying request after failure (attempt 1 of 3)
Traceback (most recent call last):
  File "/home/wsl/airflow_venv/lib/python3.10/site-packages/elastic_transport/_transport.py", line 342, in perform_request
    resp = node.perform_request(
  File "/home/wsl/airflow_venv/lib/python3.10/site-packages/elastic_transport/_node/_http_urllib3.py", line 202, in perform_request
    raise err from None
elastic_transport.ConnectionError: Connection error caused by: NewConnectionError(<urllib3.connection.HTTPConnection object at 0x7f306c0a9c90>: Failed to establish a new connection: [Errno 111] Connection refused)
[2024-06-15T01:05:23.970+0530] {logging_mixin.py:188} INFO - [2024-06-15T01:05:23.969+0530] {_transport.py:372} INFO - HEAD http://localhost:9200/ [status:N/A duration:0.000s]
[2024-06-15T01:05:23.970+0530] {logging_mixin.py:188} INFO - [2024-06-15T01:05:23.970+0530] {_node_pool.py:249} WARNING - Node <Urllib3HttpNode(http://localhost:9200)> has failed for 3 times in a row, putting on 4 second timeout
[2024-06-15T01:05:23.970+0530] {logging_mixin.py:188} INFO - [2024-06-15T01:05:23.970+0530] {_transport.py:415} WARNING - Retrying request after failure (attempt 2 of 3)
Traceback (most recent call last):
  File "/home/wsl/airflow_venv/lib/python3.10/site-packages/elastic_transport/_transport.py", line 342, in perform_request
    resp = node.perform_request(
  File "/home/wsl/airflow_venv/lib/python3.10/site-packages/elastic_transport/_node/_http_urllib3.py", line 202, in perform_request
    raise err from None
elastic_transport.ConnectionError: Connection error caused by: NewConnectionError(<urllib3.connection.HTTPConnection object at 0x7f306c0a9f30>: Failed to establish a new connection: [Errno 111] Connection refused)
[2024-06-15T01:05:23.971+0530] {logging_mixin.py:188} INFO - [2024-06-15T01:05:23.971+0530] {_transport.py:372} INFO - HEAD http://localhost:9200/ [status:N/A duration:0.000s]
[2024-06-15T01:05:23.971+0530] {logging_mixin.py:188} INFO - [2024-06-15T01:05:23.971+0530] {_node_pool.py:249} WARNING - Node <Urllib3HttpNode(http://localhost:9200)> has failed for 4 times in a row, putting on 8 second timeout
[2024-06-15T01:05:23.971+0530] {logging_mixin.py:188} INFO - Error: Connection to Elasticsearch failed
[2024-06-15T01:05:23.971+0530] {processor.py:842} WARNING - No viable dags retrieved from /home/wsl/airflow/dags/Collect Data/eindex.py
[2024-06-15T01:05:23.977+0530] {processor.py:183} INFO - Processing /home/wsl/airflow/dags/Collect Data/eindex.py took 0.900 seconds
[2024-06-15T01:06:26.837+0530] {processor.py:161} INFO - Started process (PID=35102) to work on /home/wsl/airflow/dags/Collect Data/eindex.py
[2024-06-15T01:06:26.840+0530] {processor.py:830} INFO - Processing file /home/wsl/airflow/dags/Collect Data/eindex.py for tasks to queue
[2024-06-15T01:06:26.841+0530] {logging_mixin.py:188} INFO - [2024-06-15T01:06:26.840+0530] {dagbag.py:540} INFO - Filling up the DagBag from /home/wsl/airflow/dags/Collect Data/eindex.py
[2024-06-15T01:06:27.510+0530] {logging_mixin.py:188} INFO - Columns in DataFrame: Index(['date', 'continent', 'country', 'cases', 'deaths', 'idx'], dtype='object')
[2024-06-15T01:06:27.719+0530] {logging_mixin.py:188} INFO - [2024-06-15T01:06:27.719+0530] {_transport.py:372} INFO - HEAD http://localhost:9200/ [status:N/A duration:0.001s]
[2024-06-15T01:06:27.720+0530] {logging_mixin.py:188} INFO - [2024-06-15T01:06:27.719+0530] {_node_pool.py:249} WARNING - Node <Urllib3HttpNode(http://localhost:9200)> has failed for 1 times in a row, putting on 1 second timeout
[2024-06-15T01:06:27.720+0530] {logging_mixin.py:188} INFO - [2024-06-15T01:06:27.720+0530] {_transport.py:415} WARNING - Retrying request after failure (attempt 0 of 3)
Traceback (most recent call last):
  File "/home/wsl/airflow_venv/lib/python3.10/site-packages/elastic_transport/_transport.py", line 342, in perform_request
    resp = node.perform_request(
  File "/home/wsl/airflow_venv/lib/python3.10/site-packages/elastic_transport/_node/_http_urllib3.py", line 202, in perform_request
    raise err from None
elastic_transport.ConnectionError: Connection error caused by: NewConnectionError(<urllib3.connection.HTTPConnection object at 0x7f306c09d840>: Failed to establish a new connection: [Errno 111] Connection refused)
[2024-06-15T01:06:27.721+0530] {logging_mixin.py:188} INFO - [2024-06-15T01:06:27.721+0530] {_transport.py:372} INFO - HEAD http://localhost:9200/ [status:N/A duration:0.000s]
[2024-06-15T01:06:27.721+0530] {logging_mixin.py:188} INFO - [2024-06-15T01:06:27.721+0530] {_node_pool.py:249} WARNING - Node <Urllib3HttpNode(http://localhost:9200)> has failed for 2 times in a row, putting on 2 second timeout
[2024-06-15T01:06:27.722+0530] {logging_mixin.py:188} INFO - [2024-06-15T01:06:27.721+0530] {_transport.py:415} WARNING - Retrying request after failure (attempt 1 of 3)
Traceback (most recent call last):
  File "/home/wsl/airflow_venv/lib/python3.10/site-packages/elastic_transport/_transport.py", line 342, in perform_request
    resp = node.perform_request(
  File "/home/wsl/airflow_venv/lib/python3.10/site-packages/elastic_transport/_node/_http_urllib3.py", line 202, in perform_request
    raise err from None
elastic_transport.ConnectionError: Connection error caused by: NewConnectionError(<urllib3.connection.HTTPConnection object at 0x7f306c09dc90>: Failed to establish a new connection: [Errno 111] Connection refused)
[2024-06-15T01:06:27.722+0530] {logging_mixin.py:188} INFO - [2024-06-15T01:06:27.722+0530] {_transport.py:372} INFO - HEAD http://localhost:9200/ [status:N/A duration:0.000s]
[2024-06-15T01:06:27.722+0530] {logging_mixin.py:188} INFO - [2024-06-15T01:06:27.722+0530] {_node_pool.py:249} WARNING - Node <Urllib3HttpNode(http://localhost:9200)> has failed for 3 times in a row, putting on 4 second timeout
[2024-06-15T01:06:27.723+0530] {logging_mixin.py:188} INFO - [2024-06-15T01:06:27.723+0530] {_transport.py:415} WARNING - Retrying request after failure (attempt 2 of 3)
Traceback (most recent call last):
  File "/home/wsl/airflow_venv/lib/python3.10/site-packages/elastic_transport/_transport.py", line 342, in perform_request
    resp = node.perform_request(
  File "/home/wsl/airflow_venv/lib/python3.10/site-packages/elastic_transport/_node/_http_urllib3.py", line 202, in perform_request
    raise err from None
elastic_transport.ConnectionError: Connection error caused by: NewConnectionError(<urllib3.connection.HTTPConnection object at 0x7f306c09df30>: Failed to establish a new connection: [Errno 111] Connection refused)
[2024-06-15T01:06:27.723+0530] {logging_mixin.py:188} INFO - [2024-06-15T01:06:27.723+0530] {_transport.py:372} INFO - HEAD http://localhost:9200/ [status:N/A duration:0.000s]
[2024-06-15T01:06:27.724+0530] {logging_mixin.py:188} INFO - [2024-06-15T01:06:27.724+0530] {_node_pool.py:249} WARNING - Node <Urllib3HttpNode(http://localhost:9200)> has failed for 4 times in a row, putting on 8 second timeout
[2024-06-15T01:06:27.724+0530] {logging_mixin.py:188} INFO - Error: Connection to Elasticsearch failed
[2024-06-15T01:06:27.724+0530] {processor.py:842} WARNING - No viable dags retrieved from /home/wsl/airflow/dags/Collect Data/eindex.py
[2024-06-15T01:06:27.835+0530] {processor.py:183} INFO - Processing /home/wsl/airflow/dags/Collect Data/eindex.py took 1.015 seconds
[2024-06-15T01:07:27.292+0530] {processor.py:161} INFO - Started process (PID=36022) to work on /home/wsl/airflow/dags/Collect Data/eindex.py
[2024-06-15T01:07:27.294+0530] {processor.py:830} INFO - Processing file /home/wsl/airflow/dags/Collect Data/eindex.py for tasks to queue
[2024-06-15T01:07:27.296+0530] {logging_mixin.py:188} INFO - [2024-06-15T01:07:27.296+0530] {dagbag.py:540} INFO - Filling up the DagBag from /home/wsl/airflow/dags/Collect Data/eindex.py
[2024-06-15T01:07:27.931+0530] {logging_mixin.py:188} INFO - Columns in DataFrame: Index(['date', 'continent', 'country', 'cases', 'deaths', 'idx'], dtype='object')
[2024-06-15T01:07:28.123+0530] {logging_mixin.py:188} INFO - [2024-06-15T01:07:28.123+0530] {_transport.py:372} INFO - HEAD http://localhost:9200/ [status:N/A duration:0.001s]
[2024-06-15T01:07:28.123+0530] {logging_mixin.py:188} INFO - [2024-06-15T01:07:28.123+0530] {_node_pool.py:249} WARNING - Node <Urllib3HttpNode(http://localhost:9200)> has failed for 1 times in a row, putting on 1 second timeout
[2024-06-15T01:07:28.124+0530] {logging_mixin.py:188} INFO - [2024-06-15T01:07:28.124+0530] {_transport.py:415} WARNING - Retrying request after failure (attempt 0 of 3)
Traceback (most recent call last):
  File "/home/wsl/airflow_venv/lib/python3.10/site-packages/elastic_transport/_transport.py", line 342, in perform_request
    resp = node.perform_request(
  File "/home/wsl/airflow_venv/lib/python3.10/site-packages/elastic_transport/_node/_http_urllib3.py", line 202, in perform_request
    raise err from None
elastic_transport.ConnectionError: Connection error caused by: NewConnectionError(<urllib3.connection.HTTPConnection object at 0x7f306c899870>: Failed to establish a new connection: [Errno 111] Connection refused)
[2024-06-15T01:07:28.125+0530] {logging_mixin.py:188} INFO - [2024-06-15T01:07:28.125+0530] {_transport.py:372} INFO - HEAD http://localhost:9200/ [status:N/A duration:0.000s]
[2024-06-15T01:07:28.125+0530] {logging_mixin.py:188} INFO - [2024-06-15T01:07:28.125+0530] {_node_pool.py:249} WARNING - Node <Urllib3HttpNode(http://localhost:9200)> has failed for 2 times in a row, putting on 2 second timeout
[2024-06-15T01:07:28.125+0530] {logging_mixin.py:188} INFO - [2024-06-15T01:07:28.125+0530] {_transport.py:415} WARNING - Retrying request after failure (attempt 1 of 3)
Traceback (most recent call last):
  File "/home/wsl/airflow_venv/lib/python3.10/site-packages/elastic_transport/_transport.py", line 342, in perform_request
    resp = node.perform_request(
  File "/home/wsl/airflow_venv/lib/python3.10/site-packages/elastic_transport/_node/_http_urllib3.py", line 202, in perform_request
    raise err from None
elastic_transport.ConnectionError: Connection error caused by: NewConnectionError(<urllib3.connection.HTTPConnection object at 0x7f306c899cc0>: Failed to establish a new connection: [Errno 111] Connection refused)
[2024-06-15T01:07:28.126+0530] {logging_mixin.py:188} INFO - [2024-06-15T01:07:28.126+0530] {_transport.py:372} INFO - HEAD http://localhost:9200/ [status:N/A duration:0.000s]
[2024-06-15T01:07:28.127+0530] {logging_mixin.py:188} INFO - [2024-06-15T01:07:28.126+0530] {_node_pool.py:249} WARNING - Node <Urllib3HttpNode(http://localhost:9200)> has failed for 3 times in a row, putting on 4 second timeout
[2024-06-15T01:07:28.127+0530] {logging_mixin.py:188} INFO - [2024-06-15T01:07:28.127+0530] {_transport.py:415} WARNING - Retrying request after failure (attempt 2 of 3)
Traceback (most recent call last):
  File "/home/wsl/airflow_venv/lib/python3.10/site-packages/elastic_transport/_transport.py", line 342, in perform_request
    resp = node.perform_request(
  File "/home/wsl/airflow_venv/lib/python3.10/site-packages/elastic_transport/_node/_http_urllib3.py", line 202, in perform_request
    raise err from None
elastic_transport.ConnectionError: Connection error caused by: NewConnectionError(<urllib3.connection.HTTPConnection object at 0x7f306c899f60>: Failed to establish a new connection: [Errno 111] Connection refused)
[2024-06-15T01:07:28.128+0530] {logging_mixin.py:188} INFO - [2024-06-15T01:07:28.127+0530] {_transport.py:372} INFO - HEAD http://localhost:9200/ [status:N/A duration:0.000s]
[2024-06-15T01:07:28.128+0530] {logging_mixin.py:188} INFO - [2024-06-15T01:07:28.128+0530] {_node_pool.py:249} WARNING - Node <Urllib3HttpNode(http://localhost:9200)> has failed for 4 times in a row, putting on 8 second timeout
[2024-06-15T01:07:28.128+0530] {logging_mixin.py:188} INFO - Error: Connection to Elasticsearch failed
[2024-06-15T01:07:28.128+0530] {processor.py:842} WARNING - No viable dags retrieved from /home/wsl/airflow/dags/Collect Data/eindex.py
[2024-06-15T01:07:28.134+0530] {processor.py:183} INFO - Processing /home/wsl/airflow/dags/Collect Data/eindex.py took 0.855 seconds
[2024-06-15T01:08:23.619+0530] {processor.py:161} INFO - Started process (PID=36972) to work on /home/wsl/airflow/dags/Collect Data/eindex.py
[2024-06-15T01:08:23.622+0530] {processor.py:830} INFO - Processing file /home/wsl/airflow/dags/Collect Data/eindex.py for tasks to queue
[2024-06-15T01:08:23.623+0530] {logging_mixin.py:188} INFO - [2024-06-15T01:08:23.623+0530] {dagbag.py:540} INFO - Filling up the DagBag from /home/wsl/airflow/dags/Collect Data/eindex.py
[2024-06-15T01:08:24.268+0530] {logging_mixin.py:188} INFO - Columns in DataFrame: Index(['date', 'continent', 'country', 'cases', 'deaths', 'idx'], dtype='object')
[2024-06-15T01:08:24.455+0530] {logging_mixin.py:188} INFO - [2024-06-15T01:08:24.455+0530] {_transport.py:372} INFO - HEAD http://localhost:9200/ [status:N/A duration:0.001s]
[2024-06-15T01:08:24.455+0530] {logging_mixin.py:188} INFO - [2024-06-15T01:08:24.455+0530] {_node_pool.py:249} WARNING - Node <Urllib3HttpNode(http://localhost:9200)> has failed for 1 times in a row, putting on 1 second timeout
[2024-06-15T01:08:24.456+0530] {logging_mixin.py:188} INFO - [2024-06-15T01:08:24.456+0530] {_transport.py:415} WARNING - Retrying request after failure (attempt 0 of 3)
Traceback (most recent call last):
  File "/home/wsl/airflow_venv/lib/python3.10/site-packages/elastic_transport/_transport.py", line 342, in perform_request
    resp = node.perform_request(
  File "/home/wsl/airflow_venv/lib/python3.10/site-packages/elastic_transport/_node/_http_urllib3.py", line 202, in perform_request
    raise err from None
elastic_transport.ConnectionError: Connection error caused by: NewConnectionError(<urllib3.connection.HTTPConnection object at 0x7f306c8a5870>: Failed to establish a new connection: [Errno 111] Connection refused)
[2024-06-15T01:08:24.457+0530] {logging_mixin.py:188} INFO - [2024-06-15T01:08:24.457+0530] {_transport.py:372} INFO - HEAD http://localhost:9200/ [status:N/A duration:0.000s]
[2024-06-15T01:08:24.457+0530] {logging_mixin.py:188} INFO - [2024-06-15T01:08:24.457+0530] {_node_pool.py:249} WARNING - Node <Urllib3HttpNode(http://localhost:9200)> has failed for 2 times in a row, putting on 2 second timeout
[2024-06-15T01:08:24.458+0530] {logging_mixin.py:188} INFO - [2024-06-15T01:08:24.457+0530] {_transport.py:415} WARNING - Retrying request after failure (attempt 1 of 3)
Traceback (most recent call last):
  File "/home/wsl/airflow_venv/lib/python3.10/site-packages/elastic_transport/_transport.py", line 342, in perform_request
    resp = node.perform_request(
  File "/home/wsl/airflow_venv/lib/python3.10/site-packages/elastic_transport/_node/_http_urllib3.py", line 202, in perform_request
    raise err from None
elastic_transport.ConnectionError: Connection error caused by: NewConnectionError(<urllib3.connection.HTTPConnection object at 0x7f306c8a5cc0>: Failed to establish a new connection: [Errno 111] Connection refused)
[2024-06-15T01:08:24.458+0530] {logging_mixin.py:188} INFO - [2024-06-15T01:08:24.458+0530] {_transport.py:372} INFO - HEAD http://localhost:9200/ [status:N/A duration:0.000s]
[2024-06-15T01:08:24.458+0530] {logging_mixin.py:188} INFO - [2024-06-15T01:08:24.458+0530] {_node_pool.py:249} WARNING - Node <Urllib3HttpNode(http://localhost:9200)> has failed for 3 times in a row, putting on 4 second timeout
[2024-06-15T01:08:24.459+0530] {logging_mixin.py:188} INFO - [2024-06-15T01:08:24.459+0530] {_transport.py:415} WARNING - Retrying request after failure (attempt 2 of 3)
Traceback (most recent call last):
  File "/home/wsl/airflow_venv/lib/python3.10/site-packages/elastic_transport/_transport.py", line 342, in perform_request
    resp = node.perform_request(
  File "/home/wsl/airflow_venv/lib/python3.10/site-packages/elastic_transport/_node/_http_urllib3.py", line 202, in perform_request
    raise err from None
elastic_transport.ConnectionError: Connection error caused by: NewConnectionError(<urllib3.connection.HTTPConnection object at 0x7f306c8a5f60>: Failed to establish a new connection: [Errno 111] Connection refused)
[2024-06-15T01:08:24.459+0530] {logging_mixin.py:188} INFO - [2024-06-15T01:08:24.459+0530] {_transport.py:372} INFO - HEAD http://localhost:9200/ [status:N/A duration:0.000s]
[2024-06-15T01:08:24.460+0530] {logging_mixin.py:188} INFO - [2024-06-15T01:08:24.460+0530] {_node_pool.py:249} WARNING - Node <Urllib3HttpNode(http://localhost:9200)> has failed for 4 times in a row, putting on 8 second timeout
[2024-06-15T01:08:24.460+0530] {logging_mixin.py:188} INFO - Error: Connection to Elasticsearch failed
[2024-06-15T01:08:24.460+0530] {processor.py:842} WARNING - No viable dags retrieved from /home/wsl/airflow/dags/Collect Data/eindex.py
[2024-06-15T01:08:24.466+0530] {processor.py:183} INFO - Processing /home/wsl/airflow/dags/Collect Data/eindex.py took 0.859 seconds
[2024-06-15T01:09:19.927+0530] {processor.py:161} INFO - Started process (PID=37802) to work on /home/wsl/airflow/dags/Collect Data/eindex.py
[2024-06-15T01:09:19.928+0530] {processor.py:830} INFO - Processing file /home/wsl/airflow/dags/Collect Data/eindex.py for tasks to queue
[2024-06-15T01:09:19.930+0530] {logging_mixin.py:188} INFO - [2024-06-15T01:09:19.929+0530] {dagbag.py:540} INFO - Filling up the DagBag from /home/wsl/airflow/dags/Collect Data/eindex.py
[2024-06-15T01:09:21.258+0530] {logging_mixin.py:188} INFO - Columns in DataFrame: Index(['date', 'continent', 'country', 'cases', 'deaths', 'idx'], dtype='object')
[2024-06-15T01:09:21.459+0530] {logging_mixin.py:188} INFO - [2024-06-15T01:09:21.459+0530] {_transport.py:372} INFO - HEAD http://localhost:9200/ [status:N/A duration:0.001s]
[2024-06-15T01:09:21.460+0530] {logging_mixin.py:188} INFO - [2024-06-15T01:09:21.460+0530] {_node_pool.py:249} WARNING - Node <Urllib3HttpNode(http://localhost:9200)> has failed for 1 times in a row, putting on 1 second timeout
[2024-06-15T01:09:21.460+0530] {logging_mixin.py:188} INFO - [2024-06-15T01:09:21.460+0530] {_transport.py:415} WARNING - Retrying request after failure (attempt 0 of 3)
Traceback (most recent call last):
  File "/home/wsl/airflow_venv/lib/python3.10/site-packages/elastic_transport/_transport.py", line 342, in perform_request
    resp = node.perform_request(
  File "/home/wsl/airflow_venv/lib/python3.10/site-packages/elastic_transport/_node/_http_urllib3.py", line 202, in perform_request
    raise err from None
elastic_transport.ConnectionError: Connection error caused by: NewConnectionError(<urllib3.connection.HTTPConnection object at 0x7f3085f0d930>: Failed to establish a new connection: [Errno 111] Connection refused)
[2024-06-15T01:09:21.461+0530] {logging_mixin.py:188} INFO - [2024-06-15T01:09:21.461+0530] {_transport.py:372} INFO - HEAD http://localhost:9200/ [status:N/A duration:0.000s]
[2024-06-15T01:09:21.462+0530] {logging_mixin.py:188} INFO - [2024-06-15T01:09:21.461+0530] {_node_pool.py:249} WARNING - Node <Urllib3HttpNode(http://localhost:9200)> has failed for 2 times in a row, putting on 2 second timeout
[2024-06-15T01:09:21.462+0530] {logging_mixin.py:188} INFO - [2024-06-15T01:09:21.462+0530] {_transport.py:415} WARNING - Retrying request after failure (attempt 1 of 3)
Traceback (most recent call last):
  File "/home/wsl/airflow_venv/lib/python3.10/site-packages/elastic_transport/_transport.py", line 342, in perform_request
    resp = node.perform_request(
  File "/home/wsl/airflow_venv/lib/python3.10/site-packages/elastic_transport/_node/_http_urllib3.py", line 202, in perform_request
    raise err from None
elastic_transport.ConnectionError: Connection error caused by: NewConnectionError(<urllib3.connection.HTTPConnection object at 0x7f3085f0dd80>: Failed to establish a new connection: [Errno 111] Connection refused)
[2024-06-15T01:09:21.463+0530] {logging_mixin.py:188} INFO - [2024-06-15T01:09:21.462+0530] {_transport.py:372} INFO - HEAD http://localhost:9200/ [status:N/A duration:0.000s]
[2024-06-15T01:09:21.463+0530] {logging_mixin.py:188} INFO - [2024-06-15T01:09:21.463+0530] {_node_pool.py:249} WARNING - Node <Urllib3HttpNode(http://localhost:9200)> has failed for 3 times in a row, putting on 4 second timeout
[2024-06-15T01:09:21.463+0530] {logging_mixin.py:188} INFO - [2024-06-15T01:09:21.463+0530] {_transport.py:415} WARNING - Retrying request after failure (attempt 2 of 3)
Traceback (most recent call last):
  File "/home/wsl/airflow_venv/lib/python3.10/site-packages/elastic_transport/_transport.py", line 342, in perform_request
    resp = node.perform_request(
  File "/home/wsl/airflow_venv/lib/python3.10/site-packages/elastic_transport/_node/_http_urllib3.py", line 202, in perform_request
    raise err from None
elastic_transport.ConnectionError: Connection error caused by: NewConnectionError(<urllib3.connection.HTTPConnection object at 0x7f3085f0e020>: Failed to establish a new connection: [Errno 111] Connection refused)
[2024-06-15T01:09:21.464+0530] {logging_mixin.py:188} INFO - [2024-06-15T01:09:21.464+0530] {_transport.py:372} INFO - HEAD http://localhost:9200/ [status:N/A duration:0.000s]
[2024-06-15T01:09:21.464+0530] {logging_mixin.py:188} INFO - [2024-06-15T01:09:21.464+0530] {_node_pool.py:249} WARNING - Node <Urllib3HttpNode(http://localhost:9200)> has failed for 4 times in a row, putting on 8 second timeout
[2024-06-15T01:09:21.464+0530] {logging_mixin.py:188} INFO - Error: Connection to Elasticsearch failed
[2024-06-15T01:09:21.464+0530] {processor.py:842} WARNING - No viable dags retrieved from /home/wsl/airflow/dags/Collect Data/eindex.py
[2024-06-15T01:09:21.471+0530] {processor.py:183} INFO - Processing /home/wsl/airflow/dags/Collect Data/eindex.py took 1.552 seconds
[2024-06-15T01:10:38.428+0530] {processor.py:161} INFO - Started process (PID=38785) to work on /home/wsl/airflow/dags/Collect Data/eindex.py
[2024-06-15T01:10:38.434+0530] {processor.py:830} INFO - Processing file /home/wsl/airflow/dags/Collect Data/eindex.py for tasks to queue
[2024-06-15T01:10:38.436+0530] {logging_mixin.py:188} INFO - [2024-06-15T01:10:38.435+0530] {dagbag.py:540} INFO - Filling up the DagBag from /home/wsl/airflow/dags/Collect Data/eindex.py
[2024-06-15T01:10:40.498+0530] {logging_mixin.py:188} INFO - Columns in DataFrame: Index(['date', 'continent', 'country', 'cases', 'deaths', 'idx'], dtype='object')
[2024-06-15T01:10:40.704+0530] {logging_mixin.py:188} INFO - [2024-06-15T01:10:40.704+0530] {_transport.py:372} INFO - HEAD http://localhost:9200/ [status:N/A duration:0.001s]
[2024-06-15T01:10:40.705+0530] {logging_mixin.py:188} INFO - [2024-06-15T01:10:40.704+0530] {_node_pool.py:249} WARNING - Node <Urllib3HttpNode(http://localhost:9200)> has failed for 1 times in a row, putting on 1 second timeout
[2024-06-15T01:10:40.705+0530] {logging_mixin.py:188} INFO - [2024-06-15T01:10:40.705+0530] {_transport.py:415} WARNING - Retrying request after failure (attempt 0 of 3)
Traceback (most recent call last):
  File "/home/wsl/airflow_venv/lib/python3.10/site-packages/elastic_transport/_transport.py", line 342, in perform_request
    resp = node.perform_request(
  File "/home/wsl/airflow_venv/lib/python3.10/site-packages/elastic_transport/_node/_http_urllib3.py", line 202, in perform_request
    raise err from None
elastic_transport.ConnectionError: Connection error caused by: NewConnectionError(<urllib3.connection.HTTPConnection object at 0x7f3085f25930>: Failed to establish a new connection: [Errno 111] Connection refused)
[2024-06-15T01:10:40.706+0530] {logging_mixin.py:188} INFO - [2024-06-15T01:10:40.706+0530] {_transport.py:372} INFO - HEAD http://localhost:9200/ [status:N/A duration:0.001s]
[2024-06-15T01:10:40.707+0530] {logging_mixin.py:188} INFO - [2024-06-15T01:10:40.706+0530] {_node_pool.py:249} WARNING - Node <Urllib3HttpNode(http://localhost:9200)> has failed for 2 times in a row, putting on 2 second timeout
[2024-06-15T01:10:40.707+0530] {logging_mixin.py:188} INFO - [2024-06-15T01:10:40.707+0530] {_transport.py:415} WARNING - Retrying request after failure (attempt 1 of 3)
Traceback (most recent call last):
  File "/home/wsl/airflow_venv/lib/python3.10/site-packages/elastic_transport/_transport.py", line 342, in perform_request
    resp = node.perform_request(
  File "/home/wsl/airflow_venv/lib/python3.10/site-packages/elastic_transport/_node/_http_urllib3.py", line 202, in perform_request
    raise err from None
elastic_transport.ConnectionError: Connection error caused by: NewConnectionError(<urllib3.connection.HTTPConnection object at 0x7f3085f25d80>: Failed to establish a new connection: [Errno 111] Connection refused)
[2024-06-15T01:10:40.708+0530] {logging_mixin.py:188} INFO - [2024-06-15T01:10:40.707+0530] {_transport.py:372} INFO - HEAD http://localhost:9200/ [status:N/A duration:0.000s]
[2024-06-15T01:10:40.708+0530] {logging_mixin.py:188} INFO - [2024-06-15T01:10:40.708+0530] {_node_pool.py:249} WARNING - Node <Urllib3HttpNode(http://localhost:9200)> has failed for 3 times in a row, putting on 4 second timeout
[2024-06-15T01:10:40.708+0530] {logging_mixin.py:188} INFO - [2024-06-15T01:10:40.708+0530] {_transport.py:415} WARNING - Retrying request after failure (attempt 2 of 3)
Traceback (most recent call last):
  File "/home/wsl/airflow_venv/lib/python3.10/site-packages/elastic_transport/_transport.py", line 342, in perform_request
    resp = node.perform_request(
  File "/home/wsl/airflow_venv/lib/python3.10/site-packages/elastic_transport/_node/_http_urllib3.py", line 202, in perform_request
    raise err from None
elastic_transport.ConnectionError: Connection error caused by: NewConnectionError(<urllib3.connection.HTTPConnection object at 0x7f3085f26020>: Failed to establish a new connection: [Errno 111] Connection refused)
[2024-06-15T01:10:40.709+0530] {logging_mixin.py:188} INFO - [2024-06-15T01:10:40.709+0530] {_transport.py:372} INFO - HEAD http://localhost:9200/ [status:N/A duration:0.000s]
[2024-06-15T01:10:40.709+0530] {logging_mixin.py:188} INFO - [2024-06-15T01:10:40.709+0530] {_node_pool.py:249} WARNING - Node <Urllib3HttpNode(http://localhost:9200)> has failed for 4 times in a row, putting on 8 second timeout
[2024-06-15T01:10:40.709+0530] {logging_mixin.py:188} INFO - Error: Connection to Elasticsearch failed
[2024-06-15T01:10:40.709+0530] {processor.py:842} WARNING - No viable dags retrieved from /home/wsl/airflow/dags/Collect Data/eindex.py
[2024-06-15T01:10:40.949+0530] {processor.py:183} INFO - Processing /home/wsl/airflow/dags/Collect Data/eindex.py took 2.528 seconds
[2024-06-15T01:12:04.865+0530] {processor.py:161} INFO - Started process (PID=39838) to work on /home/wsl/airflow/dags/Collect Data/eindex.py
[2024-06-15T01:12:04.869+0530] {processor.py:830} INFO - Processing file /home/wsl/airflow/dags/Collect Data/eindex.py for tasks to queue
[2024-06-15T01:12:04.871+0530] {logging_mixin.py:188} INFO - [2024-06-15T01:12:04.870+0530] {dagbag.py:540} INFO - Filling up the DagBag from /home/wsl/airflow/dags/Collect Data/eindex.py
[2024-06-15T01:12:12.795+0530] {logging_mixin.py:188} INFO - Columns in DataFrame: Index(['date', 'continent', 'country', 'cases', 'deaths', 'idx'], dtype='object')
[2024-06-15T01:12:13.586+0530] {logging_mixin.py:188} INFO - [2024-06-15T01:12:13.586+0530] {_transport.py:372} INFO - HEAD http://localhost:9200/ [status:N/A duration:0.001s]
[2024-06-15T01:12:13.587+0530] {logging_mixin.py:188} INFO - [2024-06-15T01:12:13.587+0530] {_node_pool.py:249} WARNING - Node <Urllib3HttpNode(http://localhost:9200)> has failed for 1 times in a row, putting on 1 second timeout
[2024-06-15T01:12:13.589+0530] {logging_mixin.py:188} INFO - [2024-06-15T01:12:13.588+0530] {_transport.py:415} WARNING - Retrying request after failure (attempt 0 of 3)
Traceback (most recent call last):
  File "/home/wsl/airflow_venv/lib/python3.10/site-packages/elastic_transport/_transport.py", line 342, in perform_request
    resp = node.perform_request(
  File "/home/wsl/airflow_venv/lib/python3.10/site-packages/elastic_transport/_node/_http_urllib3.py", line 202, in perform_request
    raise err from None
elastic_transport.ConnectionError: Connection error caused by: NewConnectionError(<urllib3.connection.HTTPConnection object at 0x7f3085f29930>: Failed to establish a new connection: [Errno 111] Connection refused)
[2024-06-15T01:12:13.590+0530] {logging_mixin.py:188} INFO - [2024-06-15T01:12:13.589+0530] {_transport.py:372} INFO - HEAD http://localhost:9200/ [status:N/A duration:0.000s]
[2024-06-15T01:12:13.590+0530] {logging_mixin.py:188} INFO - [2024-06-15T01:12:13.590+0530] {_node_pool.py:249} WARNING - Node <Urllib3HttpNode(http://localhost:9200)> has failed for 2 times in a row, putting on 2 second timeout
[2024-06-15T01:12:13.590+0530] {logging_mixin.py:188} INFO - [2024-06-15T01:12:13.590+0530] {_transport.py:415} WARNING - Retrying request after failure (attempt 1 of 3)
Traceback (most recent call last):
  File "/home/wsl/airflow_venv/lib/python3.10/site-packages/elastic_transport/_transport.py", line 342, in perform_request
    resp = node.perform_request(
  File "/home/wsl/airflow_venv/lib/python3.10/site-packages/elastic_transport/_node/_http_urllib3.py", line 202, in perform_request
    raise err from None
elastic_transport.ConnectionError: Connection error caused by: NewConnectionError(<urllib3.connection.HTTPConnection object at 0x7f3085f29d80>: Failed to establish a new connection: [Errno 111] Connection refused)
[2024-06-15T01:12:13.591+0530] {logging_mixin.py:188} INFO - [2024-06-15T01:12:13.591+0530] {_transport.py:372} INFO - HEAD http://localhost:9200/ [status:N/A duration:0.000s]
[2024-06-15T01:12:13.591+0530] {logging_mixin.py:188} INFO - [2024-06-15T01:12:13.591+0530] {_node_pool.py:249} WARNING - Node <Urllib3HttpNode(http://localhost:9200)> has failed for 3 times in a row, putting on 4 second timeout
[2024-06-15T01:12:13.592+0530] {logging_mixin.py:188} INFO - [2024-06-15T01:12:13.592+0530] {_transport.py:415} WARNING - Retrying request after failure (attempt 2 of 3)
Traceback (most recent call last):
  File "/home/wsl/airflow_venv/lib/python3.10/site-packages/elastic_transport/_transport.py", line 342, in perform_request
    resp = node.perform_request(
  File "/home/wsl/airflow_venv/lib/python3.10/site-packages/elastic_transport/_node/_http_urllib3.py", line 202, in perform_request
    raise err from None
elastic_transport.ConnectionError: Connection error caused by: NewConnectionError(<urllib3.connection.HTTPConnection object at 0x7f3085f2a020>: Failed to establish a new connection: [Errno 111] Connection refused)
[2024-06-15T01:12:13.592+0530] {logging_mixin.py:188} INFO - [2024-06-15T01:12:13.592+0530] {_transport.py:372} INFO - HEAD http://localhost:9200/ [status:N/A duration:0.000s]
[2024-06-15T01:12:13.593+0530] {logging_mixin.py:188} INFO - [2024-06-15T01:12:13.593+0530] {_node_pool.py:249} WARNING - Node <Urllib3HttpNode(http://localhost:9200)> has failed for 4 times in a row, putting on 8 second timeout
[2024-06-15T01:12:13.593+0530] {logging_mixin.py:188} INFO - Error: Connection to Elasticsearch failed
[2024-06-15T01:12:13.593+0530] {processor.py:842} WARNING - No viable dags retrieved from /home/wsl/airflow/dags/Collect Data/eindex.py
[2024-06-15T01:12:13.600+0530] {processor.py:183} INFO - Processing /home/wsl/airflow/dags/Collect Data/eindex.py took 8.753 seconds
[2024-06-15T01:13:50.484+0530] {processor.py:161} INFO - Started process (PID=41121) to work on /home/wsl/airflow/dags/Collect Data/eindex.py
[2024-06-15T01:13:50.686+0530] {processor.py:830} INFO - Processing file /home/wsl/airflow/dags/Collect Data/eindex.py for tasks to queue
[2024-06-15T01:13:50.691+0530] {logging_mixin.py:188} INFO - [2024-06-15T01:13:50.689+0530] {dagbag.py:540} INFO - Filling up the DagBag from /home/wsl/airflow/dags/Collect Data/eindex.py
[2024-06-15T01:13:51.438+0530] {logging_mixin.py:188} INFO - Columns in DataFrame: Index(['date', 'continent', 'country', 'cases', 'deaths', 'idx'], dtype='object')
[2024-06-15T01:13:51.649+0530] {logging_mixin.py:188} INFO - [2024-06-15T01:13:51.649+0530] {_transport.py:372} INFO - HEAD http://localhost:9200/ [status:N/A duration:0.001s]
[2024-06-15T01:13:51.650+0530] {logging_mixin.py:188} INFO - [2024-06-15T01:13:51.650+0530] {_node_pool.py:249} WARNING - Node <Urllib3HttpNode(http://localhost:9200)> has failed for 1 times in a row, putting on 1 second timeout
[2024-06-15T01:13:51.651+0530] {logging_mixin.py:188} INFO - [2024-06-15T01:13:51.650+0530] {_transport.py:415} WARNING - Retrying request after failure (attempt 0 of 3)
Traceback (most recent call last):
  File "/home/wsl/airflow_venv/lib/python3.10/site-packages/elastic_transport/_transport.py", line 342, in perform_request
    resp = node.perform_request(
  File "/home/wsl/airflow_venv/lib/python3.10/site-packages/elastic_transport/_node/_http_urllib3.py", line 202, in perform_request
    raise err from None
elastic_transport.ConnectionError: Connection error caused by: NewConnectionError(<urllib3.connection.HTTPConnection object at 0x7f3085f25990>: Failed to establish a new connection: [Errno 111] Connection refused)
[2024-06-15T01:13:51.651+0530] {logging_mixin.py:188} INFO - [2024-06-15T01:13:51.651+0530] {_transport.py:372} INFO - HEAD http://localhost:9200/ [status:N/A duration:0.000s]
[2024-06-15T01:13:51.652+0530] {logging_mixin.py:188} INFO - [2024-06-15T01:13:51.651+0530] {_node_pool.py:249} WARNING - Node <Urllib3HttpNode(http://localhost:9200)> has failed for 2 times in a row, putting on 2 second timeout
[2024-06-15T01:13:51.652+0530] {logging_mixin.py:188} INFO - [2024-06-15T01:13:51.652+0530] {_transport.py:415} WARNING - Retrying request after failure (attempt 1 of 3)
Traceback (most recent call last):
  File "/home/wsl/airflow_venv/lib/python3.10/site-packages/elastic_transport/_transport.py", line 342, in perform_request
    resp = node.perform_request(
  File "/home/wsl/airflow_venv/lib/python3.10/site-packages/elastic_transport/_node/_http_urllib3.py", line 202, in perform_request
    raise err from None
elastic_transport.ConnectionError: Connection error caused by: NewConnectionError(<urllib3.connection.HTTPConnection object at 0x7f3085f25de0>: Failed to establish a new connection: [Errno 111] Connection refused)
[2024-06-15T01:13:51.653+0530] {logging_mixin.py:188} INFO - [2024-06-15T01:13:51.652+0530] {_transport.py:372} INFO - HEAD http://localhost:9200/ [status:N/A duration:0.000s]
[2024-06-15T01:13:51.653+0530] {logging_mixin.py:188} INFO - [2024-06-15T01:13:51.653+0530] {_node_pool.py:249} WARNING - Node <Urllib3HttpNode(http://localhost:9200)> has failed for 3 times in a row, putting on 4 second timeout
[2024-06-15T01:13:51.653+0530] {logging_mixin.py:188} INFO - [2024-06-15T01:13:51.653+0530] {_transport.py:415} WARNING - Retrying request after failure (attempt 2 of 3)
Traceback (most recent call last):
  File "/home/wsl/airflow_venv/lib/python3.10/site-packages/elastic_transport/_transport.py", line 342, in perform_request
    resp = node.perform_request(
  File "/home/wsl/airflow_venv/lib/python3.10/site-packages/elastic_transport/_node/_http_urllib3.py", line 202, in perform_request
    raise err from None
elastic_transport.ConnectionError: Connection error caused by: NewConnectionError(<urllib3.connection.HTTPConnection object at 0x7f3085f26080>: Failed to establish a new connection: [Errno 111] Connection refused)
[2024-06-15T01:13:51.654+0530] {logging_mixin.py:188} INFO - [2024-06-15T01:13:51.654+0530] {_transport.py:372} INFO - HEAD http://localhost:9200/ [status:N/A duration:0.000s]
[2024-06-15T01:13:51.654+0530] {logging_mixin.py:188} INFO - [2024-06-15T01:13:51.654+0530] {_node_pool.py:249} WARNING - Node <Urllib3HttpNode(http://localhost:9200)> has failed for 4 times in a row, putting on 8 second timeout
[2024-06-15T01:13:51.654+0530] {logging_mixin.py:188} INFO - Error: Connection to Elasticsearch failed
[2024-06-15T01:13:51.654+0530] {processor.py:842} WARNING - No viable dags retrieved from /home/wsl/airflow/dags/Collect Data/eindex.py
[2024-06-15T01:13:51.663+0530] {processor.py:183} INFO - Processing /home/wsl/airflow/dags/Collect Data/eindex.py took 1.186 seconds
[2024-06-15T01:16:14.926+0530] {processor.py:161} INFO - Started process (PID=42370) to work on /home/wsl/airflow/dags/Collect Data/eindex.py
[2024-06-15T01:16:14.928+0530] {processor.py:830} INFO - Processing file /home/wsl/airflow/dags/Collect Data/eindex.py for tasks to queue
[2024-06-15T01:16:14.930+0530] {logging_mixin.py:188} INFO - [2024-06-15T01:16:14.929+0530] {dagbag.py:540} INFO - Filling up the DagBag from /home/wsl/airflow/dags/Collect Data/eindex.py
[2024-06-15T01:16:16.896+0530] {logging_mixin.py:188} INFO - Columns in DataFrame: Index(['date', 'continent', 'country', 'cases', 'deaths', 'idx'], dtype='object')
[2024-06-15T01:16:17.188+0530] {logging_mixin.py:188} INFO - [2024-06-15T01:16:17.187+0530] {_transport.py:372} INFO - HEAD http://localhost:9200/ [status:N/A duration:0.001s]
[2024-06-15T01:16:17.188+0530] {logging_mixin.py:188} INFO - [2024-06-15T01:16:17.188+0530] {_node_pool.py:249} WARNING - Node <Urllib3HttpNode(http://localhost:9200)> has failed for 1 times in a row, putting on 1 second timeout
[2024-06-15T01:16:17.189+0530] {logging_mixin.py:188} INFO - [2024-06-15T01:16:17.189+0530] {_transport.py:415} WARNING - Retrying request after failure (attempt 0 of 3)
Traceback (most recent call last):
  File "/home/wsl/airflow_venv/lib/python3.10/site-packages/elastic_transport/_transport.py", line 342, in perform_request
    resp = node.perform_request(
  File "/home/wsl/airflow_venv/lib/python3.10/site-packages/elastic_transport/_node/_http_urllib3.py", line 202, in perform_request
    raise err from None
elastic_transport.ConnectionError: Connection error caused by: NewConnectionError(<urllib3.connection.HTTPConnection object at 0x7f306c08d990>: Failed to establish a new connection: [Errno 111] Connection refused)
[2024-06-15T01:16:17.190+0530] {logging_mixin.py:188} INFO - [2024-06-15T01:16:17.190+0530] {_transport.py:372} INFO - HEAD http://localhost:9200/ [status:N/A duration:0.001s]
[2024-06-15T01:16:17.191+0530] {logging_mixin.py:188} INFO - [2024-06-15T01:16:17.190+0530] {_node_pool.py:249} WARNING - Node <Urllib3HttpNode(http://localhost:9200)> has failed for 2 times in a row, putting on 2 second timeout
[2024-06-15T01:16:17.191+0530] {logging_mixin.py:188} INFO - [2024-06-15T01:16:17.191+0530] {_transport.py:415} WARNING - Retrying request after failure (attempt 1 of 3)
Traceback (most recent call last):
  File "/home/wsl/airflow_venv/lib/python3.10/site-packages/elastic_transport/_transport.py", line 342, in perform_request
    resp = node.perform_request(
  File "/home/wsl/airflow_venv/lib/python3.10/site-packages/elastic_transport/_node/_http_urllib3.py", line 202, in perform_request
    raise err from None
elastic_transport.ConnectionError: Connection error caused by: NewConnectionError(<urllib3.connection.HTTPConnection object at 0x7f306c08dde0>: Failed to establish a new connection: [Errno 111] Connection refused)
[2024-06-15T01:16:17.192+0530] {logging_mixin.py:188} INFO - [2024-06-15T01:16:17.192+0530] {_transport.py:372} INFO - HEAD http://localhost:9200/ [status:N/A duration:0.000s]
[2024-06-15T01:16:17.192+0530] {logging_mixin.py:188} INFO - [2024-06-15T01:16:17.192+0530] {_node_pool.py:249} WARNING - Node <Urllib3HttpNode(http://localhost:9200)> has failed for 3 times in a row, putting on 4 second timeout
[2024-06-15T01:16:17.193+0530] {logging_mixin.py:188} INFO - [2024-06-15T01:16:17.192+0530] {_transport.py:415} WARNING - Retrying request after failure (attempt 2 of 3)
Traceback (most recent call last):
  File "/home/wsl/airflow_venv/lib/python3.10/site-packages/elastic_transport/_transport.py", line 342, in perform_request
    resp = node.perform_request(
  File "/home/wsl/airflow_venv/lib/python3.10/site-packages/elastic_transport/_node/_http_urllib3.py", line 202, in perform_request
    raise err from None
elastic_transport.ConnectionError: Connection error caused by: NewConnectionError(<urllib3.connection.HTTPConnection object at 0x7f306c08e080>: Failed to establish a new connection: [Errno 111] Connection refused)
[2024-06-15T01:16:17.193+0530] {logging_mixin.py:188} INFO - [2024-06-15T01:16:17.193+0530] {_transport.py:372} INFO - HEAD http://localhost:9200/ [status:N/A duration:0.001s]
[2024-06-15T01:16:17.194+0530] {logging_mixin.py:188} INFO - [2024-06-15T01:16:17.194+0530] {_node_pool.py:249} WARNING - Node <Urllib3HttpNode(http://localhost:9200)> has failed for 4 times in a row, putting on 8 second timeout
[2024-06-15T01:16:17.194+0530] {logging_mixin.py:188} INFO - Error: Connection to Elasticsearch failed
[2024-06-15T01:16:17.194+0530] {processor.py:842} WARNING - No viable dags retrieved from /home/wsl/airflow/dags/Collect Data/eindex.py
[2024-06-15T01:16:17.205+0530] {processor.py:183} INFO - Processing /home/wsl/airflow/dags/Collect Data/eindex.py took 2.288 seconds
[2024-06-15T01:17:48.605+0530] {processor.py:161} INFO - Started process (PID=43650) to work on /home/wsl/airflow/dags/Collect Data/eindex.py
[2024-06-15T01:17:48.610+0530] {processor.py:830} INFO - Processing file /home/wsl/airflow/dags/Collect Data/eindex.py for tasks to queue
[2024-06-15T01:17:48.613+0530] {logging_mixin.py:188} INFO - [2024-06-15T01:17:48.612+0530] {dagbag.py:540} INFO - Filling up the DagBag from /home/wsl/airflow/dags/Collect Data/eindex.py
[2024-06-15T01:17:49.309+0530] {logging_mixin.py:188} INFO - Columns in DataFrame: Index(['date', 'continent', 'country', 'cases', 'deaths', 'idx'], dtype='object')
[2024-06-15T01:17:49.521+0530] {logging_mixin.py:188} INFO - [2024-06-15T01:17:49.521+0530] {_transport.py:372} INFO - HEAD http://localhost:9200/ [status:N/A duration:0.001s]
[2024-06-15T01:17:49.521+0530] {logging_mixin.py:188} INFO - [2024-06-15T01:17:49.521+0530] {_node_pool.py:249} WARNING - Node <Urllib3HttpNode(http://localhost:9200)> has failed for 1 times in a row, putting on 1 second timeout
[2024-06-15T01:17:49.522+0530] {logging_mixin.py:188} INFO - [2024-06-15T01:17:49.522+0530] {_transport.py:415} WARNING - Retrying request after failure (attempt 0 of 3)
Traceback (most recent call last):
  File "/home/wsl/airflow_venv/lib/python3.10/site-packages/elastic_transport/_transport.py", line 342, in perform_request
    resp = node.perform_request(
  File "/home/wsl/airflow_venv/lib/python3.10/site-packages/elastic_transport/_node/_http_urllib3.py", line 202, in perform_request
    raise err from None
elastic_transport.ConnectionError: Connection error caused by: NewConnectionError(<urllib3.connection.HTTPConnection object at 0x7f3087fe5a20>: Failed to establish a new connection: [Errno 111] Connection refused)
[2024-06-15T01:17:49.523+0530] {logging_mixin.py:188} INFO - [2024-06-15T01:17:49.523+0530] {_transport.py:372} INFO - HEAD http://localhost:9200/ [status:N/A duration:0.000s]
[2024-06-15T01:17:49.523+0530] {logging_mixin.py:188} INFO - [2024-06-15T01:17:49.523+0530] {_node_pool.py:249} WARNING - Node <Urllib3HttpNode(http://localhost:9200)> has failed for 2 times in a row, putting on 2 second timeout
[2024-06-15T01:17:49.524+0530] {logging_mixin.py:188} INFO - [2024-06-15T01:17:49.523+0530] {_transport.py:415} WARNING - Retrying request after failure (attempt 1 of 3)
Traceback (most recent call last):
  File "/home/wsl/airflow_venv/lib/python3.10/site-packages/elastic_transport/_transport.py", line 342, in perform_request
    resp = node.perform_request(
  File "/home/wsl/airflow_venv/lib/python3.10/site-packages/elastic_transport/_node/_http_urllib3.py", line 202, in perform_request
    raise err from None
elastic_transport.ConnectionError: Connection error caused by: NewConnectionError(<urllib3.connection.HTTPConnection object at 0x7f3087fe5e70>: Failed to establish a new connection: [Errno 111] Connection refused)
[2024-06-15T01:17:49.524+0530] {logging_mixin.py:188} INFO - [2024-06-15T01:17:49.524+0530] {_transport.py:372} INFO - HEAD http://localhost:9200/ [status:N/A duration:0.000s]
[2024-06-15T01:17:49.525+0530] {logging_mixin.py:188} INFO - [2024-06-15T01:17:49.524+0530] {_node_pool.py:249} WARNING - Node <Urllib3HttpNode(http://localhost:9200)> has failed for 3 times in a row, putting on 4 second timeout
[2024-06-15T01:17:49.525+0530] {logging_mixin.py:188} INFO - [2024-06-15T01:17:49.525+0530] {_transport.py:415} WARNING - Retrying request after failure (attempt 2 of 3)
Traceback (most recent call last):
  File "/home/wsl/airflow_venv/lib/python3.10/site-packages/elastic_transport/_transport.py", line 342, in perform_request
    resp = node.perform_request(
  File "/home/wsl/airflow_venv/lib/python3.10/site-packages/elastic_transport/_node/_http_urllib3.py", line 202, in perform_request
    raise err from None
elastic_transport.ConnectionError: Connection error caused by: NewConnectionError(<urllib3.connection.HTTPConnection object at 0x7f3087fe6110>: Failed to establish a new connection: [Errno 111] Connection refused)
[2024-06-15T01:17:49.526+0530] {logging_mixin.py:188} INFO - [2024-06-15T01:17:49.526+0530] {_transport.py:372} INFO - HEAD http://localhost:9200/ [status:N/A duration:0.000s]
[2024-06-15T01:17:49.526+0530] {logging_mixin.py:188} INFO - [2024-06-15T01:17:49.526+0530] {_node_pool.py:249} WARNING - Node <Urllib3HttpNode(http://localhost:9200)> has failed for 4 times in a row, putting on 8 second timeout
[2024-06-15T01:17:49.527+0530] {logging_mixin.py:188} INFO - Error: Connection to Elasticsearch failed
[2024-06-15T01:17:49.527+0530] {processor.py:842} WARNING - No viable dags retrieved from /home/wsl/airflow/dags/Collect Data/eindex.py
[2024-06-15T01:17:49.533+0530] {processor.py:183} INFO - Processing /home/wsl/airflow/dags/Collect Data/eindex.py took 0.946 seconds
[2024-06-15T01:19:11.476+0530] {processor.py:161} INFO - Started process (PID=44501) to work on /home/wsl/airflow/dags/Collect Data/eindex.py
[2024-06-15T01:19:11.478+0530] {processor.py:830} INFO - Processing file /home/wsl/airflow/dags/Collect Data/eindex.py for tasks to queue
[2024-06-15T01:19:11.480+0530] {logging_mixin.py:188} INFO - [2024-06-15T01:19:11.479+0530] {dagbag.py:540} INFO - Filling up the DagBag from /home/wsl/airflow/dags/Collect Data/eindex.py
[2024-06-15T01:19:12.166+0530] {logging_mixin.py:188} INFO - Columns in DataFrame: Index(['date', 'continent', 'country', 'cases', 'deaths', 'idx'], dtype='object')
[2024-06-15T01:19:12.358+0530] {logging_mixin.py:188} INFO - [2024-06-15T01:19:12.357+0530] {_transport.py:372} INFO - HEAD http://localhost:9200/ [status:N/A duration:0.001s]
[2024-06-15T01:19:12.358+0530] {logging_mixin.py:188} INFO - [2024-06-15T01:19:12.358+0530] {_node_pool.py:249} WARNING - Node <Urllib3HttpNode(http://localhost:9200)> has failed for 1 times in a row, putting on 1 second timeout
[2024-06-15T01:19:12.359+0530] {logging_mixin.py:188} INFO - [2024-06-15T01:19:12.358+0530] {_transport.py:415} WARNING - Retrying request after failure (attempt 0 of 3)
Traceback (most recent call last):
  File "/home/wsl/airflow_venv/lib/python3.10/site-packages/elastic_transport/_transport.py", line 342, in perform_request
    resp = node.perform_request(
  File "/home/wsl/airflow_venv/lib/python3.10/site-packages/elastic_transport/_node/_http_urllib3.py", line 202, in perform_request
    raise err from None
elastic_transport.ConnectionError: Connection error caused by: NewConnectionError(<urllib3.connection.HTTPConnection object at 0x7f3087fe9a20>: Failed to establish a new connection: [Errno 111] Connection refused)
[2024-06-15T01:19:12.360+0530] {logging_mixin.py:188} INFO - [2024-06-15T01:19:12.360+0530] {_transport.py:372} INFO - HEAD http://localhost:9200/ [status:N/A duration:0.000s]
[2024-06-15T01:19:12.360+0530] {logging_mixin.py:188} INFO - [2024-06-15T01:19:12.360+0530] {_node_pool.py:249} WARNING - Node <Urllib3HttpNode(http://localhost:9200)> has failed for 2 times in a row, putting on 2 second timeout
[2024-06-15T01:19:12.360+0530] {logging_mixin.py:188} INFO - [2024-06-15T01:19:12.360+0530] {_transport.py:415} WARNING - Retrying request after failure (attempt 1 of 3)
Traceback (most recent call last):
  File "/home/wsl/airflow_venv/lib/python3.10/site-packages/elastic_transport/_transport.py", line 342, in perform_request
    resp = node.perform_request(
  File "/home/wsl/airflow_venv/lib/python3.10/site-packages/elastic_transport/_node/_http_urllib3.py", line 202, in perform_request
    raise err from None
elastic_transport.ConnectionError: Connection error caused by: NewConnectionError(<urllib3.connection.HTTPConnection object at 0x7f3087fe9e70>: Failed to establish a new connection: [Errno 111] Connection refused)
[2024-06-15T01:19:12.361+0530] {logging_mixin.py:188} INFO - [2024-06-15T01:19:12.361+0530] {_transport.py:372} INFO - HEAD http://localhost:9200/ [status:N/A duration:0.000s]
[2024-06-15T01:19:12.361+0530] {logging_mixin.py:188} INFO - [2024-06-15T01:19:12.361+0530] {_node_pool.py:249} WARNING - Node <Urllib3HttpNode(http://localhost:9200)> has failed for 3 times in a row, putting on 4 second timeout
[2024-06-15T01:19:12.362+0530] {logging_mixin.py:188} INFO - [2024-06-15T01:19:12.361+0530] {_transport.py:415} WARNING - Retrying request after failure (attempt 2 of 3)
Traceback (most recent call last):
  File "/home/wsl/airflow_venv/lib/python3.10/site-packages/elastic_transport/_transport.py", line 342, in perform_request
    resp = node.perform_request(
  File "/home/wsl/airflow_venv/lib/python3.10/site-packages/elastic_transport/_node/_http_urllib3.py", line 202, in perform_request
    raise err from None
elastic_transport.ConnectionError: Connection error caused by: NewConnectionError(<urllib3.connection.HTTPConnection object at 0x7f3087fea110>: Failed to establish a new connection: [Errno 111] Connection refused)
[2024-06-15T01:19:12.362+0530] {logging_mixin.py:188} INFO - [2024-06-15T01:19:12.362+0530] {_transport.py:372} INFO - HEAD http://localhost:9200/ [status:N/A duration:0.000s]
[2024-06-15T01:19:12.363+0530] {logging_mixin.py:188} INFO - [2024-06-15T01:19:12.363+0530] {_node_pool.py:249} WARNING - Node <Urllib3HttpNode(http://localhost:9200)> has failed for 4 times in a row, putting on 8 second timeout
[2024-06-15T01:19:12.363+0530] {logging_mixin.py:188} INFO - Error: Connection to Elasticsearch failed
[2024-06-15T01:19:12.363+0530] {processor.py:842} WARNING - No viable dags retrieved from /home/wsl/airflow/dags/Collect Data/eindex.py
[2024-06-15T01:19:12.370+0530] {processor.py:183} INFO - Processing /home/wsl/airflow/dags/Collect Data/eindex.py took 0.910 seconds
[2024-06-15T01:20:22.180+0530] {processor.py:161} INFO - Started process (PID=45041) to work on /home/wsl/airflow/dags/Collect Data/eindex.py
[2024-06-15T01:20:22.242+0530] {processor.py:830} INFO - Processing file /home/wsl/airflow/dags/Collect Data/eindex.py for tasks to queue
[2024-06-15T01:20:22.244+0530] {logging_mixin.py:188} INFO - [2024-06-15T01:20:22.243+0530] {dagbag.py:540} INFO - Filling up the DagBag from /home/wsl/airflow/dags/Collect Data/eindex.py
[2024-06-15T01:20:23.060+0530] {logging_mixin.py:188} INFO - Columns in DataFrame: Index(['date', 'continent', 'country', 'cases', 'deaths', 'idx'], dtype='object')
[2024-06-15T01:20:23.333+0530] {logging_mixin.py:188} INFO - [2024-06-15T01:20:23.332+0530] {_transport.py:372} INFO - HEAD http://localhost:9200/ [status:N/A duration:0.001s]
[2024-06-15T01:20:23.333+0530] {logging_mixin.py:188} INFO - [2024-06-15T01:20:23.333+0530] {_node_pool.py:249} WARNING - Node <Urllib3HttpNode(http://localhost:9200)> has failed for 1 times in a row, putting on 1 second timeout
[2024-06-15T01:20:23.335+0530] {logging_mixin.py:188} INFO - [2024-06-15T01:20:23.334+0530] {_transport.py:415} WARNING - Retrying request after failure (attempt 0 of 3)
Traceback (most recent call last):
  File "/home/wsl/airflow_venv/lib/python3.10/site-packages/elastic_transport/_transport.py", line 342, in perform_request
    resp = node.perform_request(
  File "/home/wsl/airflow_venv/lib/python3.10/site-packages/elastic_transport/_node/_http_urllib3.py", line 202, in perform_request
    raise err from None
elastic_transport.ConnectionError: Connection error caused by: NewConnectionError(<urllib3.connection.HTTPConnection object at 0x7f3085f29c60>: Failed to establish a new connection: [Errno 111] Connection refused)
[2024-06-15T01:20:23.336+0530] {logging_mixin.py:188} INFO - [2024-06-15T01:20:23.335+0530] {_transport.py:372} INFO - HEAD http://localhost:9200/ [status:N/A duration:0.001s]
[2024-06-15T01:20:23.336+0530] {logging_mixin.py:188} INFO - [2024-06-15T01:20:23.336+0530] {_node_pool.py:249} WARNING - Node <Urllib3HttpNode(http://localhost:9200)> has failed for 2 times in a row, putting on 2 second timeout
[2024-06-15T01:20:23.336+0530] {logging_mixin.py:188} INFO - [2024-06-15T01:20:23.336+0530] {_transport.py:415} WARNING - Retrying request after failure (attempt 1 of 3)
Traceback (most recent call last):
  File "/home/wsl/airflow_venv/lib/python3.10/site-packages/elastic_transport/_transport.py", line 342, in perform_request
    resp = node.perform_request(
  File "/home/wsl/airflow_venv/lib/python3.10/site-packages/elastic_transport/_node/_http_urllib3.py", line 202, in perform_request
    raise err from None
elastic_transport.ConnectionError: Connection error caused by: NewConnectionError(<urllib3.connection.HTTPConnection object at 0x7f3085f2a0b0>: Failed to establish a new connection: [Errno 111] Connection refused)
[2024-06-15T01:20:23.337+0530] {logging_mixin.py:188} INFO - [2024-06-15T01:20:23.337+0530] {_transport.py:372} INFO - HEAD http://localhost:9200/ [status:N/A duration:0.000s]
[2024-06-15T01:20:23.338+0530] {logging_mixin.py:188} INFO - [2024-06-15T01:20:23.337+0530] {_node_pool.py:249} WARNING - Node <Urllib3HttpNode(http://localhost:9200)> has failed for 3 times in a row, putting on 4 second timeout
[2024-06-15T01:20:23.338+0530] {logging_mixin.py:188} INFO - [2024-06-15T01:20:23.338+0530] {_transport.py:415} WARNING - Retrying request after failure (attempt 2 of 3)
Traceback (most recent call last):
  File "/home/wsl/airflow_venv/lib/python3.10/site-packages/elastic_transport/_transport.py", line 342, in perform_request
    resp = node.perform_request(
  File "/home/wsl/airflow_venv/lib/python3.10/site-packages/elastic_transport/_node/_http_urllib3.py", line 202, in perform_request
    raise err from None
elastic_transport.ConnectionError: Connection error caused by: NewConnectionError(<urllib3.connection.HTTPConnection object at 0x7f3085f2a350>: Failed to establish a new connection: [Errno 111] Connection refused)
[2024-06-15T01:20:23.339+0530] {logging_mixin.py:188} INFO - [2024-06-15T01:20:23.338+0530] {_transport.py:372} INFO - HEAD http://localhost:9200/ [status:N/A duration:0.000s]
[2024-06-15T01:20:23.339+0530] {logging_mixin.py:188} INFO - [2024-06-15T01:20:23.339+0530] {_node_pool.py:249} WARNING - Node <Urllib3HttpNode(http://localhost:9200)> has failed for 4 times in a row, putting on 8 second timeout
[2024-06-15T01:20:23.339+0530] {logging_mixin.py:188} INFO - Error: Connection to Elasticsearch failed
[2024-06-15T01:20:23.339+0530] {processor.py:842} WARNING - No viable dags retrieved from /home/wsl/airflow/dags/Collect Data/eindex.py
[2024-06-15T01:20:23.346+0530] {processor.py:183} INFO - Processing /home/wsl/airflow/dags/Collect Data/eindex.py took 1.172 seconds
[2024-06-15T01:21:19.138+0530] {processor.py:161} INFO - Started process (PID=45443) to work on /home/wsl/airflow/dags/Collect Data/eindex.py
[2024-06-15T01:21:19.140+0530] {processor.py:830} INFO - Processing file /home/wsl/airflow/dags/Collect Data/eindex.py for tasks to queue
[2024-06-15T01:21:19.141+0530] {logging_mixin.py:188} INFO - [2024-06-15T01:21:19.141+0530] {dagbag.py:540} INFO - Filling up the DagBag from /home/wsl/airflow/dags/Collect Data/eindex.py
[2024-06-15T01:21:19.889+0530] {logging_mixin.py:188} INFO - Columns in DataFrame: Index(['date', 'continent', 'country', 'cases', 'deaths', 'idx'], dtype='object')
[2024-06-15T01:21:20.136+0530] {logging_mixin.py:188} INFO - [2024-06-15T01:21:20.135+0530] {_transport.py:372} INFO - HEAD http://localhost:9200/ [status:N/A duration:0.001s]
[2024-06-15T01:21:20.136+0530] {logging_mixin.py:188} INFO - [2024-06-15T01:21:20.136+0530] {_node_pool.py:249} WARNING - Node <Urllib3HttpNode(http://localhost:9200)> has failed for 1 times in a row, putting on 1 second timeout
[2024-06-15T01:21:20.137+0530] {logging_mixin.py:188} INFO - [2024-06-15T01:21:20.136+0530] {_transport.py:415} WARNING - Retrying request after failure (attempt 0 of 3)
Traceback (most recent call last):
  File "/home/wsl/airflow_venv/lib/python3.10/site-packages/elastic_transport/_transport.py", line 342, in perform_request
    resp = node.perform_request(
  File "/home/wsl/airflow_venv/lib/python3.10/site-packages/elastic_transport/_node/_http_urllib3.py", line 202, in perform_request
    raise err from None
elastic_transport.ConnectionError: Connection error caused by: NewConnectionError(<urllib3.connection.HTTPConnection object at 0x7f306c0a9c60>: Failed to establish a new connection: [Errno 111] Connection refused)
[2024-06-15T01:21:20.137+0530] {logging_mixin.py:188} INFO - [2024-06-15T01:21:20.137+0530] {_transport.py:372} INFO - HEAD http://localhost:9200/ [status:N/A duration:0.000s]
[2024-06-15T01:21:20.138+0530] {logging_mixin.py:188} INFO - [2024-06-15T01:21:20.138+0530] {_node_pool.py:249} WARNING - Node <Urllib3HttpNode(http://localhost:9200)> has failed for 2 times in a row, putting on 2 second timeout
[2024-06-15T01:21:20.138+0530] {logging_mixin.py:188} INFO - [2024-06-15T01:21:20.138+0530] {_transport.py:415} WARNING - Retrying request after failure (attempt 1 of 3)
Traceback (most recent call last):
  File "/home/wsl/airflow_venv/lib/python3.10/site-packages/elastic_transport/_transport.py", line 342, in perform_request
    resp = node.perform_request(
  File "/home/wsl/airflow_venv/lib/python3.10/site-packages/elastic_transport/_node/_http_urllib3.py", line 202, in perform_request
    raise err from None
elastic_transport.ConnectionError: Connection error caused by: NewConnectionError(<urllib3.connection.HTTPConnection object at 0x7f306c0aa0b0>: Failed to establish a new connection: [Errno 111] Connection refused)
[2024-06-15T01:21:20.139+0530] {logging_mixin.py:188} INFO - [2024-06-15T01:21:20.139+0530] {_transport.py:372} INFO - HEAD http://localhost:9200/ [status:N/A duration:0.000s]
[2024-06-15T01:21:20.139+0530] {logging_mixin.py:188} INFO - [2024-06-15T01:21:20.139+0530] {_node_pool.py:249} WARNING - Node <Urllib3HttpNode(http://localhost:9200)> has failed for 3 times in a row, putting on 4 second timeout
[2024-06-15T01:21:20.139+0530] {logging_mixin.py:188} INFO - [2024-06-15T01:21:20.139+0530] {_transport.py:415} WARNING - Retrying request after failure (attempt 2 of 3)
Traceback (most recent call last):
  File "/home/wsl/airflow_venv/lib/python3.10/site-packages/elastic_transport/_transport.py", line 342, in perform_request
    resp = node.perform_request(
  File "/home/wsl/airflow_venv/lib/python3.10/site-packages/elastic_transport/_node/_http_urllib3.py", line 202, in perform_request
    raise err from None
elastic_transport.ConnectionError: Connection error caused by: NewConnectionError(<urllib3.connection.HTTPConnection object at 0x7f306c0aa350>: Failed to establish a new connection: [Errno 111] Connection refused)
[2024-06-15T01:21:20.140+0530] {logging_mixin.py:188} INFO - [2024-06-15T01:21:20.140+0530] {_transport.py:372} INFO - HEAD http://localhost:9200/ [status:N/A duration:0.000s]
[2024-06-15T01:21:20.140+0530] {logging_mixin.py:188} INFO - [2024-06-15T01:21:20.140+0530] {_node_pool.py:249} WARNING - Node <Urllib3HttpNode(http://localhost:9200)> has failed for 4 times in a row, putting on 8 second timeout
[2024-06-15T01:21:20.141+0530] {logging_mixin.py:188} INFO - Error: Connection to Elasticsearch failed
[2024-06-15T01:21:20.141+0530] {processor.py:842} WARNING - No viable dags retrieved from /home/wsl/airflow/dags/Collect Data/eindex.py
[2024-06-15T01:21:20.147+0530] {processor.py:183} INFO - Processing /home/wsl/airflow/dags/Collect Data/eindex.py took 1.019 seconds
[2024-06-15T01:22:41.535+0530] {processor.py:161} INFO - Started process (PID=46021) to work on /home/wsl/airflow/dags/Collect Data/eindex.py
[2024-06-15T01:22:41.537+0530] {processor.py:830} INFO - Processing file /home/wsl/airflow/dags/Collect Data/eindex.py for tasks to queue
[2024-06-15T01:22:41.539+0530] {logging_mixin.py:188} INFO - [2024-06-15T01:22:41.539+0530] {dagbag.py:540} INFO - Filling up the DagBag from /home/wsl/airflow/dags/Collect Data/eindex.py
[2024-06-15T01:22:42.244+0530] {logging_mixin.py:188} INFO - Columns in DataFrame: Index(['date', 'continent', 'country', 'cases', 'deaths', 'idx'], dtype='object')
[2024-06-15T01:22:42.524+0530] {logging_mixin.py:188} INFO - [2024-06-15T01:22:42.523+0530] {_transport.py:372} INFO - HEAD http://localhost:9200/ [status:N/A duration:0.002s]
[2024-06-15T01:22:42.524+0530] {logging_mixin.py:188} INFO - [2024-06-15T01:22:42.524+0530] {_node_pool.py:249} WARNING - Node <Urllib3HttpNode(http://localhost:9200)> has failed for 1 times in a row, putting on 1 second timeout
[2024-06-15T01:22:42.525+0530] {logging_mixin.py:188} INFO - [2024-06-15T01:22:42.525+0530] {_transport.py:415} WARNING - Retrying request after failure (attempt 0 of 3)
Traceback (most recent call last):
  File "/home/wsl/airflow_venv/lib/python3.10/site-packages/elastic_transport/_transport.py", line 342, in perform_request
    resp = node.perform_request(
  File "/home/wsl/airflow_venv/lib/python3.10/site-packages/elastic_transport/_node/_http_urllib3.py", line 202, in perform_request
    raise err from None
elastic_transport.ConnectionError: Connection error caused by: NewConnectionError(<urllib3.connection.HTTPConnection object at 0x7f3087ff1c00>: Failed to establish a new connection: [Errno 111] Connection refused)
[2024-06-15T01:22:42.526+0530] {logging_mixin.py:188} INFO - [2024-06-15T01:22:42.526+0530] {_transport.py:372} INFO - HEAD http://localhost:9200/ [status:N/A duration:0.001s]
[2024-06-15T01:22:42.527+0530] {logging_mixin.py:188} INFO - [2024-06-15T01:22:42.527+0530] {_node_pool.py:249} WARNING - Node <Urllib3HttpNode(http://localhost:9200)> has failed for 2 times in a row, putting on 2 second timeout
[2024-06-15T01:22:42.527+0530] {logging_mixin.py:188} INFO - [2024-06-15T01:22:42.527+0530] {_transport.py:415} WARNING - Retrying request after failure (attempt 1 of 3)
Traceback (most recent call last):
  File "/home/wsl/airflow_venv/lib/python3.10/site-packages/elastic_transport/_transport.py", line 342, in perform_request
    resp = node.perform_request(
  File "/home/wsl/airflow_venv/lib/python3.10/site-packages/elastic_transport/_node/_http_urllib3.py", line 202, in perform_request
    raise err from None
elastic_transport.ConnectionError: Connection error caused by: NewConnectionError(<urllib3.connection.HTTPConnection object at 0x7f3087ff2050>: Failed to establish a new connection: [Errno 111] Connection refused)
[2024-06-15T01:22:42.528+0530] {logging_mixin.py:188} INFO - [2024-06-15T01:22:42.528+0530] {_transport.py:372} INFO - HEAD http://localhost:9200/ [status:N/A duration:0.000s]
[2024-06-15T01:22:42.528+0530] {logging_mixin.py:188} INFO - [2024-06-15T01:22:42.528+0530] {_node_pool.py:249} WARNING - Node <Urllib3HttpNode(http://localhost:9200)> has failed for 3 times in a row, putting on 4 second timeout
[2024-06-15T01:22:42.529+0530] {logging_mixin.py:188} INFO - [2024-06-15T01:22:42.529+0530] {_transport.py:415} WARNING - Retrying request after failure (attempt 2 of 3)
Traceback (most recent call last):
  File "/home/wsl/airflow_venv/lib/python3.10/site-packages/elastic_transport/_transport.py", line 342, in perform_request
    resp = node.perform_request(
  File "/home/wsl/airflow_venv/lib/python3.10/site-packages/elastic_transport/_node/_http_urllib3.py", line 202, in perform_request
    raise err from None
elastic_transport.ConnectionError: Connection error caused by: NewConnectionError(<urllib3.connection.HTTPConnection object at 0x7f3087ff22f0>: Failed to establish a new connection: [Errno 111] Connection refused)
[2024-06-15T01:22:42.530+0530] {logging_mixin.py:188} INFO - [2024-06-15T01:22:42.530+0530] {_transport.py:372} INFO - HEAD http://localhost:9200/ [status:N/A duration:0.000s]
[2024-06-15T01:22:42.530+0530] {logging_mixin.py:188} INFO - [2024-06-15T01:22:42.530+0530] {_node_pool.py:249} WARNING - Node <Urllib3HttpNode(http://localhost:9200)> has failed for 4 times in a row, putting on 8 second timeout
[2024-06-15T01:22:42.530+0530] {logging_mixin.py:188} INFO - Error: Connection to Elasticsearch failed
[2024-06-15T01:22:42.531+0530] {processor.py:842} WARNING - No viable dags retrieved from /home/wsl/airflow/dags/Collect Data/eindex.py
[2024-06-15T01:22:42.540+0530] {processor.py:183} INFO - Processing /home/wsl/airflow/dags/Collect Data/eindex.py took 1.020 seconds
