[2024-06-14T14:19:51.284+0530] {local_task_job_runner.py:120} INFO - ::group::Pre task execution logs
[2024-06-14T14:19:51.311+0530] {taskinstance.py:2073} INFO - Dependencies all met for dep_context=non-requeueable deps ti=<TaskInstance: my_data_pipeline_dag.collect_data_1 manual__2024-06-14T08:49:37.980375+00:00 [queued]>
[2024-06-14T14:19:51.317+0530] {taskinstance.py:2073} INFO - Dependencies all met for dep_context=requeueable deps ti=<TaskInstance: my_data_pipeline_dag.collect_data_1 manual__2024-06-14T08:49:37.980375+00:00 [queued]>
[2024-06-14T14:19:51.318+0530] {taskinstance.py:2303} INFO - Starting attempt 1 of 2
[2024-06-14T14:19:51.614+0530] {taskinstance.py:2327} INFO - Executing <Task(BashOperator): collect_data_1> on 2024-06-14 08:49:37.980375+00:00
[2024-06-14T14:19:51.623+0530] {standard_task_runner.py:63} INFO - Started process 31201 to run task
[2024-06-14T14:19:51.635+0530] {standard_task_runner.py:90} INFO - Running: ['airflow', 'tasks', 'run', 'my_data_pipeline_dag', 'collect_data_1', 'manual__2024-06-14T08:49:37.980375+00:00', '--job-id', '105', '--raw', '--subdir', 'DAGS_FOLDER/my_first_dag.py', '--cfg-path', '/tmp/tmpnn3_82_2']
[2024-06-14T14:19:51.639+0530] {standard_task_runner.py:91} INFO - Job 105: Subtask collect_data_1
[2024-06-14T14:19:51.996+0530] {task_command.py:426} INFO - Running <TaskInstance: my_data_pipeline_dag.collect_data_1 manual__2024-06-14T08:49:37.980375+00:00 [running]> on host DESKTOP-J05K55U.
[2024-06-14T14:19:52.490+0530] {taskinstance.py:2644} INFO - Exporting env vars: AIRFLOW_CTX_DAG_EMAIL='airflow@example.com' AIRFLOW_CTX_DAG_OWNER='airflow' AIRFLOW_CTX_DAG_ID='my_data_pipeline_dag' AIRFLOW_CTX_TASK_ID='collect_data_1' AIRFLOW_CTX_EXECUTION_DATE='2024-06-14T08:49:37.980375+00:00' AIRFLOW_CTX_TRY_NUMBER='1' AIRFLOW_CTX_DAG_RUN_ID='manual__2024-06-14T08:49:37.980375+00:00'
[2024-06-14T14:19:52.492+0530] {taskinstance.py:430} INFO - ::endgroup::
[2024-06-14T14:19:52.493+0530] {subprocess.py:63} INFO - Tmp dir root location: /tmp
[2024-06-14T14:19:52.494+0530] {subprocess.py:75} INFO - Running command: ['/usr/bin/bash', '-c', 'python "/home/wsl/airflow/dags/Collect Data/covid_19_usa.py"']
[2024-06-14T14:19:52.506+0530] {subprocess.py:86} INFO - Output:
[2024-06-14T14:19:52.701+0530] {subprocess.py:93} INFO - Traceback (most recent call last):
[2024-06-14T14:19:52.701+0530] {subprocess.py:93} INFO -   File "/home/wsl/airflow_venv/lib/python3.10/site-packages/urllib3/connectionpool.py", line 715, in urlopen
[2024-06-14T14:19:52.701+0530] {subprocess.py:93} INFO -     httplib_response = self._make_request(
[2024-06-14T14:19:52.702+0530] {subprocess.py:93} INFO -   File "/home/wsl/airflow_venv/lib/python3.10/site-packages/urllib3/connectionpool.py", line 404, in _make_request
[2024-06-14T14:19:52.702+0530] {subprocess.py:93} INFO -     self._validate_conn(conn)
[2024-06-14T14:19:52.702+0530] {subprocess.py:93} INFO -   File "/home/wsl/airflow_venv/lib/python3.10/site-packages/urllib3/connectionpool.py", line 1058, in _validate_conn
[2024-06-14T14:19:52.702+0530] {subprocess.py:93} INFO -     conn.connect()
[2024-06-14T14:19:52.702+0530] {subprocess.py:93} INFO -   File "/home/wsl/airflow_venv/lib/python3.10/site-packages/urllib3/connection.py", line 472, in connect
[2024-06-14T14:19:52.703+0530] {subprocess.py:93} INFO -     _match_hostname(cert, self.assert_hostname or server_hostname)
[2024-06-14T14:19:52.703+0530] {subprocess.py:93} INFO -   File "/home/wsl/airflow_venv/lib/python3.10/site-packages/urllib3/connection.py", line 545, in _match_hostname
[2024-06-14T14:19:52.703+0530] {subprocess.py:93} INFO -     match_hostname(cert, asserted_hostname)
[2024-06-14T14:19:52.703+0530] {subprocess.py:93} INFO -   File "/home/wsl/airflow_venv/lib/python3.10/site-packages/urllib3/util/ssl_match_hostname.py", line 150, in match_hostname
[2024-06-14T14:19:52.704+0530] {subprocess.py:93} INFO -     raise CertificateError(
[2024-06-14T14:19:52.704+0530] {subprocess.py:93} INFO - urllib3.util.ssl_match_hostname.CertificateError: hostname 'covid-193.p.rapidapi.com' doesn't match either of 'wireless.wifirst.net', 'www.wireless.wifirst.net'
[2024-06-14T14:19:52.704+0530] {subprocess.py:93} INFO - 
[2024-06-14T14:19:52.704+0530] {subprocess.py:93} INFO - During handling of the above exception, another exception occurred:
[2024-06-14T14:19:52.704+0530] {subprocess.py:93} INFO - 
[2024-06-14T14:19:52.704+0530] {subprocess.py:93} INFO - Traceback (most recent call last):
[2024-06-14T14:19:52.704+0530] {subprocess.py:93} INFO -   File "/home/wsl/airflow_venv/lib/python3.10/site-packages/requests/adapters.py", line 486, in send
[2024-06-14T14:19:52.705+0530] {subprocess.py:93} INFO -     resp = conn.urlopen(
[2024-06-14T14:19:52.705+0530] {subprocess.py:93} INFO -   File "/home/wsl/airflow_venv/lib/python3.10/site-packages/urllib3/connectionpool.py", line 799, in urlopen
[2024-06-14T14:19:52.705+0530] {subprocess.py:93} INFO -     retries = retries.increment(
[2024-06-14T14:19:52.705+0530] {subprocess.py:93} INFO -   File "/home/wsl/airflow_venv/lib/python3.10/site-packages/urllib3/util/retry.py", line 592, in increment
[2024-06-14T14:19:52.705+0530] {subprocess.py:93} INFO -     raise MaxRetryError(_pool, url, error or ResponseError(cause))
[2024-06-14T14:19:52.705+0530] {subprocess.py:93} INFO - urllib3.exceptions.MaxRetryError: HTTPSConnectionPool(host='covid-193.p.rapidapi.com', port=443): Max retries exceeded with url: /history?country=usa (Caused by SSLError(CertificateError("hostname 'covid-193.p.rapidapi.com' doesn't match either of 'wireless.wifirst.net', 'www.wireless.wifirst.net'")))
[2024-06-14T14:19:52.705+0530] {subprocess.py:93} INFO - 
[2024-06-14T14:19:52.706+0530] {subprocess.py:93} INFO - During handling of the above exception, another exception occurred:
[2024-06-14T14:19:52.706+0530] {subprocess.py:93} INFO - 
[2024-06-14T14:19:52.706+0530] {subprocess.py:93} INFO - Traceback (most recent call last):
[2024-06-14T14:19:52.706+0530] {subprocess.py:93} INFO -   File "/home/wsl/airflow/dags/Collect Data/covid_19_usa.py", line 12, in <module>
[2024-06-14T14:19:52.706+0530] {subprocess.py:93} INFO -     response = requests.get(url, headers=headers, params=querystring)
[2024-06-14T14:19:52.706+0530] {subprocess.py:93} INFO -   File "/home/wsl/airflow_venv/lib/python3.10/site-packages/requests/api.py", line 73, in get
[2024-06-14T14:19:52.706+0530] {subprocess.py:93} INFO -     return request("get", url, params=params, **kwargs)
[2024-06-14T14:19:52.707+0530] {subprocess.py:93} INFO -   File "/home/wsl/airflow_venv/lib/python3.10/site-packages/requests/api.py", line 59, in request
[2024-06-14T14:19:52.707+0530] {subprocess.py:93} INFO -     return session.request(method=method, url=url, **kwargs)
[2024-06-14T14:19:52.707+0530] {subprocess.py:93} INFO -   File "/home/wsl/airflow_venv/lib/python3.10/site-packages/requests/sessions.py", line 589, in request
[2024-06-14T14:19:52.707+0530] {subprocess.py:93} INFO -     resp = self.send(prep, **send_kwargs)
[2024-06-14T14:19:52.707+0530] {subprocess.py:93} INFO -   File "/home/wsl/airflow_venv/lib/python3.10/site-packages/requests/sessions.py", line 703, in send
[2024-06-14T14:19:52.707+0530] {subprocess.py:93} INFO -     r = adapter.send(request, **kwargs)
[2024-06-14T14:19:52.707+0530] {subprocess.py:93} INFO -   File "/home/wsl/airflow_venv/lib/python3.10/site-packages/requests/adapters.py", line 517, in send
[2024-06-14T14:19:52.707+0530] {subprocess.py:93} INFO -     raise SSLError(e, request=request)
[2024-06-14T14:19:52.707+0530] {subprocess.py:93} INFO - requests.exceptions.SSLError: HTTPSConnectionPool(host='covid-193.p.rapidapi.com', port=443): Max retries exceeded with url: /history?country=usa (Caused by SSLError(CertificateError("hostname 'covid-193.p.rapidapi.com' doesn't match either of 'wireless.wifirst.net', 'www.wireless.wifirst.net'")))
[2024-06-14T14:19:52.726+0530] {subprocess.py:97} INFO - Command exited with return code 1
[2024-06-14T14:19:52.726+0530] {taskinstance.py:441} INFO - ::group::Post task execution logs
[2024-06-14T14:19:52.733+0530] {taskinstance.py:2890} ERROR - Task failed with exception
Traceback (most recent call last):
  File "/home/wsl/airflow_venv/lib/python3.10/site-packages/airflow/models/taskinstance.py", line 465, in _execute_task
    result = _execute_callable(context=context, **execute_callable_kwargs)
  File "/home/wsl/airflow_venv/lib/python3.10/site-packages/airflow/models/taskinstance.py", line 432, in _execute_callable
    return execute_callable(context=context, **execute_callable_kwargs)
  File "/home/wsl/airflow_venv/lib/python3.10/site-packages/airflow/models/baseoperator.py", line 400, in wrapper
    return func(self, *args, **kwargs)
  File "/home/wsl/airflow_venv/lib/python3.10/site-packages/airflow/operators/bash.py", line 243, in execute
    raise AirflowException(
airflow.exceptions.AirflowException: Bash command failed. The command returned a non-zero exit code 1.
[2024-06-14T14:19:52.737+0530] {taskinstance.py:1205} INFO - Marking task as UP_FOR_RETRY. dag_id=my_data_pipeline_dag, task_id=collect_data_1, execution_date=20240614T084937, start_date=20240614T084951, end_date=20240614T084952
[2024-06-14T14:19:52.884+0530] {standard_task_runner.py:110} ERROR - Failed to execute job 105 for task collect_data_1 (Bash command failed. The command returned a non-zero exit code 1.; 31201)
[2024-06-14T14:19:52.933+0530] {local_task_job_runner.py:240} INFO - Task exited with return code 1
[2024-06-14T14:19:52.957+0530] {taskinstance.py:3482} INFO - 0 downstream tasks scheduled from follow-on schedule check
[2024-06-14T14:19:52.958+0530] {local_task_job_runner.py:222} INFO - ::endgroup::
