2024-06-14 14:36:45,538 INFO - Task context logging is enabled
2024-06-14 14:36:45,540 INFO - Loaded executor: SequentialExecutor
2024-06-14 14:36:45,582 INFO - Starting the scheduler
2024-06-14 14:36:45,583 INFO - Processing each file at most -1 times
2024-06-14 14:36:45,590 INFO - Launched DagFileProcessorManager with pid: 39310
2024-06-14 14:36:45,592 INFO - Adopting or resetting orphaned tasks for active dag runs
2024-06-14 14:36:45,595 INFO - Configured default timezone UTC
2024-06-14 14:36:45,652 INFO - Marked 1 SchedulerJob instances as failed
2024-06-14 14:37:25,766 ERROR - Job heartbeat got an exception
Traceback (most recent call last):
  File "/home/wsl/airflow_venv/lib/python3.10/site-packages/sqlalchemy/engine/base.py", line 1910, in _execute_context
    self.dialect.do_execute(
  File "/home/wsl/airflow_venv/lib/python3.10/site-packages/sqlalchemy/engine/default.py", line 736, in do_execute
    cursor.execute(statement, parameters)
sqlite3.OperationalError: database is locked

The above exception was the direct cause of the following exception:

Traceback (most recent call last):
  File "/home/wsl/airflow_venv/lib/python3.10/site-packages/airflow/jobs/job.py", line 207, in heartbeat
    job = Job._update_heartbeat(job=self, session=session)
  File "/home/wsl/airflow_venv/lib/python3.10/site-packages/airflow/api_internal/internal_api_call.py", line 115, in wrapper
    return func(*args, **kwargs)
  File "/home/wsl/airflow_venv/lib/python3.10/site-packages/airflow/utils/session.py", line 76, in wrapper
    return func(*args, **kwargs)
  File "/home/wsl/airflow_venv/lib/python3.10/site-packages/airflow/utils/retries.py", line 89, in wrapped_function
    for attempt in run_with_db_retries(max_retries=retries, logger=logger, **retry_kwargs):
  File "/home/wsl/airflow_venv/lib/python3.10/site-packages/tenacity/__init__.py", line 347, in __iter__
    do = self.iter(retry_state=retry_state)
  File "/home/wsl/airflow_venv/lib/python3.10/site-packages/tenacity/__init__.py", line 325, in iter
    raise retry_exc.reraise()
  File "/home/wsl/airflow_venv/lib/python3.10/site-packages/tenacity/__init__.py", line 158, in reraise
    raise self.last_attempt.result()
  File "/usr/lib/python3.10/concurrent/futures/_base.py", line 451, in result
    return self.__get_result()
  File "/usr/lib/python3.10/concurrent/futures/_base.py", line 403, in __get_result
    raise self._exception
  File "/home/wsl/airflow_venv/lib/python3.10/site-packages/airflow/utils/retries.py", line 98, in wrapped_function
    return func(*args, **kwargs)
  File "/home/wsl/airflow_venv/lib/python3.10/site-packages/airflow/jobs/job.py", line 360, in _update_heartbeat
    session.commit()
  File "/home/wsl/airflow_venv/lib/python3.10/site-packages/sqlalchemy/orm/session.py", line 1454, in commit
    self._transaction.commit(_to_root=self.future)
  File "/home/wsl/airflow_venv/lib/python3.10/site-packages/sqlalchemy/orm/session.py", line 832, in commit
    self._prepare_impl()
  File "/home/wsl/airflow_venv/lib/python3.10/site-packages/sqlalchemy/orm/session.py", line 811, in _prepare_impl
    self.session.flush()
  File "/home/wsl/airflow_venv/lib/python3.10/site-packages/sqlalchemy/orm/session.py", line 3449, in flush
    self._flush(objects)
  File "/home/wsl/airflow_venv/lib/python3.10/site-packages/sqlalchemy/orm/session.py", line 3588, in _flush
    with util.safe_reraise():
  File "/home/wsl/airflow_venv/lib/python3.10/site-packages/sqlalchemy/util/langhelpers.py", line 70, in __exit__
    compat.raise_(
  File "/home/wsl/airflow_venv/lib/python3.10/site-packages/sqlalchemy/util/compat.py", line 211, in raise_
    raise exception
  File "/home/wsl/airflow_venv/lib/python3.10/site-packages/sqlalchemy/orm/session.py", line 3549, in _flush
    flush_context.execute()
  File "/home/wsl/airflow_venv/lib/python3.10/site-packages/sqlalchemy/orm/unitofwork.py", line 456, in execute
    rec.execute(self)
  File "/home/wsl/airflow_venv/lib/python3.10/site-packages/sqlalchemy/orm/unitofwork.py", line 630, in execute
    util.preloaded.orm_persistence.save_obj(
  File "/home/wsl/airflow_venv/lib/python3.10/site-packages/sqlalchemy/orm/persistence.py", line 237, in save_obj
    _emit_update_statements(
  File "/home/wsl/airflow_venv/lib/python3.10/site-packages/sqlalchemy/orm/persistence.py", line 1001, in _emit_update_statements
    c = connection._execute_20(
  File "/home/wsl/airflow_venv/lib/python3.10/site-packages/sqlalchemy/engine/base.py", line 1710, in _execute_20
    return meth(self, args_10style, kwargs_10style, execution_options)
  File "/home/wsl/airflow_venv/lib/python3.10/site-packages/sqlalchemy/sql/elements.py", line 334, in _execute_on_connection
    return connection._execute_clauseelement(
  File "/home/wsl/airflow_venv/lib/python3.10/site-packages/sqlalchemy/engine/base.py", line 1577, in _execute_clauseelement
    ret = self._execute_context(
  File "/home/wsl/airflow_venv/lib/python3.10/site-packages/sqlalchemy/engine/base.py", line 1953, in _execute_context
    self._handle_dbapi_exception(
  File "/home/wsl/airflow_venv/lib/python3.10/site-packages/sqlalchemy/engine/base.py", line 2134, in _handle_dbapi_exception
    util.raise_(
  File "/home/wsl/airflow_venv/lib/python3.10/site-packages/sqlalchemy/util/compat.py", line 211, in raise_
    raise exception
  File "/home/wsl/airflow_venv/lib/python3.10/site-packages/sqlalchemy/engine/base.py", line 1910, in _execute_context
    self.dialect.do_execute(
  File "/home/wsl/airflow_venv/lib/python3.10/site-packages/sqlalchemy/engine/default.py", line 736, in do_execute
    cursor.execute(statement, parameters)
sqlalchemy.exc.OperationalError: (sqlite3.OperationalError) database is locked
[SQL: UPDATE job SET latest_heartbeat=? WHERE job.id = ?]
[parameters: ('2024-06-14 09:07:20.754992', 3)]
(Background on this error at: https://sqlalche.me/e/14/e3q8)
2024-06-14 14:37:25,824 ERROR - Job heartbeat failed with error. Scheduler is in unhealthy state
2024-06-14 14:37:30,884 ERROR - Exception when executing SchedulerJob._run_scheduler_loop
Traceback (most recent call last):
  File "/home/wsl/airflow_venv/lib/python3.10/site-packages/sqlalchemy/engine/base.py", line 1910, in _execute_context
    self.dialect.do_execute(
  File "/home/wsl/airflow_venv/lib/python3.10/site-packages/sqlalchemy/engine/default.py", line 736, in do_execute
    cursor.execute(statement, parameters)
sqlite3.OperationalError: database is locked

The above exception was the direct cause of the following exception:

Traceback (most recent call last):
  File "/home/wsl/airflow_venv/lib/python3.10/site-packages/airflow/jobs/scheduler_job_runner.py", line 843, in _execute
    self._run_scheduler_loop()
  File "/home/wsl/airflow_venv/lib/python3.10/site-packages/airflow/jobs/scheduler_job_runner.py", line 989, in _run_scheduler_loop
    next_event = timers.run(blocking=False)
  File "/usr/lib/python3.10/sched.py", line 151, in run
    action(*argument, **kwargs)
  File "/home/wsl/airflow_venv/lib/python3.10/site-packages/airflow/utils/event_scheduler.py", line 40, in repeat
    action(*args, **kwargs)
  File "/home/wsl/airflow_venv/lib/python3.10/site-packages/airflow/utils/session.py", line 79, in wrapper
    return func(*args, session=session, **kwargs)
  File "/home/wsl/airflow_venv/lib/python3.10/site-packages/airflow/jobs/scheduler_job_runner.py", line 1672, in check_trigger_timeouts
    num_timed_out_tasks = session.execute(
  File "/home/wsl/airflow_venv/lib/python3.10/site-packages/sqlalchemy/orm/session.py", line 1717, in execute
    result = conn._execute_20(statement, params or {}, execution_options)
  File "/home/wsl/airflow_venv/lib/python3.10/site-packages/sqlalchemy/engine/base.py", line 1710, in _execute_20
    return meth(self, args_10style, kwargs_10style, execution_options)
  File "/home/wsl/airflow_venv/lib/python3.10/site-packages/sqlalchemy/sql/elements.py", line 334, in _execute_on_connection
    return connection._execute_clauseelement(
  File "/home/wsl/airflow_venv/lib/python3.10/site-packages/sqlalchemy/engine/base.py", line 1577, in _execute_clauseelement
    ret = self._execute_context(
  File "/home/wsl/airflow_venv/lib/python3.10/site-packages/sqlalchemy/engine/base.py", line 1953, in _execute_context
    self._handle_dbapi_exception(
  File "/home/wsl/airflow_venv/lib/python3.10/site-packages/sqlalchemy/engine/base.py", line 2134, in _handle_dbapi_exception
    util.raise_(
  File "/home/wsl/airflow_venv/lib/python3.10/site-packages/sqlalchemy/util/compat.py", line 211, in raise_
    raise exception
  File "/home/wsl/airflow_venv/lib/python3.10/site-packages/sqlalchemy/engine/base.py", line 1910, in _execute_context
    self.dialect.do_execute(
  File "/home/wsl/airflow_venv/lib/python3.10/site-packages/sqlalchemy/engine/default.py", line 736, in do_execute
    cursor.execute(statement, parameters)
sqlalchemy.exc.OperationalError: (sqlite3.OperationalError) database is locked
[SQL: UPDATE task_instance SET state=?, updated_at=?, trigger_id=?, next_method=?, next_kwargs=? WHERE task_instance.state = ? AND task_instance.trigger_timeout < ?]
[parameters: (<TaskInstanceState.SCHEDULED: 'scheduled'>, '2024-06-14 09:07:25.859457', None, '__fail__', '{"__var": {"error": "Trigger/execution timeout"}, "__type": "dict"}', <TaskInstanceState.DEFERRED: 'deferred'>, '2024-06-14 09:07:25.856528')]
(Background on this error at: https://sqlalche.me/e/14/e3q8)
2024-06-14 14:37:31,891 INFO - Sending Signals.SIGTERM to group 39310. PIDs of all processes in the group: [39310]
2024-06-14 14:37:31,892 INFO - Sending the signal Signals.SIGTERM to group 39310
2024-06-14 14:37:32,289 INFO - Process psutil.Process(pid=39310, status='terminated', exitcode=0, started='14:36:45') (39310) terminated with exit code 0
2024-06-14 14:37:32,291 INFO - Exited execute loop
