[2024-06-14T18:01:45.464+0530] {local_task_job_runner.py:120} INFO - ::group::Pre task execution logs
[2024-06-14T18:01:45.504+0530] {taskinstance.py:2073} INFO - Dependencies all met for dep_context=non-requeueable deps ti=<TaskInstance: my_data_pipeline_dag.collect_data_1 manual__2024-06-14T12:31:06.193719+00:00 [queued]>
[2024-06-14T18:01:45.515+0530] {taskinstance.py:2073} INFO - Dependencies all met for dep_context=requeueable deps ti=<TaskInstance: my_data_pipeline_dag.collect_data_1 manual__2024-06-14T12:31:06.193719+00:00 [queued]>
[2024-06-14T18:01:45.517+0530] {taskinstance.py:2303} INFO - Starting attempt 1 of 2
[2024-06-14T18:01:45.544+0530] {taskinstance.py:2327} INFO - Executing <Task(BashOperator): collect_data_1> on 2024-06-14 12:31:06.193719+00:00
[2024-06-14T18:01:45.549+0530] {standard_task_runner.py:63} INFO - Started process 31463 to run task
[2024-06-14T18:01:45.553+0530] {standard_task_runner.py:90} INFO - Running: ['airflow', 'tasks', 'run', 'my_data_pipeline_dag', 'collect_data_1', 'manual__2024-06-14T12:31:06.193719+00:00', '--job-id', '43', '--raw', '--subdir', 'DAGS_FOLDER/my_first_dag.py', '--cfg-path', '/tmp/tmpsvaeivcd']
[2024-06-14T18:01:45.556+0530] {standard_task_runner.py:91} INFO - Job 43: Subtask collect_data_1
[2024-06-14T18:01:45.638+0530] {task_command.py:426} INFO - Running <TaskInstance: my_data_pipeline_dag.collect_data_1 manual__2024-06-14T12:31:06.193719+00:00 [running]> on host DESKTOP-J05K55U.
[2024-06-14T18:01:53.200+0530] {taskinstance.py:2644} INFO - Exporting env vars: AIRFLOW_CTX_DAG_EMAIL='airflow@example.com' AIRFLOW_CTX_DAG_OWNER='airflow' AIRFLOW_CTX_DAG_ID='my_data_pipeline_dag' AIRFLOW_CTX_TASK_ID='collect_data_1' AIRFLOW_CTX_EXECUTION_DATE='2024-06-14T12:31:06.193719+00:00' AIRFLOW_CTX_TRY_NUMBER='1' AIRFLOW_CTX_DAG_RUN_ID='manual__2024-06-14T12:31:06.193719+00:00'
[2024-06-14T18:01:53.203+0530] {taskinstance.py:430} INFO - ::endgroup::
[2024-06-14T18:01:53.204+0530] {subprocess.py:63} INFO - Tmp dir root location: /tmp
[2024-06-14T18:01:53.205+0530] {subprocess.py:75} INFO - Running command: ['/usr/bin/bash', '-c', 'python "/home/wsl/airflow/dags/Collect Data/covid_19_usa.py"']
[2024-06-14T18:01:53.213+0530] {subprocess.py:86} INFO - Output:
[2024-06-14T18:01:54.372+0530] {subprocess.py:97} INFO - Command exited with return code 0
[2024-06-14T18:01:54.373+0530] {taskinstance.py:441} INFO - ::group::Post task execution logs
[2024-06-14T18:01:59.399+0530] {taskinstance.py:2890} ERROR - Task failed with exception
Traceback (most recent call last):
  File "/home/wsl/airflow_venv/lib/python3.10/site-packages/sqlalchemy/engine/base.py", line 1910, in _execute_context
    self.dialect.do_execute(
  File "/home/wsl/airflow_venv/lib/python3.10/site-packages/sqlalchemy/engine/default.py", line 736, in do_execute
    cursor.execute(statement, parameters)
sqlite3.OperationalError: database is locked

The above exception was the direct cause of the following exception:

Traceback (most recent call last):
  File "/home/wsl/airflow_venv/lib/python3.10/site-packages/airflow/models/taskinstance.py", line 486, in _execute_task
    task_instance.xcom_push(key=XCOM_RETURN_KEY, value=xcom_value, session=session)
  File "/home/wsl/airflow_venv/lib/python3.10/site-packages/airflow/utils/session.py", line 76, in wrapper
    return func(*args, **kwargs)
  File "/home/wsl/airflow_venv/lib/python3.10/site-packages/airflow/models/taskinstance.py", line 3182, in xcom_push
    XCom.set(
  File "/home/wsl/airflow_venv/lib/python3.10/site-packages/airflow/utils/session.py", line 76, in wrapper
    return func(*args, **kwargs)
  File "/home/wsl/airflow_venv/lib/python3.10/site-packages/airflow/models/xcom.py", line 222, in set
    dag_run_id = session.query(DagRun.id).filter_by(dag_id=dag_id, run_id=run_id).scalar()
  File "/home/wsl/airflow_venv/lib/python3.10/site-packages/sqlalchemy/orm/query.py", line 2893, in scalar
    ret = self.one()
  File "/home/wsl/airflow_venv/lib/python3.10/site-packages/sqlalchemy/orm/query.py", line 2870, in one
    return self._iter().one()
  File "/home/wsl/airflow_venv/lib/python3.10/site-packages/sqlalchemy/orm/query.py", line 2916, in _iter
    result = self.session.execute(
  File "/home/wsl/airflow_venv/lib/python3.10/site-packages/sqlalchemy/orm/session.py", line 1717, in execute
    result = conn._execute_20(statement, params or {}, execution_options)
  File "/home/wsl/airflow_venv/lib/python3.10/site-packages/sqlalchemy/engine/base.py", line 1710, in _execute_20
    return meth(self, args_10style, kwargs_10style, execution_options)
  File "/home/wsl/airflow_venv/lib/python3.10/site-packages/sqlalchemy/sql/elements.py", line 334, in _execute_on_connection
    return connection._execute_clauseelement(
  File "/home/wsl/airflow_venv/lib/python3.10/site-packages/sqlalchemy/engine/base.py", line 1577, in _execute_clauseelement
    ret = self._execute_context(
  File "/home/wsl/airflow_venv/lib/python3.10/site-packages/sqlalchemy/engine/base.py", line 1953, in _execute_context
    self._handle_dbapi_exception(
  File "/home/wsl/airflow_venv/lib/python3.10/site-packages/sqlalchemy/engine/base.py", line 2134, in _handle_dbapi_exception
    util.raise_(
  File "/home/wsl/airflow_venv/lib/python3.10/site-packages/sqlalchemy/util/compat.py", line 211, in raise_
    raise exception
  File "/home/wsl/airflow_venv/lib/python3.10/site-packages/sqlalchemy/engine/base.py", line 1910, in _execute_context
    self.dialect.do_execute(
  File "/home/wsl/airflow_venv/lib/python3.10/site-packages/sqlalchemy/engine/default.py", line 736, in do_execute
    cursor.execute(statement, parameters)
sqlalchemy.exc.OperationalError: (sqlite3.OperationalError) database is locked
[SQL: SELECT dag_run.id AS dag_run_id 
FROM dag_run 
WHERE dag_run.dag_id = ? AND dag_run.run_id = ?]
[parameters: ('my_data_pipeline_dag', 'manual__2024-06-14T12:31:06.193719+00:00')]
(Background on this error at: https://sqlalche.me/e/14/e3q8)
[2024-06-14T18:02:03.062+0530] {taskinstance.py:1205} INFO - Marking task as UP_FOR_RETRY. dag_id=my_data_pipeline_dag, task_id=collect_data_1, execution_date=20240614T123106, start_date=20240614T123145, end_date=20240614T123203
[2024-06-14T18:02:03.221+0530] {standard_task_runner.py:110} ERROR - Failed to execute job 43 for task collect_data_1 ((sqlite3.OperationalError) database is locked
[SQL: SELECT dag_run.id AS dag_run_id 
FROM dag_run 
WHERE dag_run.dag_id = ? AND dag_run.run_id = ?]
[parameters: ('my_data_pipeline_dag', 'manual__2024-06-14T12:31:06.193719+00:00')]
(Background on this error at: https://sqlalche.me/e/14/e3q8); 31463)
[2024-06-14T18:02:03.251+0530] {local_task_job_runner.py:240} INFO - Task exited with return code 1
[2024-06-14T18:02:03.336+0530] {taskinstance.py:3482} INFO - 0 downstream tasks scheduled from follow-on schedule check
[2024-06-14T18:02:03.337+0530] {local_task_job_runner.py:222} INFO - ::endgroup::
